Workbook
Name area: #REF!
Name ds: 'IKARIA TECHO'!$Q$6
Name ETR: 'CALCULO CANTIDADES '!$P$6
Name KH: 'BASE DATOS EQUIPOS Y SUBCONTRAT'!$P$6
Name plazo: #REF!
Name tc: #REF!
Name area: 'IKARIA TECHO'!$E$8
Name tc: 'IKARIA TECHO'!$Q$6
Name area: [2]Presupuesto!$C$8
Name plazo: 'Gastos generales'!$F$6
Name tc: 'Gastos generales'!$C$5

Sheet IKARIA TECHO
D3: Desglose de Presupuesto
D4: Proyecto: | E4: IKARIA TECHO
D5: Cliente: | E5: ADELANTE DESARROLLOS | R5: Actualizacion
D6: Fecha: | E6: 44719 | P6: TC | Q6: 700 | R6: 44713
D7: Ubicación: | E7: Cartago
D8: Area: | E8: 90.84
B9: CODIGO | C9: CODIGO ACUMATICA | D9: N° | E9: Descripcion actividad | F9: Cantidad | G9: Unidad | H9: Unit mater | I9: Unit MO | J9: Unit Sub/ Equipos | K9: Total Mater | L9: Total MO | M9: Total Sub/Equipos | N9: Total Directo Colones | O9: Total Directo Dólares
E10: TOTAL PRESUPUESTO | K10: =K11+K123+K182+K214+K309+K422+K504+K528+K560+K638+K667+K738+K743+K834+K886+K905 | L10: =L11+L123+L182+L214+L309+L422+L504+L528+L560+L638+L667+L738+L743+L834+L886+L905 | M10: =M11+M123+M182+M214+M309+M422+M504+M528+M560+M638+M667+M738+M743+M834+M886+M905 | N10: =N11+N123+N182+N214+N309+N422+N504+N528+N560+N638+N667+N738+N743+N834+N886+N905 | O10: =O11+O123+O182+O214+O309+O422+O504+O528+O560+O638+O667+O738+O743+O834+O886+O905
B11: 01 | D11: 1 | E11: FUNDACIONES | K11: =K12+K21+K58+K69 | L11: =L12+L21+L58+L69 | M11: =M12+M21+M58+M69 | N11: =N12+N21+N58+N69 | O11: =O12+O21+O58+O69
B12: 01-01 | D12: 1.1 | E12: OBRAS PRELIMINARES Y RELLENOS | F12: 1 | G12: gb | K12: =SUM(K13:K20) | L12: =SUM(L13:L20) | M12: =SUM(M13:M20) | N12: =SUM(N13:N20) | O12: =SUM(O13:O20)
A13: MAT | C13: =_xlfn.XLOOKUP(D13,'INSUMOS MAT '!B:B,'INSUMOS MAT '!C:C,"ERROR",0) | D13: MAT03-0014 | E13: =_xlfn.XLOOKUP(D13,'BASE DATOS PRECIOS '!B:B,'BASE DATOS PRECIOS '!C:C) | F13: 12.5 | G13: =+_xlfn.XLOOKUP(D13,'BASE DATOS PRECIOS '!B:B,'BASE DATOS PRECIOS '!D:D) | H13: =+_xlfn.XLOOKUP(E13,'BASE DATOS PRECIOS '!C:C,'BASE DATOS PRECIOS '!F:F) | K13: =+F13*H13 | L13: =+F13*I13 | M13: =+F13*J13 | N13: =SUM(K13:M13) | O13: =SUM(K13:M13)/tc
A14: MAT | C14: =_xlfn.XLOOKUP(D14,'INSUMOS MAT '!B:B,'INSUMOS MAT '!C:C,"ERROR",0) | D14: MAT08-0017 | E14: =_xlfn.XLOOKUP(D14,'BASE DATOS PRECIOS '!B:B,'BASE DATOS PRECIOS '!C:C) | F14: 2 | G14: =+_xlfn.XLOOKUP(D14,'BASE DATOS PRECIOS '!B:B,'BASE DATOS PRECIOS '!D:D) | H14: =+_xlfn.XLOOKUP(E14,'BASE DATOS PRECIOS '!C:C,'BASE DATOS PRECIOS '!F:F) | K14: =+F14*H14 | L14: =+F14*I14 | M14: =+F14*J14 | N14: =SUM(K14:M14) | O14: =SUM(K14:M14)/tc
A15: MAT | C15: =_xlfn.XLOOKUP(D15,'INSUMOS MAT '!B:B,'INSUMOS MAT '!C:C,"ERROR",0) | D15: MAT08-0029 | E15: =_xlfn.XLOOKUP(D15,'BASE DATOS PRECIOS '!B:B,'BASE DATOS PRECIOS '!C:C) | F15: 6 | G15: =+_xlfn.XLOOKUP(D15,'BASE DATOS PRECIOS '!B:B,'BASE DATOS PRECIOS '!D:D) | H15: =+_xlfn.XLOOKUP(E15,'BASE DATOS PRECIOS '!C:C,'BASE DATOS PRECIOS '!F:F) | K15: =+F15*H15 | L15: =+F15*I15 | M15: =+F15*J15 | N15: =SUM(K15:M15) | O15: =SUM(K15:M15)/tc
A16: MAT | C16: =_xlfn.XLOOKUP(D16,'INSUMOS MAT '!B:B,'INSUMOS MAT '!C:C,"ERROR",0) | D16: MAT08-0031 | E16: =_xlfn.XLOOKUP(D16,'BASE DATOS PRECIOS '!B:B,'BASE DATOS PRECIOS '!C:C) | F16: 3 | G16: =+_xlfn.XLOOKUP(D16,'BASE DATOS PRECIOS '!B:B,'BASE DATOS PRECIOS '!D:D) | H16: =+_xlfn.XLOOKUP(E16,'BASE DATOS PRECIOS '!C:C,'BASE DATOS PRECIOS '!F:F) | K16: =+F16*H16 | L16: =+F16*I16 | M16: =+F16*J16 | N16: =SUM(K16:M16) | O16: =SUM(K16:M16)/tc
A17: EQUIP | D17: BACK HOE | E17: =+_xlfn.XLOOKUP(D17,'BASE DATOS EQUIPOS Y SUBCONTRAT'!A:A,'BASE DATOS EQUIPOS Y SUBCONTRAT'!B:B) | F17: 1 | G17: =+_xlfn.XLOOKUP(D17,'BASE DATOS EQUIPOS Y SUBCONTRAT'!A:A,'BASE DATOS EQUIPOS Y SUBCONTRAT'!C:C) | H17: 0 | J17: =+_xlfn.XLOOKUP(D17,'BASE DATOS EQUIPOS Y SUBCONTRAT'!A:A,'BASE DATOS EQUIPOS Y SUBCONTRAT'!E:E) | K17: =+F17*H17 | L17: =+F17*I17 | M17: =+F17*J17 | N17: =SUM(K17:M17) | O17: =SUM(K17:M17)/tc
A18: EQUIP | D18: COMPACTADOR | E18: =+_xlfn.XLOOKUP(D18,'BASE DATOS EQUIPOS Y SUBCONTRAT'!A:A,'BASE DATOS EQUIPOS Y SUBCONTRAT'!B:B) | F18: 3 | G18: =+_xlfn.XLOOKUP(D18,'BASE DATOS EQUIPOS Y SUBCONTRAT'!A:A,'BASE DATOS EQUIPOS Y SUBCONTRAT'!C:C) | H18: 0 | J18: =+_xlfn.XLOOKUP(D18,'BASE DATOS EQUIPOS Y SUBCONTRAT'!A:A,'BASE DATOS EQUIPOS Y SUBCONTRAT'!E:E) | K18: =+F18*H18 | L18: =+F18*I18 | M18: =+F18*J18 | N18: =SUM(K18:M18) | O18: =SUM(K18:M18)/tc
A19: MO | B19: 01-01-01 | D19: OPERARIO | E19: =+_xlfn.XLOOKUP(D19,'BASE DATOS MANO DE OBRA'!A:A,'BASE DATOS MANO DE OBRA'!B:B) | F19: 38.5 | G19: =+_xlfn.XLOOKUP(D19,'BASE DATOS MANO DE OBRA'!A:A,'BASE DATOS MANO DE OBRA'!C:C) | H19: 0 | I19: =+_xlfn.XLOOKUP(D19,'BASE DATOS MANO DE OBRA'!A:A,'BASE DATOS MANO DE OBRA'!E:E) | J19: 0 | K19: =+F19*H19 | L19: =+F19*I19 | M19: =+F19*J19 | N19: =SUM(K19:M19) | O19: =SUM(K19:M19)/tc
A20: MO | B20: 01-01-01 | D20: AYUDANTE | E20: =+_xlfn.XLOOKUP(D20,'BASE DATOS MANO DE OBRA'!A:A,'BASE DATOS MANO DE OBRA'!B:B) | F20: 38.5 | G20: =+_xlfn.XLOOKUP(D20,'BASE DATOS MANO DE OBRA'!A:A,'BASE DATOS MANO DE OBRA'!C:C) | H20: 0 | I20: =+_xlfn.XLOOKUP(D20,'BASE DATOS MANO DE OBRA'!A:A,'BASE DATOS MANO DE OBRA'!E:E) | J20: 0 | K20: =+F20*H20 | L20: =+F20*I20 | M20: =+F20*J20 | N20: =SUM(K20:M20) | O20: =SUM(K20:M20)/tc
B21: 01-02 | D21: 1.2 | E21: EXCAVACIÓN Y TUBERÍAS MECÁNICAS (INCLUYE ACOMETIDA) | F21: 1 | G21: gb | K21: =SUM(K23:K57) | L21: =SUM(L23:L57) | M21: =SUM(M23:M57) | N21: =SUM(N23:N57) | O21: =SUM(O23:O57)
E22: TUBERÍA MECÁNICA
A23: MAT | C23: =_xlfn.XLOOKUP(D23,'INSUMOS MAT '!B:B,'INSUMOS MAT '!C:C,"ERROR",0) | D23: MAT19-0100 | E23: =+_xlfn.XLOOKUP(D23,'BASE DATOS PRECIOS '!B:B,'BASE DATOS PRECIOS '!C:C) | F23: 3 | G23: =+_xlfn.XLOOKUP(D23,'BASE DATOS PRECIOS '!B:B,'BASE DATOS PRECIOS '!D:D) | H23: =+_xlfn.XLOOKUP(E23,'BASE DATOS PRECIOS '!C:C,'BASE DATOS PRECIOS '!F:F) | K23: =+F23*H23 | L23: =+F23*I23 | M23: =+F23*J23 | N23: =SUM(K23:M23) | O23: =SUM(K23:M23)/tc
A24: MAT | C24: =_xlfn.XLOOKUP(D24,'INSUMOS MAT '!B:B,'INSUMOS MAT '!C:C,"ERROR",0) | D24: MAT19-0095 | E24: =+_xlfn.XLOOKUP(D24,'BASE DATOS PRECIOS '!B:B,'BASE DATOS PRECIOS '!C:C) | F24: 1 | G24: =+_xlfn.XLOOKUP(D24,'BASE DATOS PRECIOS '!B:B,'BASE DATOS PRECIOS '!D:D) | H24: =+_xlfn.XLOOKUP(E24,'BASE DATOS PRECIOS '!C:C,'BASE DATOS PRECIOS '!F:F) | K24: =+F24*H24 | L24: =+F24*I24 | M24: =+F24*J24 | N24: =SUM(K24:M24) | O24: =SUM(K24:M24)/tc
A25: MAT | C25: =_xlfn.XLOOKUP(D25,'INSUMOS MAT '!B:B,'INSUMOS MAT '!C:C,"ERROR",0) | D25: MAT19-0094 | E25: =+_xlfn.XLOOKUP(D25,'BASE DATOS PRECIOS '!B:B,'BASE DATOS PRECIOS '!C:C) | F25: 1 | G25: =+_xlfn.XLOOKUP(D25,'BASE DATOS PRECIOS '!B:B,'BASE DATOS PRECIOS '!D:D) | H25: =+_xlfn.XLOOKUP(E25,'BASE DATOS PRECIOS '!C:C,'BASE DATOS PRECIOS '!F:F) | K25: =+F25*H25 | L25: =+F25*I25 | M25: =+F25*J25 | N25: =SUM(K25:M25) | O25: =SUM(K25:M25)/tc
A26: MAT | C26: =_xlfn.XLOOKUP(D26,'INSUMOS MAT '!B:B,'INSUMOS MAT '!C:C,"ERROR",0) | D26: MAT19-0081 | E26: =+_xlfn.XLOOKUP(D26,'BASE DATOS PRECIOS '!B:B,'BASE DATOS PRECIOS '!C:C) | F26: 2 | G26: =+_xlfn.XLOOKUP(D26,'BASE DATOS PRECIOS '!B:B,'BASE DATOS PRECIOS '!D:D) | H26: =+_xlfn.XLOOKUP(E26,'BASE DATOS PRECIOS '!C:C,'BASE DATOS PRECIOS '!F:F) | K26: =+F26*H26 | L26: =+F26*I26 | M26: =+F26*J26 | N26: =SUM(K26:M26) | O26: =SUM(K26:M26)/tc
A27: MAT | C27: =_xlfn.XLOOKUP(D27,'INSUMOS MAT '!B:B,'INSUMOS MAT '!C:C,"ERROR",0) | D27: MAT19-0044 | E27: =+_xlfn.XLOOKUP(D27,'BASE DATOS PRECIOS '!B:B,'BASE DATOS PRECIOS '!C:C) | F27: 4 | G27: =+_xlfn.XLOOKUP(D27,'BASE DATOS PRECIOS '!B:B,'BASE DATOS PRECIOS '!D:D) | H27: =+_xlfn.XLOOKUP(E27,'BASE DATOS PRECIOS '!C:C,'BASE DATOS PRECIOS '!F:F) | K27: =+F27*H27 | L27: =+F27*I27 | M27: =+F27*J27 | N27: =SUM(K27:M27) | O27: =SUM(K27:M27)/tc
A28: MAT | C28: =_xlfn.XLOOKUP(D28,'INSUMOS MAT '!B:B,'INSUMOS MAT '!C:C,"ERROR",0) | D28: MAT19-0118 | E28: =+_xlfn.XLOOKUP(D28,'BASE DATOS PRECIOS '!B:B,'BASE DATOS PRECIOS '!C:C) | F28: 5 | G28: =+_xlfn.XLOOKUP(D28,'BASE DATOS PRECIOS '!B:B,'BASE DATOS PRECIOS '!D:D) | H28: =+_xlfn.XLOOKUP(E28,'BASE DATOS PRECIOS '!C:C,'BASE DATOS PRECIOS '!F:F) | K28: =+F28*H28 | L28: =+F28*I28 | M28: =+F28*J28 | N28: =SUM(K28:M28) | O28: =SUM(K28:M28)/tc
A29: MAT | C29: =_xlfn.XLOOKUP(D29,'INSUMOS MAT '!B:B,'INSUMOS MAT '!C:C,"ERROR",0) | D29: MAT19-0024 | E29: =+_xlfn.XLOOKUP(D29,'BASE DATOS PRECIOS '!B:B,'BASE DATOS PRECIOS '!C:C) | F29: 2 | G29: =+_xlfn.XLOOKUP(D29,'BASE DATOS PRECIOS '!B:B,'BASE DATOS PRECIOS '!D:D) | H29: =+_xlfn.XLOOKUP(E29,'BASE DATOS PRECIOS '!C:C,'BASE DATOS PRECIOS '!F:F) | K29: =+F29*H29 | L29: =+F29*I29 | M29: =+F29*J29 | N29: =SUM(K29:M29) | O29: =SUM(K29:M29)/tc
A30: MAT | C30: =_xlfn.XLOOKUP(D30,'INSUMOS MAT '!B:B,'INSUMOS MAT '!C:C,"ERROR",0) | D30: MAT19-0049 | E30: =+_xlfn.XLOOKUP(D30,'BASE DATOS PRECIOS '!B:B,'BASE DATOS PRECIOS '!C:C) | F30: 2 | G30: =+_xlfn.XLOOKUP(D30,'BASE DATOS PRECIOS '!B:B,'BASE DATOS PRECIOS '!D:D) | H30: =+_xlfn.XLOOKUP(E30,'BASE DATOS PRECIOS '!C:C,'BASE DATOS PRECIOS '!F:F) | K30: =+F30*H30 | L30: =+F30*I30 | M30: =+F30*J30 | N30: =SUM(K30:M30) | O30: =SUM(K30:M30)/tc
A31: MAT | C31: =_xlfn.XLOOKUP(D31,'INSUMOS MAT '!B:B,'INSUMOS MAT '!C:C,"ERROR",0) | D31: MAT19-0055 | E31: =+_xlfn.XLOOKUP(D31,'BASE DATOS PRECIOS '!B:B,'BASE DATOS PRECIOS '!C:C) | F31: 2 | G31: =+_xlfn.XLOOKUP(D31,'BASE DATOS PRECIOS '!B:B,'BASE DATOS PRECIOS '!D:D) | H31: =+_xlfn.XLOOKUP(E31,'BASE DATOS PRECIOS '!C:C,'BASE DATOS PRECIOS '!F:F) | K31: =+F31*H31 | L31: =+F31*I31 | M31: =+F31*J31 | N31: =SUM(K31:M31) | O31: =SUM(K31:M31)/tc
A32: MAT | C32: =_xlfn.XLOOKUP(D32,'INSUMOS MAT '!B:B,'INSUMOS MAT '!C:C,"ERROR",0) | D32: MAT19-0112 | E32: =+_xlfn.XLOOKUP(D32,'BASE DATOS PRECIOS '!B:B,'BASE DATOS PRECIOS '!C:C) | F32: 6 | G32: =+_xlfn.XLOOKUP(D32,'BASE DATOS PRECIOS '!B:B,'BASE DATOS PRECIOS '!D:D) | H32: =+_xlfn.XLOOKUP(E32,'BASE DATOS PRECIOS '!C:C,'BASE DATOS PRECIOS '!F:F) | K32: =+F32*H32 | L32: =+F32*I32 | M32: =+F32*J32 | N32: =SUM(K32:M32) | O32: =SUM(K32:M32)/tc
A33: MAT | C33: =_xlfn.XLOOKUP(D33,'INSUMOS MAT '!B:B,'INSUMOS MAT '!C:C,"ERROR",0) | D33: MAT19-0126 | E33: =+_xlfn.XLOOKUP(D33,'BASE DATOS PRECIOS '!B:B,'BASE DATOS PRECIOS '!C:C) | F33: 2 | G33: =+_xlfn.XLOOKUP(D33,'BASE DATOS PRECIOS '!B:B,'BASE DATOS PRECIOS '!D:D) | H33: =+_xlfn.XLOOKUP(E33,'BASE DATOS PRECIOS '!C:C,'BASE DATOS PRECIOS '!F:F) | K33: =+F33*H33 | L33: =+F33*I33 | M33: =+F33*J33 | N33: =SUM(K33:M33) | O33: =SUM(K33:M33)/tc
A34: MAT | C34: =_xlfn.XLOOKUP(D34,'INSUMOS MAT '!B:B,'INSUMOS MAT '!C:C,"ERROR",0) | D34: MAT19-0063 | E34: =+_xlfn.XLOOKUP(D34,'BASE DATOS PRECIOS '!B:B,'BASE DATOS PRECIOS '!C:C) | F34: 4 | G34: =+_xlfn.XLOOKUP(D34,'BASE DATOS PRECIOS '!B:B,'BASE DATOS PRECIOS '!D:D) | H34: =+_xlfn.XLOOKUP(E34,'BASE DATOS PRECIOS '!C:C,'BASE DATOS PRECIOS '!F:F) | K34: =+F34*H34 | L34: =+F34*I34 | M34: =+F34*J34 | N34: =SUM(K34:M34) | O34: =SUM(K34:M34)/tc
A35: MAT | C35: =_xlfn.XLOOKUP(D35,'INSUMOS MAT '!B:B,'INSUMOS MAT '!C:C,"ERROR",0) | D35: MAT19-0124 | E35: =+_xlfn.XLOOKUP(D35,'BASE DATOS PRECIOS '!B:B,'BASE DATOS PRECIOS '!C:C) | F35: 2 | G35: =+_xlfn.XLOOKUP(D35,'BASE DATOS PRECIOS '!B:B,'BASE DATOS PRECIOS '!D:D) | H35: =+_xlfn.XLOOKUP(E35,'BASE DATOS PRECIOS '!C:C,'BASE DATOS PRECIOS '!F:F) | K35: =+F35*H35 | L35: =+F35*I35 | M35: =+F35*J35 | N35: =SUM(K35:M35) | O35: =SUM(K35:M35)/tc
A36: MAT | C36: =_xlfn.XLOOKUP(D36,'INSUMOS MAT '!B:B,'INSUMOS MAT '!C:C,"ERROR",0) | D36: MAT19-0041 | E36: =+_xlfn.XLOOKUP(D36,'BASE DATOS PRECIOS '!B:B,'BASE DATOS PRECIOS '!C:C) | F36: 1 | G36: =+_xlfn.XLOOKUP(D36,'BASE DATOS PRECIOS '!B:B,'BASE DATOS PRECIOS '!D:D) | H36: =+_xlfn.XLOOKUP(E36,'BASE DATOS PRECIOS '!C:C,'BASE DATOS PRECIOS '!F:F) | K36: =+F36*H36 | L36: 0 | M36: 0 | N36: =SUM(K36:M36) | O36: 1266.5567
A37: MAT | C37: =_xlfn.XLOOKUP(D37,'INSUMOS MAT '!B:B,'INSUMOS MAT '!C:C,"ERROR",0) | D37: MAT19-0017 | E37: =+_xlfn.XLOOKUP(D37,'BASE DATOS PRECIOS '!B:B,'BASE DATOS PRECIOS '!C:C) | F37: 1 | G37: =+_xlfn.XLOOKUP(D37,'BASE DATOS PRECIOS '!B:B,'BASE DATOS PRECIOS '!D:D) | H37: =+_xlfn.XLOOKUP(E37,'BASE DATOS PRECIOS '!C:C,'BASE DATOS PRECIOS '!F:F) | K37: =+F37*H37 | L37: =+F37*I37 | M37: =+F37*J37 | N37: =SUM(K37:M37) | O37: =SUM(K37:M37)/tc
A38: MAT | C38: =_xlfn.XLOOKUP(D38,'INSUMOS MAT '!B:B,'INSUMOS MAT '!C:C,"ERROR",0) | D38: MAT19-0096 | E38: =+_xlfn.XLOOKUP(D38,'BASE DATOS PRECIOS '!B:B,'BASE DATOS PRECIOS '!C:C) | F38: 1 | G38: =+_xlfn.XLOOKUP(D38,'BASE DATOS PRECIOS '!B:B,'BASE DATOS PRECIOS '!D:D) | H38: =+_xlfn.XLOOKUP(E38,'BASE DATOS PRECIOS '!C:C,'BASE DATOS PRECIOS '!F:F) | K38: =+F38*H38 | L38: =+F38*I38 | M38: =+F38*J38 | N38: =SUM(K38:M38) | O38: =SUM(K38:M38)/tc
A39: MAT | C39: =_xlfn.XLOOKUP(D39,'INSUMOS MAT '!B:B,'INSUMOS MAT '!C:C,"ERROR",0) | D39: MAT19-0125 | E39: =+_xlfn.XLOOKUP(D39,'BASE DATOS PRECIOS '!B:B,'BASE DATOS PRECIOS '!C:C) | F39: 1 | G39: =+_xlfn.XLOOKUP(D39,'BASE DATOS PRECIOS '!B:B,'BASE DATOS PRECIOS '!D:D) | H39: =+_xlfn.XLOOKUP(E39,'BASE DATOS PRECIOS '!C:C,'BASE DATOS PRECIOS '!F:F) | K39: =+F39*H39 | L39: =+F39*I39 | M39: =+F39*J39 | N39: =SUM(K39:M39) | O39: =SUM(K39:M39)/tc
A40: MAT | C40: =_xlfn.XLOOKUP(D40,'INSUMOS MAT '!B:B,'INSUMOS MAT '!C:C,"ERROR",0) | D40: MAT03-0002 | E40: =+_xlfn.XLOOKUP(D40,'BASE DATOS PRECIOS '!B:B,'BASE DATOS PRECIOS '!C:C) | F40: 0.5 | G40: =+_xlfn.XLOOKUP(D40,'BASE DATOS PRECIOS '!B:B,'BASE DATOS PRECIOS '!D:D) | H40: =+_xlfn.XLOOKUP(E40,'BASE DATOS PRECIOS '!C:C,'BASE DATOS PRECIOS '!F:F) | K40: =+F40*H40 | L40: =+F40*I40 | M40: =+F40*J40 | N40: =SUM(K40:M40) | O40: =SUM(K40:M40)/tc
A41: MAT | C41: =_xlfn.XLOOKUP(D41,'INSUMOS MAT '!B:B,'INSUMOS MAT '!C:C,"ERROR",0) | D41: MAT08-0091 | E41: =+_xlfn.XLOOKUP(D41,'BASE DATOS PRECIOS '!B:B,'BASE DATOS PRECIOS '!C:C) | F41: 1 | G41: =+_xlfn.XLOOKUP(D41,'BASE DATOS PRECIOS '!B:B,'BASE DATOS PRECIOS '!D:D) | H41: =+_xlfn.XLOOKUP(E41,'BASE DATOS PRECIOS '!C:C,'BASE DATOS PRECIOS '!F:F) | K41: =+F41*H41 | L41: =+F41*I41 | M41: =+F41*J41 | N41: =SUM(K41:M41) | O41: =SUM(K41:M41)/tc
A42: MAT | C42: =_xlfn.XLOOKUP(D42,'INSUMOS MAT '!B:B,'INSUMOS MAT '!C:C,"ERROR",0) | D42: MAT08-0034 | E42: =+_xlfn.XLOOKUP(D42,'BASE DATOS PRECIOS '!B:B,'BASE DATOS PRECIOS '!C:C) | F42: 1 | G42: =+_xlfn.XLOOKUP(D42,'BASE DATOS PRECIOS '!B:B,'BASE DATOS PRECIOS '!D:D) | H42: =+_xlfn.XLOOKUP(E42,'BASE DATOS PRECIOS '!C:C,'BASE DATOS PRECIOS '!F:F) | K42: =+F42*H42 | L42: =+F42*I42 | M42: =+F42*J42 | N42: =SUM(K42:M42) | O42: =SUM(K42:M42)/tc
...

Sheet GRAFICO 
A3: N° | B3: DESCRIPCION | C3: CANTIDAD | D3: UNIDAD | E3: TOTAL MATERIAL | F3: TOTAL MANO DE OBRA | G3: TOTAL SUB/EQUIPOS | H3: TOTAL DIRECTO COLONES | I3: TOTAL DÓLARES | J3: % MATERIAL | K3: % MANO DE OBRA | L3: % SUB/EQUIPOS | M3: % TOTAL DIRECTO
A4: 1 | B4: FUNDACIONES | C4: 1 | D4: Global | E4: =DESGLOSE!E4 | F4: =DESGLOSE!F4 | G4: =DESGLOSE!G4 | H4: =DESGLOSE!H4 | I4: =DESGLOSE!I4 | J4: =E4/$E$21 | K4: =F4/$F$21 | L4: =G4/$G$21 | M4: =H4/$H$21
A5: 2 | B5: SUPERESTRUCTURA PRIMER NIVEL | C5: 1 | D5: Global | E5: =DESGLOSE!E9 | F5: =DESGLOSE!F9 | G5: =DESGLOSE!G9 | H5: =DESGLOSE!H9 | I5: =DESGLOSE!I9 | J5: =E5/$E$21 | K5: =F5/$F$21 | L5: =G5/$G$21 | M5: =H5/$H$21
A6: 3 | B6: SUPERESTRUCTURA SEGUNDO NIVEL | C6: 1 | D6: Global | E6: =DESGLOSE!E13 | F6: =DESGLOSE!F13 | G6: =DESGLOSE!G13 | H6: =DESGLOSE!H13 | I6: =DESGLOSE!I13 | J6: =E6/$E$21 | K6: =F6/$F$21 | L6: =G6/$G$21 | M6: =H6/$H$21
A7: 4 | B7: OTROS GRIS | C7: 1 | D7: Global | E7: =DESGLOSE!E16 | F7: =DESGLOSE!F16 | G7: =DESGLOSE!G16 | H7: =DESGLOSE!H16 | I7: =DESGLOSE!I16 | J7: =E7/$E$21 | K7: =F7/$F$21 | L7: =G7/$G$21 | M7: =H7/$H$21
A8: 5 | B8: ESTRUCTURA METÁLICA Y CUBIERTAS | C8: 1 | D8: Global | E8: =DESGLOSE!E20 | F8: =DESGLOSE!F20 | G8: =DESGLOSE!G20 | H8: =DESGLOSE!H20 | I8: =DESGLOSE!I20 | J8: =E8/$E$21 | K8: =F8/$F$21 | L8: =G8/$G$21 | M8: =H8/$H$21
A9: 6 | B9: LIVIANO | C9: 1 | D9: Global | E9: =DESGLOSE!E29 | F9: =DESGLOSE!F29 | G9: =DESGLOSE!G29 | H9: =DESGLOSE!H29 | I9: =DESGLOSE!I29 | J9: =E9/$E$21 | K9: =F9/$F$21 | L9: =G9/$G$21 | M9: =H9/$H$21
A10: 7 | B10: REPELLOS | C10: 1 | D10: Global | E10: =DESGLOSE!E32 | F10: =DESGLOSE!F32 | G10: =DESGLOSE!G32 | H10: =DESGLOSE!H32 | I10: =DESGLOSE!I32 | J10: =E10/$E$21 | K10: =F10/$F$21 | L10: =G10/$G$21 | M10: =H10/$H$21
A11: 8 | B11: ENCHAPES | C11: 1 | D11: Global | E11: =DESGLOSE!E35 | F11: =DESGLOSE!F35 | G11: =DESGLOSE!G35 | H11: =DESGLOSE!H35 | I11: =DESGLOSE!I35 | J11: =E11/$E$21 | K11: =F11/$F$21 | L11: =G11/$G$21 | M11: =H11/$H$21
A12: 9 | B12: MUEBLES Y PUERTAS | C12: 1 | D12: Global | E12: =DESGLOSE!E37 | F12: =DESGLOSE!F37 | G12: =DESGLOSE!G37 | H12: =DESGLOSE!H37 | I12: =DESGLOSE!I37 | J12: =E12/$E$21 | K12: =F12/$F$21 | L12: =G12/$G$21 | M12: =H12/$H$21
A13: 10 | B13: OBRAS ADICIONALES | C13: 1 | D13: Global | E13: =DESGLOSE!E40 | F13: =DESGLOSE!F40 | G13: =DESGLOSE!G40 | H13: =DESGLOSE!H40 | I13: =DESGLOSE!I40 | J13: =E13/$E$21 | K13: =F13/$F$21 | L13: =G13/$G$21 | M13: =H13/$H$21
A14: 11 | B14: ACABADOS | C14: 1 | D14: Global | E14: =DESGLOSE!E44 | F14: =DESGLOSE!F44 | G14: =DESGLOSE!G44 | H14: =DESGLOSE!H44 | I14: =DESGLOSE!I44 | J14: =E14/$E$21 | K14: =F14/$F$21 | L14: =G14/$G$21 | M14: =H14/$H$21
A15: 12 | B15: VENTANERIA | C15: 1 | D15: Global | E15: =DESGLOSE!E49 | F15: =DESGLOSE!F49 | G15: =DESGLOSE!G49 | H15: =DESGLOSE!H49 | I15: =DESGLOSE!I49 | J15: =E15/$E$21 | K15: =F15/$F$21 | L15: =G15/$G$21 | M15: =H15/$H$21
A16: 13 | B16: ELÉCTRICO | C16: 1 | D16: Global | E16: =DESGLOSE!E51 | F16: =DESGLOSE!F51 | G16: =DESGLOSE!G51 | H16: =DESGLOSE!H51 | I16: =DESGLOSE!I51 | J16: =E16/$E$21 | K16: =F16/$F$21 | L16: =G16/$G$21 | M16: =H16/$H$21
A17: 14 | B17: MECÁNICO | C17: 1 | D17: Global | E17: =DESGLOSE!E61 | F17: =DESGLOSE!F61 | G17: =DESGLOSE!G61 | H17: =DESGLOSE!H61 | I17: =DESGLOSE!I61 | J17: =E17/$E$21 | K17: =F17/$F$21 | L17: =G17/$G$21 | M17: =H17/$H$21
A18: 15 | B18: ALQUILERES | C18: 1 | D18: Global | E18: =DESGLOSE!E65 | F18: =DESGLOSE!F65 | G18: =DESGLOSE!G65 | H18: =DESGLOSE!H65 | I18: =DESGLOSE!I65 | J18: =E18/$E$21 | K18: =F18/$F$21 | L18: =G18/$G$21 | M18: =H18/$H$21
A19: 16 | B19: MANO DE OBRA | C19: 1 | D19: Global | E19: =DESGLOSE!E67 | F19: =DESGLOSE!F67 | G19: =DESGLOSE!G67 | H19: =DESGLOSE!H67 | I19: =DESGLOSE!I67 | J19: =E19/$E$21 | K19: =F19/$F$21 | L19: =G19/$G$21 | M19: =H19/$H$21
L20: =G20/$G$21 | M20: =H20/$H$21
D21: TOTAL | E21: =SUM(E4:E20) | F21: =SUM(F4:F20) | G21: =SUM(G4:G20) | H21: =SUM(H4:H20) | I21: =SUM(I4:I20) | J21: =SUM(J4:J20) | K21: =SUM(K4:K20) | L21: =SUM(L4:L20) | M21: =SUM(M4:M20)
G22: VERIFICACION | H22: =H21-'IKARIA TECHO'!N10

Sheet DESGLOSE
A3: N° | B3: DESCRIPCION | C3: CANTIDAD | D3: UNIDAD | E3: TOTAL MATERIAL | F3: TOTAL MANO DE OBRA | G3: TOTAL SUB/EQUIPOS | H3: TOTAL DIRECTO COLONES | I3: TOTAL DÓLARES
A4: 1 | B4: FUNDACIONES | C4: 1 | D4: Global | E4: =SUM(E5:E8) | F4: =SUM(F5:F8) | G4: =SUM(G5:G8) | H4: =SUM(H5:H8) | I4: =SUM(I5:I8)
A5: 1.1 | B5: OBRAS PRELIMINARES Y RELLENOS | C5: 1 | D5: Global | E5: ='IKARIA TECHO'!K12 | F5: ='IKARIA TECHO'!L12 | G5: ='IKARIA TECHO'!M12 | H5: ='IKARIA TECHO'!N12 | I5: ='IKARIA TECHO'!O12
A6: 1.2 | B6: EXCAVACIÓN Y TUBERÍAS MECÁNICAS (INCLUYE ACOMETIDA) | C6: 1 | D6: Global | E6: ='IKARIA TECHO'!K21 | F6: ='IKARIA TECHO'!L21 | G6: ='IKARIA TECHO'!M21 | H6: ='IKARIA TECHO'!N21 | I6: ='IKARIA TECHO'!O21
A7: 1.3 | B7: SELLO DE CONCRETO | C7: 1 | D7: Global | E7: ='IKARIA TECHO'!K58 | F7: ='IKARIA TECHO'!L58 | G7: ='IKARIA TECHO'!M58 | H7: ='IKARIA TECHO'!N58 | I7: ='IKARIA TECHO'!O58
A8: 1.4 | B8: LOSA FLOTANTE (ACERO, ELECTROMECANICOS, CONCRETO) | C8: 1 | D8: Global | E8: ='IKARIA TECHO'!K69 | F8: ='IKARIA TECHO'!L69 | G8: ='IKARIA TECHO'!M69 | H8: ='IKARIA TECHO'!N69 | I8: ='IKARIA TECHO'!O69
A9: 2 | B9: SUPERESTRUCTURA PRIMER NIVEL | C9: 1 | D9: Global | E9: =SUM(E10:E12) | F9: =SUM(F10:F12) | G9: =SUM(G10:G12) | H9: =SUM(H10:H12) | I9: =SUM(I10:I12)
A10: 2.1 | B10: ACERO EN PAREDES MUROS N1 (ELECTROMECANICO) | C10: 1 | D10: Global | E10: ='IKARIA TECHO'!K124 | F10: ='IKARIA TECHO'!L124 | G10: ='IKARIA TECHO'!M124 | H10: ='IKARIA TECHO'!N124 | I10: ='IKARIA TECHO'!O124
A11: 2.2 | B11: PAREDES, MUROS, ENTREPISO N1 (FORMALETA, CONCRETO, DESENCOFRADO) | C11: 1 | D11: Global | E11: ='IKARIA TECHO'!K154 | F11: ='IKARIA TECHO'!L154 | G11: ='IKARIA TECHO'!M154 | H11: ='IKARIA TECHO'!N154 | I11: ='IKARIA TECHO'!O154
A12: 2.3 | B12: MAMPOSTERIA | C12: 1 | D12: Global | E12: ='IKARIA TECHO'!K169 | F12: ='IKARIA TECHO'!L169 | G12: ='IKARIA TECHO'!M169 | H12: ='IKARIA TECHO'!N169 | I12: ='IKARIA TECHO'!O169
A13: 3 | B13: SUPERESTRUCTURA SEGUNDO NIVEL | C13: 1 | D13: Global | E13: =SUM(E14:E15) | F13: =SUM(F14:F15) | G13: =SUM(G14:G15) | H13: =SUM(H14:H15) | I13: =SUM(I14:I15)
A14: 3.1 | B14: ACERO EN PAREDES MUROS N2 (ELECTROMECANICO) | C14: 1 | D14: Global | E14: ='IKARIA TECHO'!K183 | F14: ='IKARIA TECHO'!L183 | G14: ='IKARIA TECHO'!M183 | H14: ='IKARIA TECHO'!N183 | I14: ='IKARIA TECHO'!O183
A15: 3.2 | B15: PAREDES, MUROS, ENTREPISO N2 (FORMALETA, CONCRETO, DESENCOFRADO) | C15: 1 | D15: Global | E15: ='IKARIA TECHO'!K201 | F15: ='IKARIA TECHO'!L201 | G15: ='IKARIA TECHO'!M201 | H15: ='IKARIA TECHO'!N201 | I15: ='IKARIA TECHO'!O201
A16: 4 | B16: OTROS GRIS | C16: 1 | D16: Global | E16: =SUM(E17:E19) | F16: =SUM(F17:F19) | G16: =SUM(G17:G19) | H16: =SUM(H17:H19) | I16: =SUM(I17:I19)
A17: 4.1 | B17: GRADAS EN CONCRETO | C17: 1 | D17: Global | E17: ='IKARIA TECHO'!K215 | F17: ='IKARIA TECHO'!L215 | G17: ='IKARIA TECHO'!M215 | H17: ='IKARIA TECHO'!N215 | I17: ='IKARIA TECHO'!O215
A18: 4.2 | B18: COLUMNAS (MEDIDOR) | C18: 1 | D18: Global | E18: ='IKARIA TECHO'!K253 | F18: ='IKARIA TECHO'!L253 | G18: ='IKARIA TECHO'!M253 | H18: ='IKARIA TECHO'!N253 | I18: ='IKARIA TECHO'!O253
A19: 4.3 | B19: CHORREA DE COCHERAS Y PILAS | C19: 1 | D19: Global | E19: ='IKARIA TECHO'!K288 | F19: ='IKARIA TECHO'!L288 | G19: ='IKARIA TECHO'!M288 | H19: ='IKARIA TECHO'!N288 | I19: ='IKARIA TECHO'!O288
A20: 5 | B20: ESTRUCTURA METÁLICA Y CUBIERTAS | C20: 1 | D20: Global | E20: =SUM(E21:E28) | F20: =SUM(F21:F28) | G20: =SUM(G21:G28) | H20: =SUM(H21:H28) | I20: =SUM(I21:I28)
A21: 5.1 | B21: ESTRUCTURA TECHO CASA | C21: 1 | D21: Global | E21: ='IKARIA TECHO'!K310 | F21: ='IKARIA TECHO'!L310 | G21: ='IKARIA TECHO'!M310 | H21: ='IKARIA TECHO'!N310 | I21: ='IKARIA TECHO'!O310
A22: 5.2 | B22: ESTRUCTURA TECHO COCHERA | C22: 1 | D22: Global | E22: ='IKARIA TECHO'!K327 | F22: ='IKARIA TECHO'!L327 | G22: ='IKARIA TECHO'!M327 | H22: ='IKARIA TECHO'!N327 | I22: ='IKARIA TECHO'!O327
A23: 5.3 | B23: CUBIERTA TECHO CASA | C23: 1 | D23: Global | E23: ='IKARIA TECHO'!K348 | F23: ='IKARIA TECHO'!L348 | G23: ='IKARIA TECHO'!M348 | H23: ='IKARIA TECHO'!N348 | I23: ='IKARIA TECHO'!O348
A24: 5.4 | B24: CUBIERTA TECHO COCHERA | C24: 1 | D24: Global | E24: ='IKARIA TECHO'!K356 | F24: ='IKARIA TECHO'!L356 | G24: ='IKARIA TECHO'!M356 | H24: ='IKARIA TECHO'!N356 | I24: ='IKARIA TECHO'!O356
A25: 5.5 | B25: HOJALATERIA Y CANOAS | C25: 1 | D25: Global | E25: ='IKARIA TECHO'!K368 | F25: ='IKARIA TECHO'!L368 | G25: ='IKARIA TECHO'!M368 | H25: ='IKARIA TECHO'!N368 | I25: ='IKARIA TECHO'!O368
A26: 5.6 | B26: GRADAS ESTRUCTURA, PINTADO Y ACABADO | C26: 1 | D26: Global | E26: ='IKARIA TECHO'!K380 | F26: ='IKARIA TECHO'!L380 | G26: ='IKARIA TECHO'!M380 | H26: ='IKARIA TECHO'!N380 | I26: ='IKARIA TECHO'!O380
A27: 5.7 | B27: BARANDA DE GRADAS (N2) | C27: 1 | D27: Global | E27: ='IKARIA TECHO'!K394 | F27: ='IKARIA TECHO'!L394 | G27: ='IKARIA TECHO'!M394 | H27: ='IKARIA TECHO'!N394 | I27: ='IKARIA TECHO'!O394
A28: 5.8 | B28: ESTRUCTURA METÁLICA INTERNA | C28: 1 | D28: Global | E28: ='IKARIA TECHO'!K408 | F28: ='IKARIA TECHO'!L408 | G28: ='IKARIA TECHO'!M408 | H28: ='IKARIA TECHO'!N408 | I28: ='IKARIA TECHO'!O408
A29: 6 | B29: LIVIANO | C29: 1 | D29: Global | E29: =SUM(E30:E31) | F29: =SUM(F30:F31) | G29: =SUM(G30:G31) | H29: =SUM(H30:H31) | I29: =SUM(I30:I31)
A30: 6.1 | B30: LIVIANO EXTERIORES | C30: 1 | D30: Global | E30: ='IKARIA TECHO'!K423 | F30: ='IKARIA TECHO'!L423 | G30: ='IKARIA TECHO'!M423 | H30: ='IKARIA TECHO'!N423 | I30: ='IKARIA TECHO'!O423
A31: 6.2 | B31: LIVIANO INTERIORES ( PAREDES LIVIANAS Y CIELOS) | C31: 1 | D31: Global | E31: ='IKARIA TECHO'!K455 | F31: ='IKARIA TECHO'!L455 | G31: ='IKARIA TECHO'!M455 | H31: ='IKARIA TECHO'!N455 | I31: ='IKARIA TECHO'!O455
A32: 7 | B32: REPELLOS | C32: 1 | D32: Global | E32: =SUM(E33:E34) | F32: =SUM(F33:F34) | G32: =SUM(G33:G34) | H32: =SUM(H33:H34) | I32: =SUM(I33:I34)
A33: 7.1 | B33: REPELLOS INTERNO Y EXTERNO | C33: 1 | D33: Global | E33: ='IKARIA TECHO'!K505 | F33: ='IKARIA TECHO'!L505 | G33: ='IKARIA TECHO'!M505 | H33: ='IKARIA TECHO'!N505 | I33: ='IKARIA TECHO'!O505
A34: 7.2 | B34: EMPASTE | C34: 1 | D34: Global | E34: ='IKARIA TECHO'!K521 | F34: ='IKARIA TECHO'!L521 | G34: ='IKARIA TECHO'!M521 | H34: ='IKARIA TECHO'!N521 | I34: ='IKARIA TECHO'!O521
A35: 8 | B35: ENCHAPES | C35: 1 | D35: Global | E35: =E36 | F35: =F36 | G35: =G36 | H35: =H36 | I35: =I36
A36: 8.1 | B36: ENCHAPES (INTERNO Y EXTERNO) | C36: 1 | D36: Global | E36: ='IKARIA TECHO'!K529 | F36: ='IKARIA TECHO'!L529 | G36: ='IKARIA TECHO'!M529 | H36: ='IKARIA TECHO'!N529 | I36: ='IKARIA TECHO'!O529
A37: 9 | B37: MUEBLES Y PUERTAS | C37: 1 | D37: Global | E37: =SUM(E38:E39) | F37: =SUM(F38:F39) | G37: =SUM(G38:G39) | H37: =SUM(H38:H39) | I37: =SUM(I38:I39)
A38: 9.1 | B38: MUEBLES | C38: 1 | D38: Global | E38: ='IKARIA TECHO'!K561 | F38: ='IKARIA TECHO'!L561 | G38: ='IKARIA TECHO'!M561 | H38: ='IKARIA TECHO'!N561 | I38: ='IKARIA TECHO'!O561
A39: 9.2 | B39: PUERTAS Y RODAPIE | C39: 1 | D39: Global | E39: ='IKARIA TECHO'!K626 | F39: ='IKARIA TECHO'!L626 | G39: ='IKARIA TECHO'!M626 | H39: ='IKARIA TECHO'!N626 | I39: ='IKARIA TECHO'!O626
A40: 10 | B40: OBRAS ADICIONALES | C40: 1 | D40: Global | E40: =SUM(E41:E43) | F40: =SUM(F41:F43) | G40: =SUM(G41:G43) | H40: =SUM(H41:H43) | I40: =SUM(I41:I43)
A41: 10.1 | B41: ZACATE | C41: 1 | D41: Global | E41: ='IKARIA TECHO'!K639 | F41: ='IKARIA TECHO'!L639 | G41: ='IKARIA TECHO'!M639 | H41: ='IKARIA TECHO'!N639 | I41: ='IKARIA TECHO'!O639
A42: 10.2 | B42: TAPIAS PREFABRICADAS | C42: 1 | D42: Global | E42: ='IKARIA TECHO'!K647 | F42: ='IKARIA TECHO'!L647 | G42: ='IKARIA TECHO'!M647 | H42: ='IKARIA TECHO'!N647 | I42: ='IKARIA TECHO'!O647
...

Sheet BASE DATOS PRECIOS 
A1: CODIGO ACUMATICA | B1: CODIGO | C1: DESCRIPCION | D1: UNIDAD | E1: PRECIO | F1: PRECIO CON IVA | G1: PRECIO ANTERIOR | H1: DIFERENCIA | I1: OBSERVACIONES | J1: FECHA ÚLTIMO MOVIMIENTO | K1: FAMILIA DEL INSUMO
B2: EQU20-0001 | C2: ACEITE 15W40 | D2: UND | E2: 4821.3212 | F2: =E2*$N$2 | G2: 0 | H2: =F2-G2 | J2: 44695 | K2: REPUESTOS-COMBUSTIBLES | M2: IVA | N2: 1.13 | O2: GENERAL
A3: =_xlfn.XLOOKUP(B3,'INSUMOS MAT '!B:B,'INSUMOS MAT '!C:C,"ERROR",0) | B3: MAT05-0105 | C3: ACERO SUAVE BLANCO 0.44 X 914 | D3: KG | E3: 1581.5384 | F3: =E3*$N$2 | G3: 0 | H3: =F3-G3 | J3: 44720 | K3: CUBIERTAS E IMPERMEBILIZANTES | M3: IVA | N3: 1.1 | O3: MADERA
A4: =_xlfn.XLOOKUP(B4,'INSUMOS MAT '!B:B,'INSUMOS MAT '!C:C,"ERROR",0) | B4: MAT08-0003 | C4: ACETONA | D4: LITRO | E4: 6171.11 | F4: =E4*$N$2 | G4: 0 | H4: =F4-G4 | J4: 44715 | K4: FERRETERIA GENERAL | M4: IVA | N4: 1 | O4: SIN IVA
A5: =_xlfn.XLOOKUP(B5,'INSUMOS MAT '!B:B,'INSUMOS MAT '!C:C,"ERROR",0) | B5: MAT08-0310 | C5: ACIDO | D5: GALON | E5: 3001.78 | F5: =E5*$N$2 | G5: 0 | H5: =F5-G5 | J5: 44707 | K5: FERRETERIA GENERAL
A6: =_xlfn.XLOOKUP(B6,'INSUMOS MAT '!B:B,'INSUMOS MAT '!C:C,"ERROR",0) | B6: MAT08-0005 | C6: ACOPLE HEMBRA POLIETILENO 12MM | D6: UND | E6: 3046.9321 | F6: =E6*$N$2 | G6: 0 | H6: =F6-G6 | J6: 44692 | K6: FERRETERIA GENERAL
A7: =_xlfn.XLOOKUP(B7,'INSUMOS MAT '!B:B,'INSUMOS MAT '!C:C,"ERROR",0) | B7: MAT08-0481 | C7: ACOPLE MACHO DE POLIETILENO 12MM | D7: UND | E7: 2251.638 | F7: =E7*$N$2 | G7: 0 | H7: =F7-G7 | J7: 44700 | K7: FERRETERIA GENERAL
A8: =_xlfn.XLOOKUP(B8,'INSUMOS MAT '!B:B,'INSUMOS MAT '!C:C,"ERROR",0) | B8: MAT06-0004 | C8: ADAPT SECILLO 1 MODULO 5521-5EW DECORADOR BLANCO | D8: UND | E8: 2803.2737 | F8: =E8*$N$2 | G8: 0 | H8: =F8-G8 | J8: 44715 | K8: ELECTRICO
A9: =_xlfn.XLOOKUP(B9,'INSUMOS MAT '!B:B,'INSUMOS MAT '!C:C,"ERROR",0) | B9: MAT06-0005 | C9: ADAPTA DOBLE 2 MODULOS 5522-5EW DECORADOR BLANCO | D9: UND | E9: 688.2492 | F9: =E9*$N$2 | G9: 0 | H9: =F9-G9 | J9: 44714 | K9: ELECTRICO
A10: =_xlfn.XLOOKUP(B10,'INSUMOS MAT '!B:B,'INSUMOS MAT '!C:C,"ERROR",0) | B10: MAT19-0171 | C10: ADAPTADOR TRAMPA 1 1/2" A 1 1/4" | D10: UND | E10: 1196.9865 | F10: =E10*$N$2 | G10: 0 | H10: =F10-G10 | J10: 44692 | K10: PVC
A11: =_xlfn.XLOOKUP(B11,'INSUMOS MAT '!B:B,'INSUMOS MAT '!C:C,"ERROR",0) | B11: MAT19-0003 | C11: ADAPTADOR HEMBRA CPVC 1/2" | D11: UND | E11: 1132.77 | F11: =E11*$N$2 | G11: 0 | H11: =F11-G11 | J11: 44692 | K11: PVC
A12: =_xlfn.XLOOKUP(B12,'INSUMOS MAT '!B:B,'INSUMOS MAT '!C:C,"ERROR",0) | B12: MAT19-0004 | C12: ADAPTADOR HEMBRA PVC 1 1/2" | D12: UND | E12: 755.79 | F12: =E12*$N$2 | G12: 0 | H12: =F12-G12 | J12: 44720 | K12: PVC
A13: =_xlfn.XLOOKUP(B13,'INSUMOS MAT '!B:B,'INSUMOS MAT '!C:C,"ERROR",0) | B13: MAT19-0005 | C13: ADAPTADOR HEMBRA PVC 1 1/4" | D13: UND | E13: 652.57 | F13: =E13*$N$2 | G13: 0 | H13: =F13-G13 | J13: 44701 | K13: PVC
A14: =_xlfn.XLOOKUP(B14,'INSUMOS MAT '!B:B,'INSUMOS MAT '!C:C,"ERROR",0) | B14: MAT19-0006 | C14: ADAPTADOR HEMBRA PVC 1/2" | D14: UND | E14: 163.6 | F14: =E14*$N$2 | G14: 0 | H14: =F14-G14 | J14: 44692 | K14: PVC
A15: =_xlfn.XLOOKUP(B15,'INSUMOS MAT '!B:B,'INSUMOS MAT '!C:C,"ERROR",0) | B15: MAT19-0008 | C15: ADAPTADOR HEMBRA PVC 3/4" | D15: UND | E15: 587.6 | F15: =E15*$N$2 | G15: 0 | H15: =F15-G15 | J15: 44650 | K15: PVC
A16: =_xlfn.XLOOKUP(B16,'INSUMOS MAT '!B:B,'INSUMOS MAT '!C:C,"ERROR",0) | B16: MAT19-0009 | C16: ADAPTADOR MACHO CPVC 1/2 | D16: UND | E16: 358.31 | F16: =E16*$N$2 | G16: 0 | H16: =F16-G16 | J16: 44722 | K16: PVC
... A28: =_xlfn.XLOOKUP(B28,'INSUMOS MAT '!B:B,'INSUMOS MAT '!C:C,"ERROR",0) | B28: MAT16-0101 | C28: ANTICORROSIVO GRIS | D28: CUBETA | E28: 76503.19 | F28: =E28*$N$2 | G28: 0 | H28: =F28-G28 | J28: 44685 | K28: PINTURAS Y REVESTIMIENTOS
B29: MAT16-0102 | C29: ANTICORROSIVO MINIO GRIS | D29: GALON | E29: 15009.54 | F29: =E29*$N$2 | G29: 0 | H29: =F29-G29 | J29: 44700 | K29: PINTURAS Y REVESTIMIENTOS
A30: =_xlfn.XLOOKUP(B30,'INSUMOS MAT '!B:B,'INSUMOS MAT '!C:C,"ERROR",0) | B30: MAT16-0100 | C30: ANTICORROSIVO MINIO ROJO | D30: CUBETA | E30: 63360.66 | F30: =E30*$N$2 | G30: 0 | H30: =F30-G30 | J30: 44685 | K30: PINTURAS Y REVESTIMIENTOS
A31: =_xlfn.XLOOKUP(B31,'INSUMOS MAT '!B:B,'INSUMOS MAT '!C:C,"ERROR",0) | B31: MAT16-0001 | C31: ANTICORROSIVO MINIO AZUL | D31: GALON | E31: 12562.663 | F31: =E31*$N$2 | G31: 0 | H31: =F31-G31 | J31: 44719 | K31: PINTURAS Y REVESTIMIENTOS
A32: =_xlfn.XLOOKUP(B32,'INSUMOS MAT '!B:B,'INSUMOS MAT '!C:C,"ERROR",0) | B32: MAT16-0083 | C32: ANTICORROSIVO MINIO BLANCO | D32: GAL | E32: 11340.093 | F32: =E32*$N$2 | G32: 0 | H32: =F32-G32 | J32: 44692 | K32: PINTURAS Y REVESTIMIENTOS
A33: =_xlfn.XLOOKUP(B33,'INSUMOS MAT '!B:B,'INSUMOS MAT '!C:C,"ERROR",0) | B33: MAT16-0002 | C33: ANTICORROSIVO MINIO ROJO | D33: GALON | E33: 12291.091 | F33: =E33*$N$2 | G33: 0 | H33: =F33-G33 | J33: 44700 | K33: PINTURAS Y REVESTIMIENTOS
A34: =_xlfn.XLOOKUP(B34,'INSUMOS MAT '!B:B,'INSUMOS MAT '!C:C,"ERROR",0) | B34: MAT06-0006 | C34: APAGADOR DOBLE 15A 120 DECO | D34: UND | E34: 2858.7757 | F34: =E34*$N$2 | G34: 0 | H34: =F34-G34 | J34: 44714 | K34: ELECTRICO
A35: =_xlfn.XLOOKUP(B35,'INSUMOS MAT '!B:B,'INSUMOS MAT '!C:C,"ERROR",0) | B35: MAT06-0008 | C35: APAGADOR DOBLE TRIWAY DECO | D35: UND | E35: 8006.5005 | F35: =E35*$N$2 | G35: 0 | H35: =F35-G35 | J35: 44700 | K35: ELECTRICO
A36: =_xlfn.XLOOKUP(B36,'INSUMOS MAT '!B:B,'INSUMOS MAT '!C:C,"ERROR",0) | B36: MAT06-0009 | C36: APAGADOR SENCILLO 15A 120 DECO | D36: UND | E36: 1041.8373 | F36: =E36*$N$2 | G36: 0 | H36: =F36-G36 | J36: 44715 | K36: ELECTRICO
A37: =_xlfn.XLOOKUP(B37,'INSUMOS MAT '!B:B,'INSUMOS MAT '!C:C,"ERROR",0) | B37: MAT06-0011 | C37: APAGADOR SENCILLO TRIWAY | D37: UND | E37: 2005.6972 | F37: =E37*$N$2 | G37: 0 | H37: =F37-G37 | J37: 44721 | K37: ELECTRICO
A38: =_xlfn.XLOOKUP(B38,'INSUMOS MAT '!B:B,'INSUMOS MAT '!C:C,"ERROR",0) | B38: MAT06-0012 | C38: APAGADOR TRIPLE 15A 120 DECO | D38: UND | E38: 3895.462 | F38: =E38*$N$2 | G38: 0 | H38: =F38-G38 | J38: 44714 | K38: ELECTRICO
A39: =_xlfn.XLOOKUP(B39,'INSUMOS MAT '!B:B,'INSUMOS MAT '!C:C,"ERROR",0) | B39: MAT05-0111 | C39: ARENA SILICA (KG) | D39: KG | E39: 1251.0027 | F39: =E39*$N$2 | G39: 0 | H39: =F39-G39 | J39: 44706 | K39: CUBIERTAS E IMPERMEBILIZANTES
A40: =_xlfn.XLOOKUP(B40,'INSUMOS MAT '!B:B,'INSUMOS MAT '!C:C,"ERROR",0) | B40: MAT06-0015 | C40: ARO REPELLO EMT 4X4 1GANG | D40: UND | E40: 264.88 | F40: =E40*$N$2 | G40: 0 | H40: =F40-G40 | J40: 44692 | K40: ELECTRICO
A41: =_xlfn.XLOOKUP(B41,'INSUMOS MAT '!B:B,'INSUMOS MAT '!C:C,"ERROR",0) | B41: MAT06-0016 | C41: ARO REPELLO EMT 4X4 2GANG | D41: UND | E41: 497.2 | F41: =E41*$N$2 | G41: 0 | H41: =F41-G41 | J41: 44719 | K41: ELECTRICO
... A58: =_xlfn.XLOOKUP(B58,'INSUMOS MAT '!B:B,'INSUMOS MAT '!C:C,"ERROR",0) | B58: MAT06-0025 | C58: BREAKER QO240 2P/40AMP | D58: UND | E58: 15255 | F58: =E58*$N$2 | G58: 0 | H58: =F58-G58 | J58: 44718 | K58: ELECTRICO
B59: MAT08-0009 | C59: BRIDA FLEXIBLE 3" PVC | D59: UND | E59: 4999.8774 | F59: =E59*$N$2 | G59: 0 | H59: =F59-G59 | J59: 44707 | K59: FERRETERIA GENERAL
A60: =_xlfn.XLOOKUP(B60,'INSUMOS MAT '!B:B,'INSUMOS MAT '!C:C,"ERROR",0) | B60: MAT08-0229 | C60: BROCA P/CONCRETO DE 5/32X 6" | D60: UND | E60: 1052.2674 | F60: =E60*$N$2 | G60: 0 | H60: =F60-G60 | J60: 44708 | K60: FERRETERIA GENERAL
A61: =_xlfn.XLOOKUP(B61,'INSUMOS MAT '!B:B,'INSUMOS MAT '!C:C,"ERROR",0) | B61: MAT08-0223 | C61: BROCA P/CONCRETO EN 3/8 CORRIENTE | D61: UND | E61: 2276.3958 | F61: =E61*$N$2 | G61: 0 | H61: =F61-G61 | J61: 44712 | K61: FERRETERIA GENERAL
A62: =_xlfn.XLOOKUP(B62,'INSUMOS MAT '!B:B,'INSUMOS MAT '!C:C,"ERROR",0) | B62: MAT08-0222 | C62: BROCA P/CONCRETO TIPO HILTY EN 3/8 | D62: UND | E62: 6211.44 | F62: =E62*$N$2 | G62: 0 | H62: =F62-G62 | J62: 44714 | K62: FERRETERIA GENERAL
A63: =_xlfn.XLOOKUP(B63,'INSUMOS MAT '!B:B,'INSUMOS MAT '!C:C,"ERROR",0) | B63: MAT08-0250 | C63: BROCA SIERRA | D63: UND | E63: 33787 | F63: =E63*$N$2 | G63: 0 | H63: =F63-G63 | J63: 44495 | K63: FERRETERIA GENERAL
A64: =_xlfn.XLOOKUP(B64,'INSUMOS MAT '!B:B,'INSUMOS MAT '!C:C,"ERROR",0) | B64: MAT08-0011 | C64: BROCA P/CONCRETO 5/16 PULG | D64: UND | E64: 1720.8061 | F64: =E64*$N$2 | G64: 0 | H64: =F64-G64 | J64: 44720 | K64: FERRETERIA GENERAL
A65: =_xlfn.XLOOKUP(B65,'INSUMOS MAT '!B:B,'INSUMOS MAT '!C:C,"ERROR",0) | B65: MAT08-0012 | C65: BROCHA CORRIENTE 2" | D65: UND | E65: 1471.5988 | F65: =E65*$N$2 | G65: 0 | H65: =F65-G65 | J65: 44721 | K65: FERRETERIA GENERAL
A66: =_xlfn.XLOOKUP(B66,'INSUMOS MAT '!B:B,'INSUMOS MAT '!C:C,"ERROR",0) | B66: MAT08-0013 | C66: BROCHA CORRIENTE 3" | D66: UND | E66: 1807.5316 | F66: =E66*$N$2 | G66: 0 | H66: =F66-G66 | J66: 44720 | K66: FERRETERIA GENERAL
A67: =_xlfn.XLOOKUP(B67,'INSUMOS MAT '!B:B,'INSUMOS MAT '!C:C,"ERROR",0) | B67: MAT06-0155 | C67: CABLE #4 TRIPLEX | D67: M | E67: 1299.4662 | F67: =E67*$N$2 | G67: 0 | H67: =F67-G67 | J67: 44498 | K67: ELECTRICO
...

Sheet BASE DATOS EQUIPOS Y SUBCONTRAT
A1: CODIGO | B1: DESCRIPCION | C1: UNIDAD | D1: PRECIO | E1: PRECIO CON IVA | F1: PRECIO ANTERIOR | G1: DIFERENCIA | H1: OBSERVACIONES | I1: FECHA ÚLTIMO MOVIMIENTO | J1: FAMILIA DEL INSUMO
A2: BACK HOE | B2: BACK HOE | C2: HORA | D2: =18500 | E2: =D2 | L2: IVA | M2: 1.13 | N2: GENERAL
A3: COMPACTADOR | B3: COMPACTADOR | C3: HORA | D3: 12000 | E3: =D3 | L3: IVA | M3: 1.1 | N3: MADERA
B10: SUBCONTRATO ELÉCTRICO
A12: SUB ACOMETIDA | B12: M.O. ACOMETIDA ELÉCTRICA | C12: GLOBAL | E12: 25000
A13: SUB ELECTRICO LOSA | B13: M.O. TUBERIA ELECTRICA LOSA | C13: GLOBAL | E13: 84000
A14: SUB ELECTRICO MUROS | B14: M.O. TUBERIA ELECTRICA MUROS | C14: GLOBAL | E14: 36000
A15: SUB BASE MEDIDOR | B15: M.O. INSTALACIÓN BASE MEDIDOR | C15: GLOBAL | E15: 15000
A16: SUB ILUMINACION | B16: M.O. SALIDAS DE ILUMINACION | C16: GLOBAL | E16: 48000
A17: SUB TABLEROS | B17: M.O. ARMADO TABLEROS | C17: GLOBAL | E17: 27500
A18: SUB CABLEADO | B18: M.O. CABLEADO ELÉCTRICO | C18: GLOBAL | E18: 112000
A19: SUB PLAQUERIA | B19: M.O. COLOCACIÓN DE PLAQUERÍA | C19: GLOBAL | E19: 60000
A20: SUB ENTREGA FINAL | B20: M.O. TRABAJOS ELÉCTRICOS PARA ENTREGA FINAL | C20: GLOBAL | E20: 87500
E21: =SUM(E12:E20)
B29: FORMALETA
A31: FORMALETA LOSA | B31: FORMALETA LOSA FLOTANTE | C31: GLOBAL
A32: FORMALETA MUROS | B32: FORMALETA MUROS | C32: GLOBAL | E32: 0
A33: FORMALETA COLUMNAS | B33: FORMALETA COLUMNAS | C33: GLOBAL | E33: 0
B38: OTROS
A39: GRANITO | B39: GRANITO CON INSTALACION | C39: M | D39: =85250*1.03 | E39: =D39*'BASE DATOS PRECIOS '!$N$4 | F39: 0 | G39: =E39-F39
A40: VENTANERIA IKARIA | B40: SUBCONTRATO VENTANERIA (MATERIAL Y MANO DE OBRA) | C40: GLOBAL | D40: =896000*1.03 | E40: =D40*'BASE DATOS PRECIOS '!$N$4 | F40: 0 | G40: =E40-F40
A41: VENTANERIA SKYROS | B41: SUBCONTRATO VENTANERIA (MATERIAL Y MANO DE OBRA) | C41: GLOBAL | D41: =947511.36*1.03 | E41: =D41*'[3]BASE DATOS PRECIOS '!$N$4 | F41: 0 | G41: =E41-F41
K680: =+(37168.41*1.13)/(0.93*5.45)

Sheet BASE DATOS MANO DE OBRA
A1: CODIGO | B1: DESCRIPCION | C1: UNIDAD | D1: PRECIO | E1: PRECIO CON CARGAS SOCIALES | F1: PRECIO ANTERIOR | G1: DIFERENCIA | H1: OBSERVACIONES | I1: FECHA ÚLTIMO MOVIMIENTO | J1: FAMILIA DEL INSUMO
A2: ENCARGADO | B2: ENCARGADO PLUS | C2: hora | D2: 2000 | E2: =D2*1.5 | G2: =E2-F2 | L2: IVA | M2: 1.13 | N2: GENERAL
A3: OP CALIFICADO | B3: OPERARIO CALIFICADO PLUS | C3: hora | D3: 2000 | E3: =D3*1.5 | G3: =E3-F3 | L3: IVA | M3: 1.1 | N3: MADERA
A4: OPERARIO | B4: OPERARIO PLUS | C4: hora | D4: 1900 | E4: =D4*1.5 | G4: =E4-F4 | L4: IVA | M4: 1 | N4: SIN IVA
A5: AYUDANTE | B5: AYUDANTE PLUS | C5: hora | D5: 1550 | E5: =D5*1.5 | G5: =E5-F5
B16: <
K659: =+(37168.41*1.13)/(0.93*5.45)

Sheet INSUMOS MAT 
B1: (ID) Insumo | D1: Descripción | E1: Unidad | F1: Grupo de Insumo | G1: Familia de Insumos
B2: MAT01-0001 | C2: 0101-0001 | D2: GRIFERIA ALTA NOVO CROMADA P/VESSEL | E2: UND | F2: MATERIALES | G2: ACABADOS
B3: MAT01-0002 | C3: 0101-0002 | D3: GRIFERIA DUCHA BREZZA MONO S/LAVAPIES EZ4015551 SSB | E3: UND | F3: MATERIALES | G3: ACABADOS
B4: MAT01-0005 | C4: 0101-0005 | D4: GRIFERIA LAV.CROMA METAL 4" PALANCA CROMO P/LAV MILANO | E4: UND | F4: MATERIALES | G4: ACABADOS
B5: MAT01-0006 | C5: 0101-0006 | D5: GRIFERIA LAVAPLATOS KENAI MONO | E5: UND | F5: MATERIALES | G5: ACABADOS
B6: MAT01-0007 | C6: 0101-0007 | D6: GRIFERIA BREZZA MONO BAJA MU1015551 | E6: UND | F6: MATERIALES | G6: ACABADOS
B7: MAT01-0008 | C7: 0101-0008 | D7: INODORO CORONA SMART BLANCO | E7: UND | F7: MATERIALES | G7: ACABADOS
B8: MAT01-0010 | C8: 0101-0010 | D8: LAVATORIO SPAZIO DE SOBREPONER BLANCO | E8: UND | F8: MATERIALES | G8: ACABADOS
B9: MAT01-0011 | C9: 0101-0011 | D9: LAVATORIO MILANO BLANCO CON PEDESTAL | E9: UND | F9: MATERIALES | G9: ACABADOS
B10: MAT01-0012 | C10: 0101-0012 | D10: LAVATORIO OLYMPUS II CON PEDESTAL | E10: UND | F10: MATERIALES | G10: ACABADOS
B11: MAT01-0013 | C11: 0101-0013 | D11: PILA Y MUEBLE FIBRA DE VIDRIO 50X70CM | E11: UND | F11: MATERIALES | G11: ACABADOS
B12: MAT01-0014 | C12: 0101-0014 | D12: REJILLA P/BAÑO CUADRADA / REJ-10'2" (50mm) | E12: UND | F12: MATERIALES | G12: ACABADOS
B13: MAT01-0015 | C13: 0101-0015 | D13: DESVIADOR DE 1 VIA | E13: UND | F13: MATERIALES | G13: ACABADOS
... B50: MAT01-0054 | C50: 0101-0054 | D50: LLAVIN Y ACCESORIO CARBONE | E50: UND | F50: MATERIALES | G50: ACABADOS
B51: (ID) Insumo | D51: Descripción | E51: Unidad | F51: Grupo de Insumo | G51: Familia de Insumos
B52: MAT02-0001 | C52: 0102-0001 | D52: ALAMBRE NEGRO #16 (1.68MM) | E52: KG | F52: MATERIALES | G52: ACEROS Y METALES
B53: MAT02-0002 | C53: 0102-0002 | D53: ANGULAR 1 1/4"X3/16" | E53: UND | F53: MATERIALES | G53: ACEROS Y METALES
B54: MAT02-0003 | C54: 0102-0003 | D54: ANGULAR DE 2"x 3/16" | E54: UND | F54: MATERIALES | G54: ACEROS Y METALES
B55: MAT02-0004 | C55: 0102-0004 | D55: ANGULAR HN 1 1/4"x1.8" | E55: UND | F55: MATERIALES | G55: ACEROS Y METALES
B56: MAT02-0005 | C56: 0102-0005 | D56: LAMINA DE JORDOMEX #1 ACS 4X8X3MM | E56: UND | F56: MATERIALES | G56: ACEROS Y METALES
B57: MAT02-0006 | C57: 0102-0006 | D57: LAMINA DE JORDOMEX #3 (1/2) ROMBO 13X32 3MM ESPESOR | E57: UND | F57: MATERIALES | G57: ACEROS Y METALES
B58: MAT02-0007 | C58: 0102-0007 | D58: LAMINA H.N. ANTIDESLIZ 1.22X2.44X3MM | E58: UND | F58: MATERIALES | G58: ACEROS Y METALES
B59: MAT02-0008 | C59: 0102-0008 | D59: MALLA ELECTROSOLDADA 4.88MM | E59: UND | F59: MATERIALES | G59: ACEROS Y METALES
B60: MAT02-0009 | C60: 0102-0009 | D60: MALLA ELECTROSOLDADA #1 (4.11MM) | E60: UND | F60: MATERIALES | G60: ACEROS Y METALES
B61: MAT02-0010 | C61: 0102-0010 | D61: MALLA ELECTROSOLDADA #2 (5.3 MM) | E61: UND | F61: MATERIALES | G61: ACEROS Y METALES
B62: MAT02-0011 | C62: 0102-0011 | D62: PERLING 3X2X15MM EN 1.2MM H.G. | E62: UND | F62: MATERIALES | G62: ACEROS Y METALES
B63: MAT02-0012 | C63: 0102-0012 | D63: PLATINA 3"x1/4" | E63: UND | F63: MATERIALES | G63: ACEROS Y METALES
... B218: MAT02-0168 | C218: 0102-0168 | D218: VIGA U 4x1/4" | E218: UND | F218: MATERIALES | G218: ACEROS Y METALES
B219: (ID) Insumo | D219: Descripción | E219: Unidad | F219: Grupo de Insumo | G219: Familia de Insumos
B220: MAT03-0001 | C220: 0103-0001 | D220: ARENA SILICA | E220: SACO | F220: MATERIALES | G220: AGREGADOS
B221: MAT03-0002 | C221: 0103-0002 | D221: ARENA FINA DE RIO | E221: M3 | F221: MATERIALES | G221: AGREGADOS
B222: MAT03-0003 | C222: 0103-0003 | D222: ARENA LAVADA | E222: M3 | F222: MATERIALES | G222: AGREGADOS
B223: MAT03-0004 | C223: 0103-0004 | D223: BASE GRANULAR | E223: M3 | F223: MATERIALES | G223: AGREGADOS
B224: MAT03-0005 | C224: 0103-0005 | D224: LASTRE GRUESO | E224: M3 | F224: MATERIALES | G224: AGREGADOS
B225: MAT03-0006 | C225: 0103-0006 | D225: PIEDRA CUARTILLA | E225: M3 | F225: MATERIALES | G225: AGREGADOS
B226: MAT03-0007 | C226: 0103-0007 | D226: PIEDRA QUINTILLA | E226: M3 | F226: MATERIALES | G226: AGREGADOS
B227: MAT03-0008 | C227: 0103-0008 | D227: POLVO DE PIEDRA | E227: M3 | F227: MATERIALES | G227: AGREGADOS
B228: MAT03-0009 | C228: 0103-0009 | D228: SUB BASE GRANULAR | E228: M3 | F228: MATERIALES | G228: AGREGADOS
B229: MAT03-0010 | C229: 0103-0010 | D229: TIERRA | E229: M3 | F229: MATERIALES | G229: AGREGADOS
B230: MAT03-0011 | C230: 0103-0011 | D230: PIEDRA TERCERA | E230: M3 | F230: MATERIALES | G230: AGREGADOS
...

Sheet CALCULO CANTIDADES 
D3: IKARIA TECHO
C7: 1 | D7: RELLENOS
C9: Lastre
C10: Espesor: | D10: 0.15 | E10: m
C11: Área casa (incluye área de pilas) | D11: 394.99 | E11: m2
C13: m3 totales | D13: 59.2485 | E13: m3 | J13: Diferencia
G14: COMPARACION SISTEMA
D15: Costo | E15: Costo Total | G15: Horas | H15: Costo/hora | I15: Costo Total
C16: Mano de obra (trazado) (m2) | D16: 1273.55 | E16: =D16*D11 | F16: Trazo | G16: 30 | H16: 1700 | I16: =G16*H16
C17: Mano de obra (excavación) (m3) | D17: 18148.02 | F17: Zanjeo | G17: 39 | H17: 1700 | I17: =G17*H17
C18: Mano de obra (relleno ) (m3) | D18: 28973.15 | E18: =D18*D13 | I18: =SUM(I16:I17) | J18: =E19-I18
D19: Total | E19: =SUM(E16:E18)
C23: 2 | D23: SELLO DE CONCRETO
C25: Sello concreto
C26: Espesor: | D26: 0.06 | E26: m
C27: Área casa (NO incluye área de pilas) | D27: 343.6413 | E27: m2
C29: m3 totales | D29: 23.6994 | E29: m3
C31: Cemento | D31: 142.2 | E31: sacos
C32: Arena | D32: 17.7746 | E32: m3
C33: Piedra | D33: 18.9595 | E33: m3
C35: CANTIDADES DOSIFICACION ADELANTE (DIEGO - JARDEL)
C36: Cemento | D36: =D29*180 | E36: kilos
C37: Arena | D37: =D29*0.73 | E37: m3
C38: Piedra | D38: =D29*0.6 | E38: m3
J41: Diferencia
G42: COMPARACION SISTEMA
D43: Costo | E43: Costo Total | G43: Horas | H43: Costo/hora | I43: Costo Total
C44: Mano de obra (concreto) (m3) | D44: 41390.21 | E44: =D44*D29 | F44: Sello | G44: 27 | H44: 1700 | I44: =G44*H44 | J44: =E44-I44
C48: 3 | D48: LOSA FLOTANTE
C50: CONCRETO
C52: Espesor: | D52: 0.2 | E52: m
C53: Área casa (NO incluye área de pilas) | D53: 343.6413 | E53: m2
C55: m3 totales | D55: 68.7283 | E55: m3
C57: Cemento | D57: 549.83 | E57: sacos
C58: Arena | D58: 51.5462 | E58: m3
C59: Piedra | D59: 54.9826 | E59: m3
C62: CANTIDADES DOSIFICACION ADELANTE (DIEGO - JARDEL)
C63: Cemento | D63: =D55*333 | E63: kilos
C64: Arena | D64: =D55*0.59 | E64: m3
C65: Piedra | D65: =D55*0.67 | E65: m3
...

Sheet TABLA DE AVANCE 
I1: VERIFICACION | J1: =D4-'IKARIA TECHO'!N10
A3: CODIGO | B3: N° | C3: Descripcion actividad | D3: Total Directo Colones | E3: porcentaje de avance | F3: monto | G3: Monto faltante por gastar
C4: TOTAL PRESUPUESTO | D4: =SUM(D5:D69)/2
A5: 01 | B5: 1 | C5: FUNDACIONES | D5: ='IKARIA TECHO'!N11 | E5: 0.1 | F5: =D5*E5 | G5: =D5-F5
A6: 01-01 | B6: 1.1 | C6: OBRAS PRELIMINARES Y RELLENOS | D6: ='IKARIA TECHO'!N12 | F6: =D6*E6 | G6: =D6-F6
A7: 01-02 | B7: 1.2 | C7: EXCAVACIÓN Y TUBERÍAS MECÁNICAS | D7: ='IKARIA TECHO'!N21 | F7: =D7*E7 | G7: =D7-F7
A8: 01-03 | B8: 1.3 | C8: SELLO DE CONCRETO | D8: ='IKARIA TECHO'!N58 | F8: =D8*E8 | G8: =D8-F8
A9: 01-04 | B9: 1.4 | C9: LOSA FLOTANTE (ACERO, ELECTROMECANICOS, CONCRETO) | D9: ='IKARIA TECHO'!N69 | F9: =D9*E9 | G9: =D9-F9
A10: 02 | B10: 2 | C10: SUPERESTRUCTURA PRIMER NIVEL | D10: ='IKARIA TECHO'!N123 | F10: =D10*E10 | G10: =D10-F10
A11: 02-01 | B11: 2.1 | C11: ACERO EN PAREDES MUROS N1 (ELECTROMECANICO) | D11: ='IKARIA TECHO'!N124 | F11: =D11*E11 | G11: =D11-F11
A12: 02-02 | B12: 2.2 | C12: PAREDES, MUROS, ENTREPISO N1 (FORMALETA, CONCRETO, DESENCOFRADO) | D12: ='IKARIA TECHO'!N154 | F12: =D12*E12 | G12: =D12-F12
A13: 02-03 | B13: 2.3 | C13: MAMPOSTERIA | D13: ='IKARIA TECHO'!N169 | F13: =D13*E13 | G13: =D13-F13
A14: 03 | B14: 3 | C14: SUPERESTRUCTURA SEGUNDO NIVEL | D14: ='IKARIA TECHO'!N182 | F14: =D14*E14 | G14: =D14-F14
A15: 03-01 | B15: 3.1 | C15: ACERO EN PAREDES MUROS N2 (ELECTROMECANICO) | D15: ='IKARIA TECHO'!N183 | F15: =D15*E15 | G15: =D15-F15
A16: 03-02 | B16: 3.2 | C16: PAREDES, MUROS, ENTREPISO N2 (FORMALETA, CONCRETO, DESENCOFRADO) | D16: ='IKARIA TECHO'!N201 | F16: =D16*E16 | G16: =D16-F16
A17: 04 | B17: 4 | C17: OTROS GRIS | D17: ='IKARIA TECHO'!N214 | F17: =D17*E17 | G17: =D17-F17
A18: 04-01 | B18: 4.1 | C18: GRADAS EN CONCRETO | D18: ='IKARIA TECHO'!N215 | F18: =D18*E18 | G18: =D18-F18
A19: 04-02 | B19: 4.2 | C19: COLUMNAS (MEDIDOR) | D19: ='IKARIA TECHO'!N253 | F19: =D19*E19 | G19: =D19-F19
A20: 04-03 | B20: 4.3 | C20: CHORREA DE COCHERAS Y PILAS | D20: ='IKARIA TECHO'!N288 | F20: =D20*E20 | G20: =D20-F20
A21: 05 | B21: 5 | C21: ESTRUCTURA METÁLICA Y CUBIERTAS | D21: ='IKARIA TECHO'!N309 | F21: =D21*E21 | G21: =D21-F21
A22: 05-01 | B22: 5.1 | C22: ESTRUCTURA TECHO CASA | D22: ='IKARIA TECHO'!N310 | F22: =D22*E22 | G22: =D22-F22
A23: 05-02 | B23: 5.2 | C23: ESTRUCTURA TECHO COCHERA | D23: ='IKARIA TECHO'!N327 | F23: =D23*E23 | G23: =D23-F23
A24: 05-03 | B24: 5.3 | C24: CUBIERTA TECHO CASA | D24: ='IKARIA TECHO'!N348 | F24: =D24*E24 | G24: =D24-F24
A25: 05-04 | B25: 5.4 | C25: CUBIERTA TECHO COCHERA | D25: ='IKARIA TECHO'!N356 | F25: =D25*E25 | G25: =D25-F25
A26: 05-05 | B26: 5.5 | C26: HOJALATERIA Y CANOAS | D26: ='IKARIA TECHO'!N368 | F26: =D26*E26 | G26: =D26-F26
A27: 05-06 | B27: 5.6 | C27: GRADAS ESTRUCTURA, PINTADO Y ACABADO | D27: ='IKARIA TECHO'!N380 | F27: =D27*E27 | G27: =D27-F27
A28: 05-07 | B28: 5.7 | C28: BARANDA DE GRADAS (N2) | D28: ='IKARIA TECHO'!N394 | F28: =D28*E28 | G28: =D28-F28
A29: 05-08 | B29: 5.8 | C29: ESTRUCTURA METÁLICA INTERNA | D29: ='IKARIA TECHO'!N408 | F29: =D29*E29 | G29: =D29-F29
A30: 06 | B30: 6 | C30: LIVIANO | D30: ='IKARIA TECHO'!N422 | F30: =D30*E30 | G30: =D30-F30
A31: 06-01 | B31: 6.1 | C31: LIVIANO EXTERIORES | D31: ='IKARIA TECHO'!N423 | F31: =D31*E31 | G31: =D31-F31
A32: 06-02 | B32: 6.2 | C32: LIVIANO INTERIORES ( PAREDES LIVIANAS Y CIELOS) | D32: ='IKARIA TECHO'!N455 | F32: =D32*E32 | G32: =D32-F32
A33: 07 | B33: 7 | C33: REPELLOS | D33: ='IKARIA TECHO'!N504 | F33: =D33*E33 | G33: =D33-F33
A34: 07-01 | B34: 7.1 | C34: REPELLOS INTERNO Y EXTERNO | D34: ='IKARIA TECHO'!N505 | F34: =D34*E34 | G34: =D34-F34
A35: 07-02 | B35: 7.2 | C35: EMPASTE | D35: ='IKARIA TECHO'!N521 | F35: =D35*E35 | G35: =D35-F35
A36: 08 | B36: 8 | C36: ENCHAPES | D36: ='IKARIA TECHO'!N528 | F36: =D36*E36 | G36: =D36-F36
A37: 08-01 | B37: 8.1 | C37: ENCHAPES (INTERNO Y EXTERNO) | D37: ='IKARIA TECHO'!N529 | F37: =D37*E37 | G37: =D37-F37
A38: 09 | B38: 9 | C38: MUEBLES Y PUERTAS | D38: ='IKARIA TECHO'!N560 | F38: =D38*E38 | G38: =D38-F38
A39: 09-01 | B39: 9.1 | C39: MUEBLES | D39: ='IKARIA TECHO'!N561 | F39: =D39*E39 | G39: =D39-F39
A40: 09-02 | B40: 9.2 | C40: PUERTAS Y RODAPIE | D40: ='IKARIA TECHO'!N626 | F40: =D40*E40 | G40: =D40-F40
A41: 10 | B41: 10 | C41: OBRAS ADICIONALES | D41: ='IKARIA TECHO'!N638 | F41: =D41*E41 | G41: =D41-F41
...

Sheet Costo personal
C3: SALARIO POR HORA APROBADO POR GERENCIA
C4: Fecha de aprobación: 08/02/2022
C5: Vigente desde: 08/02/2022
C8: Descripción de Puesto | D8: Salario x Hora | E8: Bono | G8: cargas sociales | H8: 48 Horas semanales | I8: Horas Extra Por Semana | J8: Costo Por Semana | K8: Cargas Sociales | L8: Total a Pagar x Semana | M8: Total a Pagar x Mes
B10: MO-01-01 | C10: Encargado Plus | D10: 2000 | E10: 500 | F10: =SUM(D10:E10) | G10: =+F10*1.5 | H10: =+(D10+E10)*48 | I10: =+(D10+E10)*7*1.5 | J10: =+I10+H10 | K10: =+J10*0.5 | L10: =+K10+J10 | M10: =+L10*4.32
B11: MO-01-02 | C11: Encargado Avanzado | D11: 2000 | E11: 300 | F11: =SUM(D11:E11) | G11: =+F11*1.5 | H11: =+(D11+E11)*48 | I11: =+(D11+E11)*7*1.5 | J11: =+I11+H11 | K11: =+J11*0.5 | L11: =+K11+J11 | M11: =+L11*4.32
B12: MO-01-03 | C12: Encargado | D12: 2000 | E12: 200 | F12: =SUM(D12:E12) | G12: =+F12*1.5 | H12: =+(D12+E12)*48 | I12: =+(D12+E12)*7*1.5 | J12: =+I12+H12 | K12: =+J12*0.5 | L12: =+K12+J12 | M12: =+L12*4.32
B14: MO-02-01 | C14: Operario calificado Plus | D14: 2000 | F14: =SUM(D14:E14) | G14: =+F14*1.5 | H14: =+(D14+E14)*48 | I14: =+(D14+E14)*7*1.5 | J14: =+I14+H14 | K14: =+J14*0.5 | L14: =+K14+J14 | M14: =+L14*4.32
B15: MO-02-02 | C15: Operario calificado Avanzado | D15: 1900 | F15: =SUM(D15:E15) | G15: =+F15*1.5 | H15: =+(D15+E15)*48 | I15: =+(D15+E15)*7*1.5 | J15: =+I15+H15 | K15: =+J15*0.5 | L15: =+K15+J15 | M15: =+L15*4.32
C16: Operario calificado (nuevo ingreso) | D16: 1700 | F16: =SUM(D16:E16) | G16: =+F16*1.5 | H16: =+(D16+E16)*48 | I16: =+(D16+E16)*7*1.5 | J16: =+I16+H16 | K16: =+J16*0.5 | L16: =+K16+J16 | M16: =+L16*4.32
B18: MO-03-01 | C18: Operario Plus | D18: 1900 | F18: =SUM(D18:E18) | G18: =+F18*1.5 | H18: =+(D18+E18)*48 | I18: =+(D18+E18)*7*1.5 | J18: =+I18+H18 | K18: =+J18*0.5 | L18: =+K18+J18 | M18: =+L18*4.32
B19: MO-03-02 | C19: Operario Avanzado | D19: 1800 | F19: =SUM(D19:E19) | G19: =+F19*1.5 | H19: =+(D19+E19)*48 | I19: =+(D19+E19)*7*1.5 | J19: =+I19+H19 | K19: =+J19*0.5 | L19: =+K19+J19 | M19: =+L19*4.32
B20: MO-03-03 | C20: Operario (nuevo ingreso) | D20: 1600 | F20: =SUM(D20:E20) | G20: =+F20*1.5 | H20: =+(D20+E20)*48 | I20: =+(D20+E20)*7*1.5 | J20: =+I20+H20 | K20: =+J20*0.5 | L20: =+K20+J20 | M20: =+L20*4.32
B22: MO-04-01 | C22: Ayudante Plus | D22: 1550 | F22: =SUM(D22:E22) | G22: =+F22*1.5 | H22: =+(D22+E22)*48 | I22: =+(D22+E22)*7*1.5 | J22: =+I22+H22 | K22: =+J22*0.5 | L22: =+K22+J22 | M22: =+L22*4.32
B23: MO-04-02 | C23: Ayudante Avanzado | D23: 1450 | F23: =SUM(D23:E23) | G23: =+F23*1.5 | H23: =+(D23+E23)*48 | I23: =+(D23+E23)*7*1.5 | J23: =+I23+H23 | K23: =+J23*0.5 | L23: =+K23+J23 | M23: =+L23*4.32
B24: MO-04-03 | C24: Ayudante (nuevo ingreso) | D24: 1360 | F24: =SUM(D24:E24) | G24: =+F24*1.5 | H24: =+(D24+E24)*48 | I24: =+(D24+E24)*7*1.5 | J24: =+I24+H24 | K24: =+J24*0.5 | L24: =+K24+J24 | M24: =+L24*4.32
C27: NOTAS:
C28: Operario Calificado: Soldadores y Ebanistas
C29: Operario: Repellos, Enchapes, Pasta, Armadura, Formaleta, Fontaneros, Obras Complementarias
C31: ACLARACIONES:
C32: - Los ingresos se harán con Los parámetros indicados
C33: - Para ingresar en Rango de avanzado debe contar como mínimo 1 mes de laborar en la empresa demostrando que es merecedor de la mejora salarial. (Este lo revisara el maestro de Obras)
C34: - Para ingresar en Rango de Plus debe contar como mínimo 6 mes de laborar en la empresa demostrando que es merecedor de la mejora salarial. (Este lo revisara el maestro de Obras)

Sheet HORAS MANO DE OBRA
A1: Nivel | B1: CODIGO | C1: DESCRIPCION | D1: TOTAL HORAS
A2: 1 | B2: 01 | C2: FUNDACIONES
A3: 2 | B3: 01-01 | C3: OBRAS PRELIMINARES Y RELLENOS
A4: 3 | B4: 01-01-01 | C4: TRAZO LASTRE Y COMPACTACION | D4: =SUMIF('IKARIA TECHO'!B:B,'HORAS MANO DE OBRA'!B4,'IKARIA TECHO'!F:F)
A5: 2 | B5: 01-02 | C5: EXCAVACION
A6: 3 | B6: 01-02-01 | C6: ZANJEO | D6: =SUMIF('IKARIA TECHO'!B:B,'HORAS MANO DE OBRA'!B6,'IKARIA TECHO'!F:F)
A7: 2 | B7: 01-03 | C7: SELLO DE CONCRETO
A8: 3 | B8: 01-03-01 | C8: SELLO | D8: =SUMIF('IKARIA TECHO'!B:B,'HORAS MANO DE OBRA'!B8,'IKARIA TECHO'!F:F)
A9: 2 | B9: 01-04 | C9: LOSA FLOTANTE (ACERO, MECANICO, CONCRETO)
A10: 3 | B10: 01-04-01 | C10: ACERO LOSA | D10: =SUMIF('IKARIA TECHO'!B:B,'HORAS MANO DE OBRA'!B10,'IKARIA TECHO'!F:F)
A11: 3 | B11: 01-04-02 | C11: FORMALETA LOSA | D11: =SUMIF('IKARIA TECHO'!B:B,'HORAS MANO DE OBRA'!B11,'IKARIA TECHO'!F:F)
A12: 3 | B12: 01-04-03 | C12: COLADO LOSA | D12: =SUMIF('IKARIA TECHO'!B:B,'HORAS MANO DE OBRA'!B12,'IKARIA TECHO'!F:F)
A13: 3 | B13: 01-04-04 | C13: INSTALACION MECANICA LOSAS | D13: =SUMIF('IKARIA TECHO'!B:B,'HORAS MANO DE OBRA'!B13,'IKARIA TECHO'!F:F)
A14: 3 | B14: 01-04-05 | C14: POTABLE LOSA | D14: =SUMIF('IKARIA TECHO'!B:B,'HORAS MANO DE OBRA'!B14,'IKARIA TECHO'!F:F)
A15: 1 | B15: 02 | C15: SUPERESTRUCTURAS NI
A16: 2 | B16: 02-01 | C16: ACERO Y MECANICO MUROS N1
A17: 3 | B17: 02-01-01 | C17: ACERO MUROS N1 | D17: =SUMIF('IKARIA TECHO'!B:B,'HORAS MANO DE OBRA'!B17,'IKARIA TECHO'!F:F)
A18: 3 | B18: 02-01-02 | C18: FORMALETA N1 | D18: =SUMIF('IKARIA TECHO'!B:B,'HORAS MANO DE OBRA'!B18,'IKARIA TECHO'!F:F)
A19: 3 | B19: 02-01-03 | C19: INSTALACION MECANICA MUROS N1 | D19: =SUMIF('IKARIA TECHO'!B:B,'HORAS MANO DE OBRA'!B19,'IKARIA TECHO'!F:F)
A20: 2 | B20: 02-02 | C20: COLADO MUROS N1
A21: 3 | B21: 02-02-01 | C21: COLADO MUROS N1 | D21: =SUMIF('IKARIA TECHO'!B:B,'HORAS MANO DE OBRA'!B21,'IKARIA TECHO'!F:F)
A22: 3 | B22: 02-02-02 | C22: TRAZO FORMALETA N1 | D22: =SUMIF('IKARIA TECHO'!B:B,'HORAS MANO DE OBRA'!B22,'IKARIA TECHO'!F:F)
A23: 3 | B23: 02-02-03 | C23: DESENCOFRE MUROS N1 | D23: =SUMIF('IKARIA TECHO'!B:B,'HORAS MANO DE OBRA'!B23,'IKARIA TECHO'!F:F)
A24: 2 | B24: 02-03 | C24: MAMPOSTERIA
A25: 3 | B25: 02-03-01 | C25: MAMPOSTERIA | D25: =SUMIF('IKARIA TECHO'!B:B,'HORAS MANO DE OBRA'!B25,'IKARIA TECHO'!F:F)
A26: 1 | B26: 03 | C26: SUPERESTRUCTURAS N2
A27: 2 | B27: 03-01 | C27: ACERO MUROS N2
A28: 3 | B28: 03-01-01 | C28: ACERO MUROS N2 | D28: =SUMIF('IKARIA TECHO'!B:B,'HORAS MANO DE OBRA'!B28,'IKARIA TECHO'!F:F)
A29: 3 | B29: 03-01-02 | C29: FORMALETA N2 | D29: =SUMIF('IKARIA TECHO'!B:B,'HORAS MANO DE OBRA'!B29,'IKARIA TECHO'!F:F)
A30: 3 | B30: 03-01-03 | C30: INSTALACION MECANICA MUROS N2 | D30: =SUMIF('IKARIA TECHO'!B:B,'HORAS MANO DE OBRA'!B30,'IKARIA TECHO'!F:F)
A31: 2 | B31: 03-02 | C31: COLADO MUROS N2
A32: 3 | B32: 03-02-01 | C32: COLADO MUROS N2 | D32: =SUMIF('IKARIA TECHO'!B:B,'HORAS MANO DE OBRA'!B32,'IKARIA TECHO'!F:F)
A33: 3 | B33: 03-02-02 | C33: TRAZO FORMALETA N2 | D33: =SUMIF('IKARIA TECHO'!B:B,'HORAS MANO DE OBRA'!B33,'IKARIA TECHO'!F:F)
A34: 3 | B34: 03-02-03 | C34: DESENCOFRE MUROS N2 | D34: =SUMIF('IKARIA TECHO'!B:B,'HORAS MANO DE OBRA'!B34,'IKARIA TECHO'!F:F)
A35: 1 | B35: 04 | C35: OTROS GRIS
A36: 2 | B36: 04-01 | C36: GRADAS CONCRETO
A37: 3 | B37: 04-01-01 | C37: ACERO GRADAS N1 | D37: =SUMIF('IKARIA TECHO'!B:B,'HORAS MANO DE OBRA'!B37,'IKARIA TECHO'!F:F)
A38: 3 | B38: 04-01-02 | C38: FORMALETA GRADAS N1 | D38: =SUMIF('IKARIA TECHO'!B:B,'HORAS MANO DE OBRA'!B38,'IKARIA TECHO'!F:F)
A39: 3 | B39: 04-01-03 | C39: COLADO GRADAS N1 | D39: =SUMIF('IKARIA TECHO'!B:B,'HORAS MANO DE OBRA'!B39,'IKARIA TECHO'!F:F)
A40: 3 | B40: 04-01-04 | C40: DESENCOFRE GRADAS N1 | D40: =SUMIF('IKARIA TECHO'!B:B,'HORAS MANO DE OBRA'!B40,'IKARIA TECHO'!F:F)
...

Sheet ANALISIS
B1: CODIGO ACUMATICA | C1: CODIGO | D1: DESCRIPCION | E1: CANTIDAD | F1: PRECIO UNITARIO | G1: PRECIO TOTAL | H1: % PORCENTAJE
B2: =_xlfn.XLOOKUP(C2,'INSUMOS MAT '!B:B,'INSUMOS MAT '!C:C,"ERROR",0) | C2: MAT03-0014 | D2: =_xlfn.XLOOKUP(C2,'IKARIA TECHO'!D:D,'IKARIA TECHO'!E:E,"ERROR",0) | E2: =SUMIF('IKARIA TECHO'!D:D,ANALISIS!C2,'IKARIA TECHO'!F:F) | F2: =_xlfn.XLOOKUP(C2,'IKARIA TECHO'!D:D,'IKARIA TECHO'!H:H,"ERROR",0) | G2: =E2*F2 | H2: =G2/$G$289
B3: =_xlfn.XLOOKUP(C3,'INSUMOS MAT '!B:B,'INSUMOS MAT '!C:C,"ERROR",0) | C3: MAT08-0017 | D3: =_xlfn.XLOOKUP(C3,'IKARIA TECHO'!D:D,'IKARIA TECHO'!E:E,"ERROR",0) | E3: =SUMIF('IKARIA TECHO'!D:D,ANALISIS!C3,'IKARIA TECHO'!F:F) | F3: =_xlfn.XLOOKUP(C3,'IKARIA TECHO'!D:D,'IKARIA TECHO'!H:H,"ERROR",0) | G3: =E3*F3 | H3: =G3/$G$289
B4: =_xlfn.XLOOKUP(C4,'INSUMOS MAT '!B:B,'INSUMOS MAT '!C:C,"ERROR",0) | C4: MAT08-0029 | D4: =_xlfn.XLOOKUP(C4,'IKARIA TECHO'!D:D,'IKARIA TECHO'!E:E,"ERROR",0) | E4: =SUMIF('IKARIA TECHO'!D:D,ANALISIS!C4,'IKARIA TECHO'!F:F) | F4: =_xlfn.XLOOKUP(C4,'IKARIA TECHO'!D:D,'IKARIA TECHO'!H:H,"ERROR",0) | G4: =E4*F4 | H4: =G4/$G$289
B5: =_xlfn.XLOOKUP(C5,'INSUMOS MAT '!B:B,'INSUMOS MAT '!C:C,"ERROR",0) | C5: MAT08-0031 | D5: =_xlfn.XLOOKUP(C5,'IKARIA TECHO'!D:D,'IKARIA TECHO'!E:E,"ERROR",0) | E5: =SUMIF('IKARIA TECHO'!D:D,ANALISIS!C5,'IKARIA TECHO'!F:F) | F5: =_xlfn.XLOOKUP(C5,'IKARIA TECHO'!D:D,'IKARIA TECHO'!H:H,"ERROR",0) | G5: =E5*F5 | H5: =G5/$G$289
B6: =_xlfn.XLOOKUP(C6,'INSUMOS MAT '!B:B,'INSUMOS MAT '!C:C,"ERROR",0) | C6: MAT19-0100 | D6: =_xlfn.XLOOKUP(C6,'IKARIA TECHO'!D:D,'IKARIA TECHO'!E:E,"ERROR",0) | E6: =SUMIF('IKARIA TECHO'!D:D,ANALISIS!C6,'IKARIA TECHO'!F:F) | F6: =_xlfn.XLOOKUP(C6,'IKARIA TECHO'!D:D,'IKARIA TECHO'!H:H,"ERROR",0) | G6: =E6*F6 | H6: =G6/$G$289
B7: =_xlfn.XLOOKUP(C7,'INSUMOS MAT '!B:B,'INSUMOS MAT '!C:C,"ERROR",0) | C7: MAT19-0095 | D7: =_xlfn.XLOOKUP(C7,'IKARIA TECHO'!D:D,'IKARIA TECHO'!E:E,"ERROR",0) | E7: =SUMIF('IKARIA TECHO'!D:D,ANALISIS!C7,'IKARIA TECHO'!F:F) | F7: =_xlfn.XLOOKUP(C7,'IKARIA TECHO'!D:D,'IKARIA TECHO'!H:H,"ERROR",0) | G7: =E7*F7 | H7: =G7/$G$289
B8: =_xlfn.XLOOKUP(C8,'INSUMOS MAT '!B:B,'INSUMOS MAT '!C:C,"ERROR",0) | C8: MAT19-0094 | D8: =_xlfn.XLOOKUP(C8,'IKARIA TECHO'!D:D,'IKARIA TECHO'!E:E,"ERROR",0) | E8: =SUMIF('IKARIA TECHO'!D:D,ANALISIS!C8,'IKARIA TECHO'!F:F) | F8: =_xlfn.XLOOKUP(C8,'IKARIA TECHO'!D:D,'IKARIA TECHO'!H:H,"ERROR",0) | G8: =E8*F8 | H8: =G8/$G$289
B9: =_xlfn.XLOOKUP(C9,'INSUMOS MAT '!B:B,'INSUMOS MAT '!C:C,"ERROR",0) | C9: MAT19-0081 | D9: =_xlfn.XLOOKUP(C9,'IKARIA TECHO'!D:D,'IKARIA TECHO'!E:E,"ERROR",0) | E9: =SUMIF('IKARIA TECHO'!D:D,ANALISIS!C9,'IKARIA TECHO'!F:F) | F9: =_xlfn.XLOOKUP(C9,'IKARIA TECHO'!D:D,'IKARIA TECHO'!H:H,"ERROR",0) | G9: =E9*F9 | H9: =G9/$G$289
B10: =_xlfn.XLOOKUP(C10,'INSUMOS MAT '!B:B,'INSUMOS MAT '!C:C,"ERROR",0) | C10: MAT19-0044 | D10: =_xlfn.XLOOKUP(C10,'IKARIA TECHO'!D:D,'IKARIA TECHO'!E:E,"ERROR",0) | E10: =SUMIF('IKARIA TECHO'!D:D,ANALISIS!C10,'IKARIA TECHO'!F:F) | F10: =_xlfn.XLOOKUP(C10,'IKARIA TECHO'!D:D,'IKARIA TECHO'!H:H,"ERROR",0) | G10: =E10*F10 | H10: =G10/$G$289
B11: =_xlfn.XLOOKUP(C11,'INSUMOS MAT '!B:B,'INSUMOS MAT '!C:C,"ERROR",0) | C11: MAT19-0118 | D11: =_xlfn.XLOOKUP(C11,'IKARIA TECHO'!D:D,'IKARIA TECHO'!E:E,"ERROR",0) | E11: =SUMIF('IKARIA TECHO'!D:D,ANALISIS!C11,'IKARIA TECHO'!F:F) | F11: =_xlfn.XLOOKUP(C11,'IKARIA TECHO'!D:D,'IKARIA TECHO'!H:H,"ERROR",0) | G11: =E11*F11 | H11: =G11/$G$289
B12: =_xlfn.XLOOKUP(C12,'INSUMOS MAT '!B:B,'INSUMOS MAT '!C:C,"ERROR",0) | C12: MAT19-0024 | D12: =_xlfn.XLOOKUP(C12,'IKARIA TECHO'!D:D,'IKARIA TECHO'!E:E,"ERROR",0) | E12: =SUMIF('IKARIA TECHO'!D:D,ANALISIS!C12,'IKARIA TECHO'!F:F) | F12: =_xlfn.XLOOKUP(C12,'IKARIA TECHO'!D:D,'IKARIA TECHO'!H:H,"ERROR",0) | G12: =E12*F12 | H12: =G12/$G$289
