Workbook
Name _Fill: #REF!
Name _Key1: #REF!
Name _Sort: #REF!
Name AR: #REF!
Name area: #REF!
Name Beginning_Balance: -FV(interest_rate/12,payment_number-1,-monthly_payment,loan_amount)
Name Beginning_Balance: -FV(interest_rate/12,payment_number-1,-monthly_payment,loan_amount)
Name Beginning_Balance: -FV(interest_rate/12,payment_number-1,-monthly_payment,loan_amount)
Name Beginning_Balance: -FV(interest_rate/12,payment_number-1,-monthly_payment,loan_amount)
Name CE: #REF!
Name cellbimuser3312070200E1100905702600: 1667853438554
Name CodigoProyecto: Descompuesto!$L$3
Name ds: Detallado!$Q$4
Name ETR: #REF!
Name FAN: '3.1_ELEC'!#REF!
Name FAN: '3.2_MEC'!#REF!
Name FAN: '1_OG y 2_ACA'!$D$112
Name FCL: '3.1_ELEC'!#REF!
Name FCL: '3.2_MEC'!#REF!
Name FCL: '1_OG y 2_ACA'!$D$95
Name FDG: '3.1_ELEC'!#REF!
Name FDG: '3.2_MEC'!#REF!
Name FDG: '1_OG y 2_ACA'!$D$96
Name FILTRAR__Cant_E__D5_D126__Cant_E__F5_F126__0: #REF!
Name KH: 'BASE DATOS EQUIPOS Y SUBCONTRAT'!$P$6
Name ListaObra: #REF!
Name ListaSubTareas: #REF!
Name losaa: '3.1_ELEC'!#REF!
Name losaa: '3.2_MEC'!#REF!
Name losaa: '1_OG y 2_ACA'!$D$102
Name losaac: '1_OG y 2_ACA'!$D$281
Name losaad: '3.1_ELEC'!#REF!
Name losaad: '3.2_MEC'!#REF!
Name losaad: '1_OG y 2_ACA'!$D$105
Name losac: '3.1_ELEC'!#REF!
Name losac: '3.2_MEC'!#REF!
Name losac: '1_OG y 2_ACA'!$D$104
Name losap: '3.1_ELEC'!#REF!
Name losap: '3.2_MEC'!#REF!
Name losap: '1_OG y 2_ACA'!$D$103
Name muroa: '3.1_ELEC'!#REF!
Name muroa: '3.2_MEC'!#REF!
Name muroa: '1_OG y 2_ACA'!$D$106
Name muroad: '3.1_ELEC'!#REF!
Name muroad: '3.2_MEC'!#REF!
Name muroad: '1_OG y 2_ACA'!$D$109
Name muroc: '3.1_ELEC'!#REF!
Name muroc: '3.2_MEC'!#REF!
Name muroc: '1_OG y 2_ACA'!$D$108
Name murof: '3.1_ELEC'!#REF!
Name murof: '3.2_MEC'!#REF!
Name murof: '1_OG y 2_ACA'!$D$110
Name murop: '3.1_ELEC'!#REF!
Name murop: '3.2_MEC'!#REF!
Name murop: '1_OG y 2_ACA'!$D$107
Name PARED_LIV_2P: #REF!
Name PARED_LIV_2P: #REF!
Name PI: #REF!
Name plazo: 'Gastos generales'!$F$6
Name plazo: #REF!

Sheet ANALISIS
C1: CODIGO | D1: DESCRIPCION | E1: CANTIDAD | F1: PRECIO UNITARIO | G1: PRECIO TOTAL | H1: % PORCENTAJE
C2: MAT01-0001 | D2: =_xlfn.XLOOKUP(C2,Detallado!C:C,Detallado!E:E,"ERROR",0) -> ERROR | E2: =SUMIF(Detallado!C:C,ANALISIS!C2,Detallado!F:F) -> 0 | F2: =_xlfn.XLOOKUP(C2,Detallado!C:C,Detallado!H:H,"ERROR",0) -> ERROR | G2: =E2*F2 -> #VALUE! | H2: =G2/$G$313 -> #VALUE! | J2: 35867.2 | K2: 35867.2 | M2: =+K2-G2 -> #VALUE!
C3: MAT01-0002 | D3: =_xlfn.XLOOKUP(C3,Detallado!C:C,Detallado!E:E,"ERROR",0) -> ERROR | E3: =SUMIF(Detallado!C:C,ANALISIS!C3,Detallado!F:F) -> 0 | F3: =_xlfn.XLOOKUP(C3,Detallado!C:C,Detallado!H:H,"ERROR",0) -> ERROR | G3: =E3*F3 -> #VALUE! | H3: =G3/$G$313 -> #VALUE! | J3: 42456 | K3: 42456 | M3: =+K3-G3 -> #VALUE!
C4: MAT01-0005 | D4: =_xlfn.XLOOKUP(C4,Detallado!C:C,Detallado!E:E,"ERROR",0) -> ERROR | E4: =SUMIF(Detallado!C:C,ANALISIS!C4,Detallado!F:F) -> 0 | F4: =_xlfn.XLOOKUP(C4,Detallado!C:C,Detallado!H:H,"ERROR",0) -> ERROR | G4: =E4*F4 -> #VALUE! | H4: =G4/$G$313 -> #VALUE! | J4: 25198.68 | K4: 0 | M4: =+K4-G4 -> #VALUE!
C5: MAT01-0006 | D5: =_xlfn.XLOOKUP(C5,Detallado!C:C,Detallado!E:E,"ERROR",0) -> ERROR | E5: =SUMIF(Detallado!C:C,ANALISIS!C5,Detallado!F:F) -> 0 | F5: =_xlfn.XLOOKUP(C5,Detallado!C:C,Detallado!H:H,"ERROR",0) -> ERROR | G5: =E5*F5 -> #VALUE! | H5: =G5/$G$313 -> #VALUE! | J5: 64593.335 | K5: 64593.335 | M5: =+K5-G5 -> #VALUE!
C6: MAT01-0007 | D6: =_xlfn.XLOOKUP(C6,Detallado!C:C,Detallado!E:E,"ERROR",0) -> ERROR | E6: =SUMIF(Detallado!C:C,ANALISIS!C6,Detallado!F:F) -> 0 | F6: =_xlfn.XLOOKUP(C6,Detallado!C:C,Detallado!H:H,"ERROR",0) -> ERROR | G6: =E6*F6 -> #VALUE! | H6: =G6/$G$313 -> #VALUE! | J6: 33640 | K6: 0 | M6: =+K6-G6 -> #VALUE!
C7: MAT01-0008 | D7: =_xlfn.XLOOKUP(C7,Detallado!C:C,Detallado!E:E,"ERROR",0) -> ERROR | E7: =SUMIF(Detallado!C:C,ANALISIS!C7,Detallado!F:F) -> 0 | F7: =_xlfn.XLOOKUP(C7,Detallado!C:C,Detallado!H:H,"ERROR",0) -> ERROR | G7: =E7*F7 -> #VALUE! | H7: =G7/$G$313 -> #VALUE! | J7: 83520 | K7: 83520 | M7: =+K7-G7 -> #VALUE!
C8: MAT01-0010 | D8: =_xlfn.XLOOKUP(C8,Detallado!C:C,Detallado!E:E,"ERROR",0) -> ERROR | E8: =SUMIF(Detallado!C:C,ANALISIS!C8,Detallado!F:F) -> 0 | F8: =_xlfn.XLOOKUP(C8,Detallado!C:C,Detallado!H:H,"ERROR",0) -> ERROR | G8: =E8*F8 -> #VALUE! | H8: =G8/$G$313 -> #VALUE! | J8: 25520 | K8: 25520 | M8: =+K8-G8 -> #VALUE!
C9: MAT01-0011 | D9: =_xlfn.XLOOKUP(C9,Detallado!C:C,Detallado!E:E,"ERROR",0) -> ERROR | E9: =SUMIF(Detallado!C:C,ANALISIS!C9,Detallado!F:F) -> 0 | F9: =_xlfn.XLOOKUP(C9,Detallado!C:C,Detallado!H:H,"ERROR",0) -> ERROR | G9: =E9*F9 -> #VALUE! | H9: =G9/$G$313 -> #VALUE! | J9: 26100 | K9: 0 | M9: =+K9-G9 -> #VALUE!
C10: MAT01-0012 | D10: =_xlfn.XLOOKUP(C10,Detallado!C:C,Detallado!E:E,"ERROR",0) -> ERROR | E10: =SUMIF(Detallado!C:C,ANALISIS!C10,Detallado!F:F) -> 0 | F10: =_xlfn.XLOOKUP(C10,Detallado!C:C,Detallado!H:H,"ERROR",0) -> ERROR | G10: =E10*F10 -> #VALUE! | H10: =G10/$G$313 -> #VALUE! | J10: 40426 | K10: 0 | M10: =+K10-G10 -> #VALUE!
C11: MAT01-0025 | D11: =_xlfn.XLOOKUP(C11,Detallado!C:C,Detallado!E:E,"ERROR",0) -> ERROR | E11: =SUMIF(Detallado!C:C,ANALISIS!C11,Detallado!F:F) -> 0 | F11: =_xlfn.XLOOKUP(C11,Detallado!C:C,Detallado!H:H,"ERROR",0) -> ERROR | G11: =E11*F11 -> #VALUE! | H11: =G11/$G$313 -> #VALUE! | J11: 102654.87 | K11: 102654.87 | M11: =+K11-G11 -> #VALUE!
C12: MAT02-0001 | D12: =_xlfn.XLOOKUP(C12,Detallado!C:C,Detallado!E:E,"ERROR",0) -> ERROR | E12: =SUMIF(Detallado!C:C,ANALISIS!C12,Detallado!F:F) -> 0 | F12: =_xlfn.XLOOKUP(C12,Detallado!C:C,Detallado!H:H,"ERROR",0) -> ERROR | G12: =E12*F12 -> #VALUE! | H12: =G12/$G$313 -> #VALUE! | J12: 866.02808 | K12: 54559.769 | M12: =+K12-G12 -> #VALUE!
C13: MAT02-0010 | D13: =_xlfn.XLOOKUP(C13,Detallado!C:C,Detallado!E:E,"ERROR",0) -> ERROR | E13: =SUMIF(Detallado!C:C,ANALISIS!C13,Detallado!F:F) -> 0 | F13: =_xlfn.XLOOKUP(C13,Detallado!C:C,Detallado!H:H,"ERROR",0) -> ERROR | G13: =E13*F13 -> #VALUE! | H13: =G13/$G$313 -> #VALUE! | J13: 27221.952 | K13: 299441.47 | M13: =+K13-G13 -> #VALUE!
... C309: TABLATECK 8 | D309: =_xlfn.XLOOKUP(C309,Detallado!C:C,Detallado!E:E,"ERROR",0) -> ERROR | E309: =SUMIF(Detallado!C:C,ANALISIS!C309,Detallado!F:F) -> 0 | F309: =_xlfn.XLOOKUP(C309,Detallado!C:C,Detallado!H:H,"ERROR",0) -> ERROR | G309: =E309*F309 -> #VALUE! | H309: =G309/$G$313 -> #VALUE! | J309: 1172.5664 | K309: 4690.2655 | M309: =+K309-G309 -> #VALUE!
D310: =_xlfn.XLOOKUP(C310,Detallado!C:C,Detallado!E:E,"ERROR",0) -> TOTAL PRESUPUESTO | E310: =SUMIF(Detallado!C:C,ANALISIS!C310,Detallado!F:F) -> 0 | F310: =_xlfn.XLOOKUP(C310,Detallado!C:C,Detallado!H:H,"ERROR",0) -> 0 | G310: =E310*F310 -> 0 | H310: =G310/$G$313 -> #VALUE!
F313: Total | G313: =SUM(G2:G312) -> #VALUE! | H313: =SUM(H2:H312) -> #VALUE!
F315: Verificacion | G315: =Detallado!K8 -> 23471758
F316: Diferencia | G316: =G313-G315 -> #VALUE!
G318: 15693774

Sheet DESGLOSE
A3: N° | B3: DESCRIPCION | C3: CANTIDAD | D3: UNIDAD | E3: TOTAL MATERIAL | F3: TOTAL MANO DE OBRA | G3: TOTAL SUB/EQUIPOS | H3: TOTAL DIRECTO COLONES | I3: TOTAL DÓLARES | J3: COSTO/M2
A4: 1 | B4: FUNDACIONES | C4: =+'1_OG y 2_ACA'!D12 -> 48.12 | D4: m2 | E4: =SUM(E5:E8) -> 1835286.7 | F4: =SUM(F5:F8) -> 1179900 | G4: =SUM(G5:G8) -> 151000 | H4: =SUM(H5:H8) -> 3166186.7 | I4: =SUM(I5:I8) -> 6147.9354 | J4: =H4/C4 -> 65797.729
A5: 1.1 | B5: OBRAS PRELIMINARES Y RELLENOS | C5: =+C4 -> 48.12 | D5: m2 | E5: =Detallado!K11 -> 276899.83 | F5: =Detallado!L11 -> 168187.5 | G5: =Detallado!M11 -> 151000 | H5: =Detallado!N11 -> 596087.33 | I5: =Detallado!O11 -> 1157.4511 | J5: =H5/C5 -> 12387.517
A6: 1.2 | B6: EXCAVACIÓN Y TUBERÍAS MECÁNICAS (INCLUYE ACOMETIDA) | C6: =+C4 -> 48.12 | D6: m2 | E6: =Detallado!K21 -> 13982.942 | F6: =Detallado!L21 -> 131962.5 | G6: =Detallado!M21 -> 0 | H6: =Detallado!N21 -> 145945.44 | I6: =Detallado!O21 -> 283.38921 | J6: =H6/C6 -> 3032.9477
A7: 1.3 | B7: SELLO DE CONCRETO | C7: =+C4 -> 48.12 | D7: m2 | E7: =Detallado!K28 -> 157774.98 | F7: =Detallado!L28 -> 23287.5 | G7: =Detallado!M28 -> 0 | H7: =Detallado!N28 -> 181062.48 | I7: =Detallado!O28 -> 351.57762 | J7: =H7/C7 -> 3762.7281
A8: 1.4 | B8: LOSA FLOTANTE (ACERO, ELECTROMECANICOS, CONCRETO) | C8: =+C4 -> 48.12 | D8: m2 | E8: =Detallado!K37 -> 1386629 | F8: =Detallado!L37 -> 856462.5 | G8: =Detallado!M37 -> 0 | H8: =Detallado!N37 -> 2243091.5 | I8: =Detallado!O37 -> 4355.5174 | J8: =H8/C8 -> 46614.536 | L8: MAT | M8: M.O
A9: 2 | B9: SUPERESTRUCTURA PRIMER NIVEL | C9: =C10 -> 129.48 | D9: m2 | E9: =SUM(E10:E12) -> 2432321.8 | F9: =SUM(F10:F12) -> 2093287.5 | G9: =SUM(G10:G12) -> 276815.7 | H9: =SUM(H10:H12) -> 4802425 | I9: =SUM(I10:I12) -> 9325.097 | J9: =H9/C9 -> 37090.091 | L9: 2702858.3 | M9: 959962.5
A10: 2.1 | B10: ACERO EN PAREDES MUROS N1 (ELECTROMECANICO) | C10: =+'1_OG y 2_ACA'!D343 -> 129.48 | D10: m2 | E10: =Detallado!K55 -> 704662.5 | F10: =Detallado!L55 -> 1112625 | G10: =Detallado!M55 -> 0 | H10: =Detallado!N55 -> 1817287.5 | I10: =Detallado!O55 -> 3528.7136 | J10: =H10/C10 -> 14035.276 | K10: ACERO Y CONCRETO | L10: =+L9-E9 -> 270536.54 | M10: =+M9-F9 -> -1133325
A11: 2.2 | B11: PAREDES, MUROS, ENTREPISO N1 (FORMALETA, CONCRETO, DESENCOFRADO) | C11: =+C10 -> 129.48 | D11: m2 | E11: =Detallado!K68 -> 1727659.3 | F11: =Detallado!L68 -> 980662.5 | G11: =Detallado!M68 -> 276815.7 | H11: =Detallado!N68 -> 2985137.5 | I11: =Detallado!O68 -> 5796.3834 | J11: =H11/C11 -> 23054.815 | K11: ACABADO AZOTEA
A12: 2.3 | B12: MAMPOSTERIA | C12: 1 | D12: Global | E12: =Detallado!K84 -> 0 | F12: =Detallado!L84 -> 0 | G12: =Detallado!M84 -> 0 | H12: =Detallado!N84 -> 0 | I12: =Detallado!O84 -> 0 | J12: =H12/C12 -> 0
A13: 3 | B13: SUPERESTRUCTURA SEGUNDO NIVEL | C13: 1 | D13: Global | E13: =SUM(E14:E15) -> 1979575 | F13: =SUM(F14:F15) -> 1283400 | G13: =SUM(G14:G15) -> 254144.45 | H13: =SUM(H14:H15) -> 3570907.5 | I13: =SUM(I14:I15) -> 6829.3582 | J13: =H13/C13 -> 3570907.5
A14: 3.1 | B14: ACERO EN PAREDES MUROS N2 (ELECTROMECANICO) | C14: 1 | D14: Global | E14: =Detallado!K89 -> 423822.75 | F14: =Detallado!L89 -> 859050 | G14: =Detallado!M89 -> 0 | H14: =Detallado!N89 -> 1336660.7 | I14: =Detallado!O89 -> 2491.015 | J14: =H14/C14 -> 1336660.7
A15: 3.2 | B15: PAREDES, MUROS, ENTREPISO N2 (FORMALETA, CONCRETO, DESENCOFRADO) | C15: 1 | D15: Global | E15: =Detallado!K101 -> 1555752.3 | F15: =Detallado!L101 -> 424350 | G15: =Detallado!M101 -> 254144.45 | H15: =Detallado!N101 -> 2234246.7 | I15: =Detallado!O101 -> 4338.3432 | J15: =H15/C15 -> 2234246.7
A16: 4 | B16: OTROS GRIS | C16: 1 | D16: Global | E16: =SUM(E17:E19) -> 1212110.7 | F16: =SUM(F17:F19) -> 1304100 | G16: =SUM(G17:G19) -> 59260.2 | H16: =SUM(H17:H19) -> 2575470.9 | I16: =SUM(I17:I19) -> 5000.9143 | J16: =H16/C16 -> 2575470.9
A17: 4.1 | B17: GRADAS EN CONCRETO | C17: 1 | D17: Global | E17: =Detallado!K254 -> 341339.46 | F17: =Detallado!L254 -> 543375 | G17: =Detallado!M254 -> 44260.2 | H17: =Detallado!N254 -> 928974.66 | I17: =Detallado!O254 -> 1803.8343 | J17: =H17/C17 -> 928974.66
A18: 4.2 | B18: COLUMNAS (MEDIDOR) | C18: 1 | D18: Global | E18: =Detallado!K269 -> 89072.417 | F18: =Detallado!L269 -> 152662.5 | G18: =Detallado!M269 -> 0 | H18: =Detallado!N269 -> 241734.92 | I18: =Detallado!O269 -> 469.38819 | J18: =H18/C18 -> 241734.92
A19: 4.3 | B19: CHORREA DE COCHERAS Y PILAS | C19: 33.01 | D19: m2 | E19: =Detallado!K282 -> 781698.78 | F19: =Detallado!L282 -> 608062.5 | G19: =Detallado!M282 -> 15000 | H19: =Detallado!N282 -> 1404761.3 | I19: =Detallado!O282 -> 2727.6918 | J19: =H19/C19 -> 42555.628
A20: 5 | B20: ESTRUCTURA METÁLICA Y CUBIERTAS | C20: =C21+C22 -> 60.8 | D20: m2 | E20: =SUM(E21:E28) -> 1467743.8 | F20: =SUM(F21:F28) -> 2632312.5 | G20: =SUM(G21:G28) -> 0 | H20: =SUM(H21:H28) -> 4100056.3 | I20: =SUM(I21:I28) -> 7961.2743 | J20: =H20/C20 -> 67435.136
A21: 5.1 | B21: ESTRUCTURA TECHO CASA | C21: =+'1_OG y 2_ACA'!E724 -> 44.8 | D21: m2 | E21: =Detallado!K116 -> 729007.47 | F21: =Detallado!L116 -> 1047000 | G21: =Detallado!M116 -> 0 | H21: =Detallado!N116 -> 1776007.5 | I21: =Detallado!O116 -> 3448.5582 | J21: =H21/C21 -> 39643.024
A22: 5.2 | B22: ESTRUCTURA TECHO COCHERA | C22: =+'1_OG y 2_ACA'!E797 -> 16 | D22: m2 | E22: =Detallado!K144 -> 263802.06 | F22: =Detallado!L144 -> 408000 | G22: =Detallado!M144 -> 0 | H22: =Detallado!N144 -> 671802.06 | I22: =Detallado!O144 -> 1304.47 | J22: =H22/C22 -> 41987.629
A23: 5.3 | B23: CUBIERTA TECHO CASA | C23: =+C21 -> 44.8 | D23: m2 | E23: =Detallado!K168 -> 150159.27 | F23: =Detallado!L168 -> 403650 | G23: =Detallado!M168 -> 0 | H23: =Detallado!N168 -> 553809.27 | I23: =Detallado!O168 -> 1075.3578 | J23: =H23/C23 -> 12361.814
A24: 5.4 | B24: CUBIERTA TECHO COCHERA | C24: =+C22 -> 16 | D24: Global | E24: =Detallado!K175 -> 0 | F24: =Detallado!L175 -> 0 | G24: =Detallado!M175 -> 0 | H24: =Detallado!N175 -> 0 | I24: =Detallado!O175 -> 0 | J24: =H24/C24 -> 0
A25: 5.5 | B25: HOJALATERIA Y CANOAS | C25: 1 | D25: Global | E25: =Detallado!K237 -> 143392.11 | F25: =Detallado!L237 -> 553725 | G25: =Detallado!M237 -> 0 | H25: =Detallado!N237 -> 697117.11 | I25: =Detallado!O237 -> 1353.6255 | J25: =H25/C25 -> 697117.11
A26: 5.6 | B26: GRADAS ESTRUCTURA, PINTADO Y ACABADO | C26: 1 | D26: Global | E26: =Detallado!K187 -> 0 | F26: =Detallado!L187 -> 0 | G26: =Detallado!M187 -> 0 | H26: =Detallado!N187 -> 0 | I26: =Detallado!O187 -> 0 | J26: =H26/C26 -> 0
A27: 5.7 | B27: BARANDA DE GRADAS (N2) | C27: 1 | D27: Global | E27: =Detallado!K213 -> 181382.87 | F27: =Detallado!L213 -> 219937.5 | G27: =Detallado!M213 -> 0 | H27: =Detallado!N213 -> 401320.37 | I27: =Detallado!O213 -> 779.26286 | J27: =H27/C27 -> 401320.37
A28: 5.8 | B28: ESTRUCTURA METÁLICA INTERNA | C28: 1 | D28: Global | E28: =Detallado!K229 -> 0 | F28: =Detallado!L229 -> 0 | G28: =Detallado!M229 -> 0 | H28: =Detallado!N229 -> 0 | I28: =Detallado!O229 -> 0 | J28: =H28/C28 -> 0
A29: 6 | B29: LIVIANO | C29: =C30+C31 -> 105.45 | D29: m2 | E29: =SUM(E30:E31) -> 1635299.4 | F29: =SUM(F30:F31) -> 540787.5 | G29: =SUM(G30:G31) -> 0 | H29: =SUM(H30:H31) -> 2176086.9 | I29: =SUM(I30:I31) -> 4225.4114 | J29: =H29/C29 -> 20636.196
A30: 6.1 | B30: LIVIANO EXTERIORES | C30: =+'1_OG y 2_ACA'!D1299+'1_OG y 2_ACA'!D1318+'1_OG y 2_ACA'!D1341 -> 52.55 | D30: m2 | E30: =Detallado!K323 -> 514909.4 | F30: =Detallado!L323 -> 243225 | G30: =Detallado!M323 -> 0 | H30: =Detallado!N323 -> 758134.4 | I30: =Detallado!O323 -> 1472.1056 | J30: =H30/C30 -> 14426.915
A31: 6.2 | B31: LIVIANO INTERIORES ( PAREDES LIVIANAS Y CIELOS) | C31: =+'1_OG y 2_ACA'!D1366+'1_OG y 2_ACA'!E1390 -> 52.9 | D31: m2 | E31: =Detallado!K361 -> 1120390 | F31: =Detallado!L361 -> 297562.5 | G31: =Detallado!M361 -> 0 | H31: =Detallado!N361 -> 1417952.5 | I31: =Detallado!O361 -> 2753.3058 | J31: =H31/C31 -> 26804.395
A32: 7 | B32: REPELLOS | C32: =C33 -> 474.2825 | D32: m2 | E32: =SUM(E33:E34) -> 1229814.6 | F32: =SUM(F33:F34) -> 1278225 | G32: =SUM(G33:G34) -> 0 | H32: =SUM(H33:H34) -> 2508039.6 | I32: =SUM(I33:I34) -> 4869.9797 | J32: =H32/C32 -> 5288.0711
A33: 7.1 | B33: REPELLOS INTERNO Y EXTERNO | C33: =+'1_OG y 2_ACA'!D1453 -> 474.2825 | D33: m2 | E33: =Detallado!K395 -> 960861.6 | F33: =Detallado!L395 -> 1014300 | G33: =Detallado!M395 -> 0 | H33: =Detallado!N395 -> 1975161.6 | I33: =Detallado!O395 -> 3835.2652 | J33: =H33/C33 -> 4164.5256
A34: 7.2 | B34: EMPASTE | C34: =+'1_OG y 2_ACA'!D1465 -> 225.0125 | D34: m2 | E34: =Detallado!K399 -> 268952.96 | F34: =Detallado!L399 -> 263925 | G34: =Detallado!M399 -> 0 | H34: =Detallado!N399 -> 532877.96 | I34: =Detallado!O399 -> 1034.7145 | J34: =H34/C34 -> 2368.2149
A35: 8 | B35: ENCHAPES | C35: 1 | D35: Global | E35: =E36 -> 844081.25 | F35: =F36 -> 626175 | G35: =G36 -> 0 | H35: =H36 -> 1470256.3 | I35: =I36 -> 2854.8665 | J35: =H35/C35 -> 1470256.3
A36: 8.1 | B36: ENCHAPES (INTERNO Y EXTERNO) | C36: =+'1_OG y 2_ACA'!D1489+'1_OG y 2_ACA'!D1550+'1_OG y 2_ACA'!D1509+'1_OG y 2_ACA'!#REF! -> #REF! | D36: m2 | E36: =Detallado!K407 -> 844081.25 | F36: =Detallado!L407 -> 626175 | G36: =Detallado!M407 -> 0 | H36: =Detallado!N407 -> 1470256.3 | I36: =Detallado!O407 -> 2854.8665 | J36: =H36/C36 -> #REF!
A37: 9 | B37: MUEBLES Y PUERTAS | C37: 1 | D37: Global | E37: =SUM(E38:E39) -> 3664782.7 | F37: =SUM(F38:F39) -> 618262.5 | G37: =SUM(G38:G39) -> 268000 | H37: =SUM(H38:H39) -> 4551045.2 | I37: =SUM(I38:I39) -> 8836.9809 | J37: =H37/C37 -> 4551045.2
A38: 9.1 | B38: MUEBLES | C38: 5 | D38: un | E38: =Detallado!K477 -> 1806677.9 | F38: =Detallado!L477 -> 300000 | G38: =Detallado!M477 -> 268000 | H38: =Detallado!N477 -> 2374677.9 | I38: =Detallado!O477 -> 4611.025 | J38: =H38/C38 -> 474935.57
A39: 9.2 | B39: PUERTAS Y RODAPIE | C39: 1 | D39: Global | E39: =Detallado!K513 -> 1858104.8 | F39: =Detallado!L513 -> 318262.5 | G39: =Detallado!M513 -> 0 | H39: =Detallado!N513 -> 2176367.3 | I39: =Detallado!O513 -> 4225.956 | J39: =H39/C39 -> 2176367.3
A40: 10 | B40: OBRAS ADICIONALES | C40: 1 | D40: Global | E40: =SUM(E41:E43) -> 670539.01 | F40: =SUM(F41:F43) -> 455400 | G40: =SUM(G41:G43) -> 0 | H40: =SUM(H41:H43) -> 1125939 | I40: =SUM(I41:I43) -> 2186.2893 | J40: =H40/C40 -> 1125939
A41: 10.1 | B41: ZACATE | C41: =+Detallado!F549 -> 36.34 | D41: m2 | E41: =Detallado!K549 -> 195691.58 | F41: =Detallado!L549 -> 150075 | G41: =Detallado!M549 -> 0 | H41: =Detallado!N549 -> 345766.58 | I41: =Detallado!O549 -> 671.39142 | J41: =H41/C41 -> 9514.7656
A42: 10.2 | B42: TAPIAS PREFABRICADAS | C42: =+Detallado!#REF! -> #REF! | D42: m | E42: =Detallado!K299 -> 277853.73 | F42: =Detallado!L299 -> 144900 | G42: =Detallado!M299 -> 0 | H42: =Detallado!N299 -> 422753.73 | I42: =Detallado!O299 -> 820.88103 | J42: =H42/C42 -> #REF!
...

Sheet Resumen Presupuesto
A1: , | B1: ESTIMADO ZANTE AZOTEA | G1: TIPO CAMBIO | H1: 505
A3: N° | B3: Actividad | C3: Cantidad | D3: Unidad | E3: COSTO M2 | F3: TOTAL
A5: 1 | B5: OBRA GRIS
A6: 1.1 | B6: FUNDACIONES
A7: 1.1.1 | B7: TRAZADO Y RELLENOS | C7: =+Detallado!F11 -> 57.62 | D7: m2 | E7: =F7/C7 -> 10345.146 | F7: =Detallado!N11 -> 596087.33 | I7: N11
A8: 1.1.2 | B8: EXCAVACIÓN | C8: =+Detallado!F21 -> 57.62 | D8: m2 | E8: =F8/C8 -> 2532.8956 | F8: =Detallado!N21 -> 145945.44 | I8: N20
A9: 1.1.3 | B9: SELLO DE CONCRETO | C9: =+Detallado!F28 -> 48.12 | D9: m2 | E9: =F9/C9 -> 3762.7281 | F9: =Detallado!N28 -> 181062.48 | I9: N29
A10: 1.1.4 | B10: LOSA FLOTANTE (ACERO, CONCRETO, FORMALETA) | C10: =+Detallado!F37 -> 48.12 | D10: m2 | E10: =F10/C10 -> 46614.536 | F10: =Detallado!N37 -> 2243091.5 | I10: N40
B12: TOTAL LOSAS | C12: =+C8 -> 57.62 | D12: m2 | E12: =+F12/C12 -> 54949.44 | F12: =+SUBTOTAL(9,F7:F10) -> 3166186.7
A14: 1.2 | B14: MUROS N1 Y N2, ENTREPISO
A15: 1.2.1 | B15: ACERO EN PAREDES MUROS N1 | C15: =+Detallado!F55 -> 129.48 | D15: m2 | E15: =F15/C15 -> 14035.276 | F15: =Detallado!N55 -> 1817287.5 | I15: N60
A16: 1.2.2 | B16: PAREDES, MUROS, ENTREPISO N1 | C16: =+Detallado!F68 -> 129.48 | D16: m2 | E16: =F16/C16 -> 23054.815 | F16: =Detallado!N68 -> 2985137.5 | I16: N72
A17: 1.2.3 | B17: MAMPOSTERIA | C17: =+Detallado!F84 -> 1 | D17: Global | E17: =F17/C17 -> 0 | F17: =Detallado!N84 -> 0 | I17: N85
A18: 1.2.4 | B18: ACERO EN PAREDES MUROS N2 | C18: =+Detallado!F89 -> 132.88 | D18: Global | E18: =F18/C18 -> 10059.157 | F18: =Detallado!N89 -> 1336660.7 | I18: N90
A19: 1.2.5 | B19: PAREDES, MUROS, ENTREPISO N2 | C19: =+Detallado!F101 -> 132.88 | D19: Global | E19: =F19/C19 -> 16814.018 | F19: =Detallado!N101 -> 2234246.7 | I19: N102
B21: TOTAL MUROS PRIMER Y SEGUNDO NIVEL | C21: =C15 -> 129.48 | D21: m2 | E21: =+F21/C21 -> 64668.925 | F21: =+SUBTOTAL(9,F15:F19) -> 8373332.4
A23: 1.3 | B23: ESTRUCTURA METÁLICA Y CUBIERTAS
A24: 1.3.1 | B24: ESTRUCTURA TECHO CASA | C24: =+Detallado!F116 -> 44.8 | D24: m2 | E24: =F24/C24 -> 39643.024 | F24: =Detallado!N116 -> 1776007.5 | I24: N118
A25: 1.3.2 | B25: ESTRUCTURA TECHO COCHERA | C25: =+Detallado!F144 -> 16 | D25: m2 | E25: =F25/C25 -> 41987.629 | F25: =Detallado!N144 -> 671802.06 | I25: N138
A26: 1.3.3 | B26: CUBIERTA TECHO CASA | C26: =+Detallado!F168 -> 44.8 | D26: m2 | E26: =F26/C26 -> 12361.814 | F26: =Detallado!N168 -> 553809.27 | I26: N158
A27: 1.3.4 | B27: CUBIERTA TECHO COCHERA | C27: =+Detallado!F175 -> 16 | D27: m2 | E27: =F27/C27 -> 0 | F27: =Detallado!N175 -> 0 | I27: N165
A28: 1.3.5 | B28: GRADAS ESTRUCTURA, PINTADO Y ACABADO | C28: =+Detallado!F187 -> 1 | D28: Global | E28: =F28/C28 -> 0 | F28: =Detallado!N187 -> 0 | I28: N177
A29: 1.3.6 | B29: BARANDA DE GRADAS (N2) | C29: =+Detallado!F213 -> 1 | D29: Global | E29: =F29/C29 -> 401320.37 | F29: =Detallado!N213 -> 401320.37 | I29: N203
A30: 1.3.7 | B30: ESTRUCTURA METÁLICA INTERNA | C30: =+Detallado!F229 -> 1 | D30: Global | E30: =F30/C30 -> 0 | F30: =Detallado!N229 -> 0 | I30: N219
B32: TOTAL ESTRUCT METÁLICA Y CUBIERTAS | C32: =C24+C25 -> 60.8 | D32: m2 | E32: =+F32/C32 -> 55969.394 | F32: =+SUBTOTAL(9,F24:F30) -> 3402939.2
A34: 1.4 | B34: HOJALATERIA
A35: 1.4.1 | B35: CANOAS Y BOTAGUAS | C35: =+Detallado!F237 -> 1 | D35: Global | E35: =F35/C35 -> 697117.11 | F35: =Detallado!N237 -> 697117.11 | I35: N228
A36: 1.4.2 | B36: BAJANTES | C36: =+Detallado!F248 -> 1 | D36: Global | E36: =F36/C36 -> 177676.52 | F36: =Detallado!N248 -> 177676.52 | I36: N240
B38: TOTAL HOJALATERIA | C38: =C35+C36 -> 2 | D38: m2 | E38: =+F38/C38 -> 437396.81 | F38: =+SUBTOTAL(9,F35:F36) -> 874793.63
A40: 1.5 | B40: OBRAS COMPLEMENTARIAS
A41: 1.5.1 | B41: GRADAS EN CONCRETO | C41: =+Detallado!F253 -> 1 | D41: Global | E41: =F41/C41 -> 928974.66 | F41: =Detallado!N254 -> 928974.66 | I41: N247
A42: 1.5.2 | B42: COLUMNAS (MEDIDOR) | C42: =+Detallado!F269 -> 1 | D42: Global | E42: =F42/C42 -> 241734.92 | F42: =Detallado!N269 -> 241734.92
A43: 1.5.3 | B43: CHORREA DE COCHERAS Y PILAS | C43: =+Detallado!F282 -> 39.3 | D43: m2 | E43: =F43/C43 -> 35744.562 | F43: =Detallado!N282 -> 1404761.3
A44: 1.5.4 | B44: TAPIAS PREFABRICADAS | C44: =+Detallado!F299 -> 8.5 | D44: m | E44: =F44/C44 -> 49735.733 | F44: =Detallado!N299 -> 422753.73
A45: 1.5.5 | B45: ACERAS | C45: =+Detallado!F312 -> 12.24 | D45: m2 | E45: =F45/C45 -> 29200.874 | F45: =Detallado!N312 -> 357418.7
B47: TOTAL OBRAS COMPLEMENTARIAS | C47: 1 | D47: Global | E47: =+F47/C47 -> 3355643.3 | F47: =+SUBTOTAL(9,F41:F45) -> 3355643.3
A49: 1.6 | B49: LIVIANO
A50: 1.6.1 | B50: LIVIANO EXTERIORES (PRECINTA Y TAPICHELES, ALEROS) | C50: =+Detallado!F324+Detallado!F334+Detallado!F345 -> 52.55 | D50: m2 | E50: =F50/C50 -> 14426.915 | F50: =Detallado!N323 -> 758134.4
A51: 1.6.2 | B51: LIVIANO INTERIORES ( PAREDES LIVIANAS Y CIELOS) | C51: =+Detallado!F362+Detallado!F375 -> 52.9 | D51: m2 | E51: =F51/C51 -> 26804.395 | F51: =Detallado!N361 -> 1417952.5
B53: TOTAL LIVIANO | C53: =C50+C51 -> 105.45 | D53: m2 | E53: =+F53/C53 -> 20636.196 | F53: =+SUBTOTAL(9,F50:F51) -> 2176086.9
...

Sheet Descompuesto
A1: N Obra | B1: N Linea | C1: N Actividad | D1: Descripcion actividad | E1: Tipo Tarea | F1: Tipo | G1: N° | H1: Cantidad | I1: Unit Mat | J1: Variante
A2: VN-L.32 | B2: 1 | C2: 1.1 | D2: LASTRE FINO | E2: Auxiliar | F2: Artículo | G2: M10-0023 | H2: 19 | I2: 14166.663 | L2: PROYECTO
A3: VN-L.32 | B3: 2 | C3: 1.1 | D3: BOLSA CAL | E3: Auxiliar | F3: Artículo | G3: M06-0163 | H3: 2 | I3: 1627.2 | L3: ='1_OG y 2_ACA'!E3 -> VN-L.32
A4: VN-L.32 | B4: 3 | C4: 1.1 | D4: CRAYON LYRA AMARILLO | E4: Auxiliar | F4: Artículo | G4: M06-0179 | H4: 6 | I4: 340.017
A5: VN-L.32 | B5: 4 | C5: 1.1 | D5: CUERDA ALBAÑIL BLANCA | E5: Auxiliar | F5: Artículo | G5: M06-0180 | H5: 7 | I5: 812.9107
A6: VN-L.32 | B6: 5 | C6: 1.1 | D6: ARENA LAVADA | E6: Auxiliar | F6: Artículo | G6: M10-0010 | H6: 0.5 | I6: 12044.501
A7: VN-L.32 | B7: 6 | C7: 1.1 | D7: MECHA BLANCA | E7: Auxiliar | F7: Artículo | G7: M06-0231 | H7: 1 | I7: 4338.0022
A8: VN-L.32 | B8: 7 | C8: 1.1 | D8: ACETONA | E8: Auxiliar | F8: Artículo | G8: M06-0123 | H8: 1 | I8: 2809.7789
A9: VN-L.32 | B9: 8 | C9: 1.1 | D9: TUBO 1X2X1.5MM HN | E9: Auxiliar | F9: Artículo | G9: M01-0067 | H9: 1 | I9: 14238
A10: VN-L.32 | B10: 9 | C10: 1.1 | D10: VARILLA DEFORME #4 | E10: Auxiliar | F10: Artículo | G10: M01-0148 | H10: 1 | I10: 2395.6
A11: VN-L.32 | B11: 10 | C11: 1.1 | D11: REGLA SEMIDURO 1X3X4 SIN CEPILLAR | E11: Auxiliar | F11: Artículo | G11: M09-0042 | H11: 5 | I11: 1524.9915
A12: VN-L.32 | B12: 11 | C12: 1.1 | D12: CONCRETO FC 120 CM2 (Concreto Pobre, Sello) | E12: Auxiliar | F12: Artículo | G12: M10-0091 | H12: 2.406 | I12: 54479.503
A13: VN-L.32 | B13: 12 | C13: 1.1 | D13: ADITIVO ERGO 4000 PG50 | E13: Auxiliar | F13: Artículo | G13: M10-0009 | H13: 8 | I13: 748.625
A14: VN-L.32 | B14: 13 | C14: 1.1 | D14: VARILLA DEFORME #2 | E14: Auxiliar | F14: Artículo | G14: M01-0146 | H14: 53 | I14: 569.8025
A15: VN-L.32 | B15: 14 | C15: 1.1 | D15: VARILLA DEFORME #3 | E15: Auxiliar | F15: Artículo | G15: M01-0147 | H15: 361 | I15: 1344.7 | J15: 02
A16: VN-L.32 | B16: 16 | C16: 1.1 | D16: ALAMBRE NEGRO #16 (1.68MM) | E16: Auxiliar | F16: Artículo | G16: M01-0001 | H16: 58 | I16: 586.8542
A17: VN-L.32 | B17: 17 | C17: 1.1 | D17: SEPARADOR TIPO CONO 2.5CM (1") SP125 | E17: Auxiliar | F17: Artículo | G17: M06-0261 | H17: 49 | I17: 56.5
A18: VN-L.32 | B18: 18 | C18: 1.1 | D18: SEPARADORES TIPO CONO 12CM SP450 | E18: Auxiliar | F18: Artículo | G18: M06-0264 | H18: 49 | I18: 203.4
A19: VN-L.32 | B19: 19 | C19: 1.1 | D19: DISCO CORTE METAL FINO 9" | E19: Auxiliar | F19: Artículo | G19: M08-0037 | H19: 7 | I19: 3037.6321
A20: VN-L.32 | B20: 20 | C20: 1.1 | D20: CONCRETO FC 210 KG/CM2 NORMAL | E20: Auxiliar | F20: Artículo | G20: M10-0065 | H20: 10.1052 | I20: 78867.084
A21: VN-L.32 | B21: 21 | C21: 1.2 | D21: VARILLA DEFORME #2 | E21: Auxiliar | F21: Artículo | G21: M01-0146 | H21: 6 | I21: 569.8025
A22: VN-L.32 | B22: 22 | C22: 1.2 | D22: VARILLA DEFORME #3 | E22: Auxiliar | F22: Artículo | G22: M01-0147 | H22: 146 | I22: 1344.7 | J22: 01
A23: VN-L.32 | B23: 23 | C23: 1.2 | D23: VARILLA DEFORME #3 | E23: Auxiliar | F23: Artículo | G23: M01-0147 | H23: 323 | I23: 1344.7 | J23: 02
A24: VN-L.32 | B24: 24 | C24: 1.2 | D24: VARILLA DEFORME #4 | E24: Auxiliar | F24: Artículo | G24: M01-0148 | H24: 78.5 | I24: 2395.6
A25: VN-L.32 | B25: 25 | C25: 1.2 | D25: MALLA ELECTROSOLDADA #2 (5.3 MM) | E25: Auxiliar | F25: Artículo | G25: M01-0145 | H25: 13.317175 | I25: 18762.497
A26: VN-L.32 | B26: 26 | C26: 1.2 | D26: ALAMBRE NEGRO #16 (1.68MM) | E26: Auxiliar | F26: Artículo | G26: M01-0001 | H26: 108 | I26: 586.8542
A27: VN-L.32 | B27: 27 | C27: 1.2 | D27: DISCO CORTE FINO METAL 4-1/2 | E27: Auxiliar | F27: Artículo | G27: M08-0051 | H27: 7 | I27: 3661.2
A28: VN-L.32 | B28: 28 | C28: 1.2 | D28: DISCO CORTE METAL FINO 9" | E28: Auxiliar | F28: Artículo | G28: M08-0037 | H28: 7 | I28: 3037.6321
A29: VN-L.32 | B29: 29 | C29: 1.2 | D29: ESPUMA EXPANSIVA 750ML | E29: Auxiliar | F29: Artículo | G29: M06-0193 | H29: 4 | I29: 6420.0046
A30: VN-L.32 | B30: 30 | C30: 1.2 | D30: FUNDAS DE 10CM | E30: Auxiliar | F30: Artículo | G30: M06-0195 | H30: 1200 | I30: 29.553229
A31: VN-L.32 | B31: 31 | C31: 1.2 | D31: REGLA SEMIDURO 1X3X4 SIN CEPILLAR | E31: Auxiliar | F31: Artículo | G31: M09-0042 | H31: 10 | I31: 1524.9915
A32: VN-L.32 | B32: 32 | C32: 1.2 | D32: CLAVO ACERO 2 X 3.8MM CAJA (250) | E32: Auxiliar | F32: Artículo | G32: M06-0040 | H32: 2 | I32: 6370.375
A33: VN-L.32 | B33: 33 | C33: 1.2 | D33: REPEMAX CAPA GRUESA 80XA-W2 (40KG) | E33: Auxiliar | F33: Artículo | G33: M10-0090 | H33: 6 | I33: 5527.4967
A34: VN-L.32 | B34: 34 | C34: 1.2 | D34: PERNO ANCLAJE 3/8X3-1/2 | E34: Auxiliar | F34: Artículo | G34: M06-0240 | H34: 60 | I34: 156.8101
A35: VN-L.32 | B35: 35 | C35: 1.2 | D35: CRAYON LYRA AMARILLO | E35: Auxiliar | F35: Artículo | G35: M06-0179 | H35: 10 | I35: 340.017
... A43: VN-L.32 | B43: 45 | C43: 1.3 | D43: ANGULAR HN 1"X1/8 | E43: Auxiliar | F43: Artículo | G43: M01-0018 | H43: 1 | I43: 4081.0741
A44: VN-L.32 | B44: 46 | C44: 1.3 | D44: VARILLA DEFORME #3 | E44: Auxiliar | F44: Artículo | G44: M01-0147 | H44: 6 | I44: 1344.7 | J44: 01
A45: VN-L.32 | B45: 47 | C45: 1.3 | D45: VARILLA DEFORME #4 | E45: Auxiliar | F45: Artículo | G45: M01-0148 | H45: 4 | I45: 2395.6
A46: VN-L.32 | B46: 48 | C46: 1.3 | D46: SOLDADURA 3/32 (6013) | E46: Auxiliar | F46: Artículo | G46: M01-0055 | H46: 5 | I46: 3600.0331
A47: VN-L.32 | B47: 49 | C47: 1.3 | D47: DISCO CORTE METAL FINO 9" | E47: Auxiliar | F47: Artículo | G47: M08-0037 | H47: 17 | I47: 3037.6321
...

Sheet Detallado
C1: Desglose de Presupuesto
C2: Proyecto: | E2: =+'1_OG y 2_ACA'!D3 -> Modelo Casa
C3: Cliente: | E3: ADELANTE DESARROLLOS | R3: Actualizacion
C4: Fecha: | E4: 45995 | P4: TC | Q4: 515 | R4: 45727
C5: Ubicación: | E5: Cartago
C6: Area: | E6: ='1_OG y 2_ACA'!D9 -> 126.79
A7: DESCRIPCION DE HORAS M.O. | B7: N Tarea | C7: N° | D7: Variante | E7: Descripcion actividad | F7: Cantidad | G7: Unidad | H7: Unit mater | I7: Unit MO | J7: Unit Sub/ Equipos | K7: Total Mater | L7: Total MO | M7: Total Sub/Equipos | N7: Total Directo Colones | O7: Total Directo Dólares | X7: m.o | Y7: =+X50/'1_OG y 2_ACA'!D11 -> 107706.74 | Z7: =+'1_OG y 2_ACA'!D11 -> 116.57
E8: TOTAL PRESUPUESTO | K8: =+SUBTOTAL(9,K9:K950) -> 23471758 | L8: =+SUBTOTAL(9,L9:L950) -> 13952475 | M8: =+SUBTOTAL(9,M9:M950) -> 3317703.5 | N8: =+SUBTOTAL(9,N9:N950) -> 40741936 | O8: =+SUBTOTAL(9,O9:O950) -> 79110.556 | V8: =+C11 -> 1.1.1 | W8: =+E11 -> TRAZADO Y RELLENOS | X8: =+L11 -> 168187.5 | Y8: =+X8/$X$50 -> 0.013395657 | Z8: =+X8/$Z$7 -> 1442.8026
C9: 1 | E9: OBRA GRIS | K9: =+SUBTOTAL(9,K10:K392) -> 11108224 | L9: =+SUBTOTAL(9,L10:L392) -> 9499537.5 | M9: =+SUBTOTAL(9,M10:M392) -> 741220.35 | N9: =+SUBTOTAL(9,N10:N392) -> 21348982 | O9: =+SUBTOTAL(9,O10:O392) -> 41454.334 | V9: =+C21 -> 1.1.2 | W9: =+E21 -> EXCAVACIÓN | X9: =+L21 -> 131962.5 | Y9: =+X9/$X$50 -> 0.010510439 | Z9: =+X9/$Z$7 -> 1132.0451
B10: =VALUE(IF(AND(LEN(TRIM(C10))-LEN(SUBSTITUTE(TRIM(C10),".",""))=1,ISNUMBER(VALUE(SUBSTITUTE(TRIM(C10),".","")))),TRIM(C10),B9)) -> 1.1 | C10: 1.1 | E10: FUNDACIONES | F10: 1 | G10: UND | K10: =+SUBTOTAL(9,K11:K53) -> 1835286.7 | L10: =+SUBTOTAL(9,L11:L53) -> 1179900 | M10: =+SUBTOTAL(9,M11:M53) -> 151000 | N10: =+SUBTOTAL(9,N11:N53) -> 3166186.7 | O10: =+SUBTOTAL(9,O11:O53) -> 6147.9354 | V10: =+C28 -> 1.1.3 | W10: =+E28 -> SELLO DE CONCRETO | X10: =+L28 -> 23287.5 | Y10: =+X10/$X$50 -> 0.0018547833 | Z10: =+X10/$Z$7 -> 199.77267
B11: =VALUE(IF(AND(LEN(TRIM(C11))-LEN(SUBSTITUTE(TRIM(C11),".",""))=1,ISNUMBER(VALUE(SUBSTITUTE(TRIM(C11),".","")))),TRIM(C11),B10)) -> 1.1 | C11: 1.1.1 | E11: TRAZADO Y RELLENOS | F11: =+'1_OG y 2_ACA'!D219 -> 57.62 | G11: m2 | K11: =+SUBTOTAL(9,K12:K20) -> 276899.83 | L11: =+SUBTOTAL(9,L12:L20) -> 168187.5 | M11: =+SUBTOTAL(9,M12:M20) -> 151000 | N11: =+SUBTOTAL(9,N12:N20) -> 596087.33 | O11: =+SUBTOTAL(9,O12:O20) -> 1157.4511 | V11: =+C37 -> 1.1.4 | W11: =+E37 -> LOSA FLOTANTE (ACERO, CONCRETO) | X11: =+L37 -> 856462.5 | Y11: =+X11/$X$50 -> 0.068214808 | Z11: =+X11/$Z$7 -> 7347.1948 | AA11: =+AVERAGE(Z8:Z11) -> 2530.4538
B12: =VALUE(IF(AND(LEN(TRIM(C12))-LEN(SUBSTITUTE(TRIM(C12),".",""))=1,ISNUMBER(VALUE(SUBSTITUTE(TRIM(C12),".","")))),TRIM(C12),B11)) -> 1.1 | C12: M10-0023 | E12: =_xlfn.XLOOKUP(C12,'BASE DATOS PRECIOS '!B:B,'BASE DATOS PRECIOS '!E:E) -> LASTRE FINO | F12: =ROUNDUP('1_OG y 2_ACA'!D222,0) -> 19 | G12: =+_xlfn.XLOOKUP(C12,'BASE DATOS PRECIOS '!B:B,'BASE DATOS PRECIOS '!F:F) -> M3 | H12: =+_xlfn.XLOOKUP(E12,'BASE DATOS PRECIOS '!E:E,'BASE DATOS PRECIOS '!H:H) -> 14166.663 | K12: =+F12*H12 -> 269166.6 | L12: =+F12*I12 -> 0 | M12: =+F12*J12 -> 0 | N12: =SUM(K12:M12) -> 269166.6 | O12: =SUM(K12:M12)/tc -> 522.65359 | V12: =+C55 -> 1.2.1 | W12: =+E55 -> ACERO EN PAREDES MUROS N1 | X12: =+L55 -> 1112625 | Y12: =+X12/$X$50 -> 0.088617425 | Z12: =+X12/$Z$7 -> 9544.6942
B13: =VALUE(IF(AND(LEN(TRIM(C13))-LEN(SUBSTITUTE(TRIM(C13),".",""))=1,ISNUMBER(VALUE(SUBSTITUTE(TRIM(C13),".","")))),TRIM(C13),B12)) -> 1.1 | C13: M06-0163 | E13: =_xlfn.XLOOKUP(C13,'BASE DATOS PRECIOS '!B:B,'BASE DATOS PRECIOS '!E:E) -> BOLSA CAL | F13: =+'1_OG y 2_ACA'!D223 -> 2 | G13: =+_xlfn.XLOOKUP(C13,'BASE DATOS PRECIOS '!B:B,'BASE DATOS PRECIOS '!F:F) -> BOLSA | H13: =+_xlfn.XLOOKUP(E13,'BASE DATOS PRECIOS '!E:E,'BASE DATOS PRECIOS '!H:H) -> 1627.2 | K13: =+F13*H13 -> 3254.4 | L13: =+F13*I13 -> 0 | M13: =+F13*J13 -> 0 | N13: =SUM(K13:M13) -> 3254.4 | O13: =SUM(K13:M13)/tc -> 6.3192233 | V13: =+C68 -> 1.2.2 | W13: =+E68 -> PAREDES, MUROS N1 (FORMALETA, CONCRETO, DESENCOFRADO) | X13: =+L68 -> 980662.5 | Y13: =+X13/$X$50 -> 0.078106986 | Z13: =+X13/$Z$7 -> 8412.6491
B14: =VALUE(IF(AND(LEN(TRIM(C14))-LEN(SUBSTITUTE(TRIM(C14),".",""))=1,ISNUMBER(VALUE(SUBSTITUTE(TRIM(C14),".","")))),TRIM(C14),B13)) -> 1.1 | C14: M06-0179 | E14: =_xlfn.XLOOKUP(C14,'BASE DATOS PRECIOS '!B:B,'BASE DATOS PRECIOS '!E:E) -> CRAYON LYRA AMARILLO | F14: =+'1_OG y 2_ACA'!D224 -> 6 | G14: =+_xlfn.XLOOKUP(C14,'BASE DATOS PRECIOS '!B:B,'BASE DATOS PRECIOS '!F:F) -> UND | H14: =+_xlfn.XLOOKUP(E14,'BASE DATOS PRECIOS '!E:E,'BASE DATOS PRECIOS '!H:H) -> 340.017 | K14: =+F14*H14 -> 2040.102 | L14: =+F14*I14 -> 0 | M14: =+F14*J14 -> 0 | N14: =SUM(K14:M14) -> 2040.102 | O14: =SUM(K14:M14)/tc -> 3.9613631 | V14: =+C84 -> 1.2.3 | W14: =+E84 -> MAMPOSTERIA | X14: =+L84 -> 0 | Y14: =+X14/$X$50 -> 0 | Z14: =+X14/$Z$7 -> 0
B15: =VALUE(IF(AND(LEN(TRIM(C15))-LEN(SUBSTITUTE(TRIM(C15),".",""))=1,ISNUMBER(VALUE(SUBSTITUTE(TRIM(C15),".","")))),TRIM(C15),B14)) -> 1.1 | C15: M06-0180 | E15: =_xlfn.XLOOKUP(C15,'BASE DATOS PRECIOS '!B:B,'BASE DATOS PRECIOS '!E:E) -> CUERDA ALBAÑIL BLANCA | F15: =+'1_OG y 2_ACA'!D225 -> 3 | G15: =+_xlfn.XLOOKUP(C15,'BASE DATOS PRECIOS '!B:B,'BASE DATOS PRECIOS '!F:F) -> UND | H15: =+_xlfn.XLOOKUP(E15,'BASE DATOS PRECIOS '!E:E,'BASE DATOS PRECIOS '!H:H) -> 812.9107 | K15: =+F15*H15 -> 2438.7321 | L15: =+F15*I15 -> 0 | M15: =+F15*J15 -> 0 | N15: =SUM(K15:M15) -> 2438.7321 | O15: =SUM(K15:M15)/tc -> 4.7354021 | V15: =+C89 -> 1.2.4 | W15: =+E89 -> ACERO EN PAREDES MUROS N2 | X15: =+L89 -> 859050 | Y15: =+X15/$X$50 -> 0.068420895 | Z15: =+X15/$Z$7 -> 7369.3918
B16: =VALUE(IF(AND(LEN(TRIM(C16))-LEN(SUBSTITUTE(TRIM(C16),".",""))=1,ISNUMBER(VALUE(SUBSTITUTE(TRIM(C16),".","")))),TRIM(C16),B15)) -> 1.1 | C16: BACK HOE | E16: =+_xlfn.XLOOKUP(C16,'BASE DATOS EQUIPOS Y SUBCONTRAT'!A:A,'BASE DATOS EQUIPOS Y SUBCONTRAT'!B:B) -> BACK HOE | F16: =+'1_OG y 2_ACA'!F233 -> 6 | G16: =+_xlfn.XLOOKUP(C16,'BASE DATOS EQUIPOS Y SUBCONTRAT'!A:A,'BASE DATOS EQUIPOS Y SUBCONTRAT'!C:C) -> HORA | H16: 0 | J16: =+_xlfn.XLOOKUP(C16,'BASE DATOS EQUIPOS Y SUBCONTRAT'!A:A,'BASE DATOS EQUIPOS Y SUBCONTRAT'!E:E) -> 15000 | K16: =+F16*H16 -> 0 | L16: =+F16*I16 -> 0 | M16: =+F16*J16 -> 90000 | N16: =SUM(K16:M16) -> 90000 | O16: =SUM(K16:M16)/tc -> 174.75728 | V16: =+C101 -> 1.2.5 | W16: =+E101 -> PAREDES, MUROS N2 (FORMALETA, CONCRETO, DESENCOFRADO) | X16: =+L101 -> 424350 | Y16: =+X16/$X$50 -> 0.033798274 | Z16: =+X16/$Z$7 -> 3640.302 | AA16: =+AVERAGE(Z12:Z16) -> 5793.4074
B17: =VALUE(IF(AND(LEN(TRIM(C17))-LEN(SUBSTITUTE(TRIM(C17),".",""))=1,ISNUMBER(VALUE(SUBSTITUTE(TRIM(C17),".","")))),TRIM(C17),B16)) -> 1.1 | C17: COMPACTADOR | E17: =+_xlfn.XLOOKUP(C17,'BASE DATOS EQUIPOS Y SUBCONTRAT'!A:A,'BASE DATOS EQUIPOS Y SUBCONTRAT'!B:B) -> COMPACTADOR | F17: =+'1_OG y 2_ACA'!F234 -> 1 | G17: =+_xlfn.XLOOKUP(C17,'BASE DATOS EQUIPOS Y SUBCONTRAT'!A:A,'BASE DATOS EQUIPOS Y SUBCONTRAT'!C:C) -> HORA | H17: 0 | J17: =+_xlfn.XLOOKUP(C17,'BASE DATOS EQUIPOS Y SUBCONTRAT'!A:A,'BASE DATOS EQUIPOS Y SUBCONTRAT'!E:E) -> 13000 | K17: =+F17*H17 -> 0 | L17: =+F17*I17 -> 0 | M17: =+F17*J17 -> 13000 | N17: =SUM(K17:M17) -> 13000 | O17: =SUM(K17:M17)/tc -> 25.242718 | V17: =+C116 -> 1.3.1 | W17: =+E116 -> ESTRUCTURA TECHO CASA | X17: =+L116 -> 1047000 | Y17: =+X17/$X$50 -> 0.08339058 | Z17: =+X17/$Z$7 -> 8981.7277
B18: =VALUE(IF(AND(LEN(TRIM(C18))-LEN(SUBSTITUTE(TRIM(C18),".",""))=1,ISNUMBER(VALUE(SUBSTITUTE(TRIM(C18),".","")))),TRIM(C18),B17)) -> 1.1 | C18: VAGONETA | E18: =+_xlfn.XLOOKUP(C18,'BASE DATOS EQUIPOS Y SUBCONTRAT'!A:A,'BASE DATOS EQUIPOS Y SUBCONTRAT'!B:B) -> VAGONETA | F18: =+'1_OG y 2_ACA'!F235 -> 2 | G18: =+_xlfn.XLOOKUP(C18,'BASE DATOS EQUIPOS Y SUBCONTRAT'!A:A,'BASE DATOS EQUIPOS Y SUBCONTRAT'!C:C) -> HORA | J18: =+_xlfn.XLOOKUP(C18,'BASE DATOS EQUIPOS Y SUBCONTRAT'!A:A,'BASE DATOS EQUIPOS Y SUBCONTRAT'!E:E) -> 24000 | K18: =+F18*H18 -> 0 | L18: =+F18*I18 -> 0 | M18: =+F18*J18 -> 48000 | N18: =SUM(K18:M18) -> 48000 | O18: =SUM(K18:M18)/tc -> 93.203883 | V18: =+C144 -> 1.3.2 | W18: =+E144 -> ESTRUCTURA TECHO COCHERA | X18: =+L144 -> 408000 | Y18: =+X18/$X$50 -> 0.032496043 | Z18: =+X18/$Z$7 -> 3500.0429
A19: Losa Flotante (Formaleta trazo) | B19: =VALUE(IF(AND(LEN(TRIM(C19))-LEN(SUBSTITUTE(TRIM(C19),".",""))=1,ISNUMBER(VALUE(SUBSTITUTE(TRIM(C19),".","")))),TRIM(C19),B18)) -> 1.1 | C19: OPERARIO | E19: =+_xlfn.XLOOKUP(C19,'BASE DATOS MANO DE OBRA'!A:A,'BASE DATOS MANO DE OBRA'!B:B) -> OPERARIO PLUS | F19: =ROUND('1_OG y 2_ACA'!F230,0)/2 -> 32.5 | G19: =+_xlfn.XLOOKUP(C19,'BASE DATOS MANO DE OBRA'!A:A,'BASE DATOS MANO DE OBRA'!C:C) -> hora | H19: 0 | I19: =+_xlfn.XLOOKUP(C19,'BASE DATOS MANO DE OBRA'!A:A,'BASE DATOS MANO DE OBRA'!E:E) -> 2850 | J19: 0 | K19: =+F19*H19 -> 0 | L19: =+F19*I19 -> 92625 | M19: =+F19*J19 -> 0 | N19: =SUM(K19:M19) -> 92625 | O19: =SUM(K19:M19)/tc -> 179.85437 | V19: =+C168 -> 1.3.3 | W19: =+E168 -> CUBIERTA TECHO CASA | X19: =+L168 -> 403650 | Y19: =+X19/$X$50 -> 0.032149577 | Z19: =+X19/$Z$7 -> 3462.7263
A20: Losa Flotante (Formaleta trazo) | B20: =VALUE(IF(AND(LEN(TRIM(C20))-LEN(SUBSTITUTE(TRIM(C20),".",""))=1,ISNUMBER(VALUE(SUBSTITUTE(TRIM(C20),".","")))),TRIM(C20),B19)) -> 1.1 | C20: AYUDANTE | E20: =+_xlfn.XLOOKUP(C20,'BASE DATOS MANO DE OBRA'!A:A,'BASE DATOS MANO DE OBRA'!B:B) -> AYUDANTE PLUS | F20: =+F19 -> 32.5 | G20: =+_xlfn.XLOOKUP(C20,'BASE DATOS MANO DE OBRA'!A:A,'BASE DATOS MANO DE OBRA'!C:C) -> hora | H20: 0 | I20: =+_xlfn.XLOOKUP(C20,'BASE DATOS MANO DE OBRA'!A:A,'BASE DATOS MANO DE OBRA'!E:E) -> 2325 | J20: 0 | K20: =+F20*H20 -> 0 | L20: =+F20*I20 -> 75562.5 | M20: =+F20*J20 -> 0 | N20: =SUM(K20:M20) -> 75562.5 | O20: =SUM(K20:M20)/tc -> 146.7233 | V20: =+C175 -> 1.3.4 | W20: =+E175 -> CUBIERTA TECHO COCHERA | X20: =+L175 -> 0 | Y20: =+X20/$X$50 -> 0 | Z20: =+X20/$Z$7 -> 0
B21: =VALUE(IF(AND(LEN(TRIM(C21))-LEN(SUBSTITUTE(TRIM(C21),".",""))=1,ISNUMBER(VALUE(SUBSTITUTE(TRIM(C21),".","")))),TRIM(C21),B20)) -> 1.1 | C21: 1.1.2 | E21: EXCAVACIÓN | F21: =+'1_OG y 2_ACA'!D219 -> 57.62 | G21: m2 | K21: =+SUBTOTAL(9,K22:K27) -> 13982.942 | L21: =+SUBTOTAL(9,L22:L27) -> 131962.5 | M21: =+SUBTOTAL(9,M22:M27) -> 0 | N21: =+SUBTOTAL(9,N22:N27) -> 145945.44 | O21: =+SUBTOTAL(9,O22:O27) -> 283.38921 | V21: =+C187 -> 1.3.5 | W21: =+E187 -> GRADAS ESTRUCTURA, PINTADO Y ACABADO | X21: =+L187 -> 0 | Y21: =+X21/$X$50 -> 0 | Z21: =+X21/$Z$7 -> 0
B22: =VALUE(IF(AND(LEN(TRIM(C22))-LEN(SUBSTITUTE(TRIM(C22),".",""))=1,ISNUMBER(VALUE(SUBSTITUTE(TRIM(C22),".","")))),TRIM(C22),B21)) -> 1.1 | C22: M10-0010 | E22: =+_xlfn.XLOOKUP(C22,'BASE DATOS PRECIOS '!B:B,'BASE DATOS PRECIOS '!E:E) -> ARENA LAVADA | F22: =+'1_OG y 2_ACA'!D241 -> 0.5 | G22: =+_xlfn.XLOOKUP(C22,'BASE DATOS PRECIOS '!B:B,'BASE DATOS PRECIOS '!F:F) -> M3 | H22: =+_xlfn.XLOOKUP(E22,'BASE DATOS PRECIOS '!E:E,'BASE DATOS PRECIOS '!H:H) -> 12044.501 | K22: =+F22*H22 -> 6022.2503 | L22: =+F22*I22 -> 0 | M22: =+F22*J22 -> 0 | N22: =SUM(K22:M22) -> 6022.2503 | O22: =SUM(K22:M22)/tc -> 11.69369 | V22: =+C213 -> 1.3.6 | W22: =+E213 -> BARANDA DE GRADAS (N2) | X22: =+L213 -> 219937.5 | Y22: =+X22/$X$50 -> 0.017517398 | Z22: =+X22/$Z$7 -> 1886.7419
B23: =VALUE(IF(AND(LEN(TRIM(C23))-LEN(SUBSTITUTE(TRIM(C23),".",""))=1,ISNUMBER(VALUE(SUBSTITUTE(TRIM(C23),".","")))),TRIM(C23),B22)) -> 1.1 | C23: M06-0231 | E23: =+_xlfn.XLOOKUP(C23,'BASE DATOS PRECIOS '!B:B,'BASE DATOS PRECIOS '!E:E) -> MECHA BLANCA | F23: =+'1_OG y 2_ACA'!D242 -> 1 | G23: =+_xlfn.XLOOKUP(C23,'BASE DATOS PRECIOS '!B:B,'BASE DATOS PRECIOS '!F:F) -> KG | H23: =+_xlfn.XLOOKUP(E23,'BASE DATOS PRECIOS '!E:E,'BASE DATOS PRECIOS '!H:H) -> 4338.0022 | K23: =+F23*H23 -> 4338.0022 | L23: =+F23*I23 -> 0 | M23: =+F23*J23 -> 0 | N23: =SUM(K23:M23) -> 4338.0022 | O23: =SUM(K23:M23)/tc -> 8.4233052 | V23: =+C229 -> 1.3.7 | W23: =+E229 -> ESTRUCTURA METÁLICA INTERNA | X23: =+L229 -> 0 | Y23: =+X23/$X$50 -> 0 | Z23: =+X23/$Z$7 -> 0 | AA23: =+AVERAGE(Z17:Z23) -> 2547.3198
B24: =VALUE(IF(AND(LEN(TRIM(C24))-LEN(SUBSTITUTE(TRIM(C24),".",""))=1,ISNUMBER(VALUE(SUBSTITUTE(TRIM(C24),".","")))),TRIM(C24),B23)) -> 1.1 | C24: M06-0180 | E24: =+_xlfn.XLOOKUP(C24,'BASE DATOS PRECIOS '!B:B,'BASE DATOS PRECIOS '!E:E) -> CUERDA ALBAÑIL BLANCA | F24: =+'1_OG y 2_ACA'!D243 -> 1 | G24: =+_xlfn.XLOOKUP(C24,'BASE DATOS PRECIOS '!B:B,'BASE DATOS PRECIOS '!F:F) -> UND | H24: =+_xlfn.XLOOKUP(E24,'BASE DATOS PRECIOS '!E:E,'BASE DATOS PRECIOS '!H:H) -> 812.9107 | K24: =+F24*H24 -> 812.9107 | L24: =+F24*I24 -> 0 | M24: =+F24*J24 -> 0 | N24: =SUM(K24:M24) -> 812.9107 | O24: =SUM(K24:M24)/tc -> 1.5784674 | V24: =+C237 -> 1.4.1 | W24: =+E237 -> BOTAGUAS Y CANOAS | X24: =+L237 -> 553725 | Y24: =+X24/$X$50 -> 0.044102625 | Z24: =+X24/$Z$7 -> 4750.1501
B25: =VALUE(IF(AND(LEN(TRIM(C25))-LEN(SUBSTITUTE(TRIM(C25),".",""))=1,ISNUMBER(VALUE(SUBSTITUTE(TRIM(C25),".","")))),TRIM(C25),B24)) -> 1.1 | C25: M06-0123 | E25: =+_xlfn.XLOOKUP(C25,'BASE DATOS PRECIOS '!B:B,'BASE DATOS PRECIOS '!E:E) -> ACETONA | F25: =+'1_OG y 2_ACA'!D244 -> 1 | G25: =+_xlfn.XLOOKUP(C25,'BASE DATOS PRECIOS '!B:B,'BASE DATOS PRECIOS '!F:F) -> LITRO | H25: =+_xlfn.XLOOKUP(E25,'BASE DATOS PRECIOS '!E:E,'BASE DATOS PRECIOS '!H:H) -> 2809.7789 | K25: =+F25*H25 -> 2809.7789 | L25: =+F25*I25 -> 0 | M25: =+F25*J25 -> 0 | N25: =SUM(K25:M25) -> 2809.7789 | O25: =SUM(K25:M25)/tc -> 5.4558814 | V25: =+C248 -> 1.4.2 | W25: =+E248 -> BAJANTES | X25: =+L248 -> 160425 | Y25: =+X25/$X$50 -> 0.012777396 | Z25: =+X25/$Z$7 -> 1376.2117 | AA25: =+AVERAGE(Z24:Z25) -> 3063.1809
A26: Losa Flotante (Formaleta trazo) | B26: =VALUE(IF(AND(LEN(TRIM(C26))-LEN(SUBSTITUTE(TRIM(C26),".",""))=1,ISNUMBER(VALUE(SUBSTITUTE(TRIM(C26),".","")))),TRIM(C26),B25)) -> 1.1 | C26: OPERARIO | E26: =+_xlfn.XLOOKUP(C26,'BASE DATOS MANO DE OBRA'!A:A,'BASE DATOS MANO DE OBRA'!B:B) -> OPERARIO PLUS | F26: =ROUND('1_OG y 2_ACA'!F248,0)/2 -> 25.5 | G26: =+_xlfn.XLOOKUP(C26,'BASE DATOS MANO DE OBRA'!A:A,'BASE DATOS MANO DE OBRA'!C:C) -> hora | H26: 0 | I26: =+_xlfn.XLOOKUP(C26,'BASE DATOS MANO DE OBRA'!A:A,'BASE DATOS MANO DE OBRA'!E:E) -> 2850 | J26: 0 | K26: =+F26*H26 -> 0 | L26: =+F26*I26 -> 72675 | M26: =+F26*J26 -> 0 | N26: =SUM(K26:M26) -> 72675 | O26: =SUM(K26:M26)/tc -> 141.1165 | V26: =+C254 -> 1.5.1 | W26: =+E254 -> GRADAS EN CONCRETO | X26: =+L254 -> 543375 | Y26: =+X26/$X$50 -> 0.043278277 | Z26: =+X26/$Z$7 -> 4661.3623
A27: Losa Flotante (Formaleta trazo) | B27: =VALUE(IF(AND(LEN(TRIM(C27))-LEN(SUBSTITUTE(TRIM(C27),".",""))=1,ISNUMBER(VALUE(SUBSTITUTE(TRIM(C27),".","")))),TRIM(C27),B26)) -> 1.1 | C27: AYUDANTE | E27: =+_xlfn.XLOOKUP(C27,'BASE DATOS MANO DE OBRA'!A:A,'BASE DATOS MANO DE OBRA'!B:B) -> AYUDANTE PLUS | F27: =+F26 -> 25.5 | G27: =+_xlfn.XLOOKUP(C27,'BASE DATOS MANO DE OBRA'!A:A,'BASE DATOS MANO DE OBRA'!C:C) -> hora | H27: 0 | I27: =+_xlfn.XLOOKUP(C27,'BASE DATOS MANO DE OBRA'!A:A,'BASE DATOS MANO DE OBRA'!E:E) -> 2325 | J27: 0 | K27: =+F27*H27 -> 0 | L27: =+F27*I27 -> 59287.5 | M27: =+F27*J27 -> 0 | N27: =SUM(K27:M27) -> 59287.5 | O27: =SUM(K27:M27)/tc -> 115.12136 | V27: =+C269 -> 1.5.2 | W27: =+E269 -> COLUMNAS (MEDIDOR) | X27: =+L269 -> 152662.5 | Y27: =+X27/$X$50 -> 0.012159135 | Z27: =+X27/$Z$7 -> 1309.6208
B28: =VALUE(IF(AND(LEN(TRIM(C28))-LEN(SUBSTITUTE(TRIM(C28),".",""))=1,ISNUMBER(VALUE(SUBSTITUTE(TRIM(C28),".","")))),TRIM(C28),B27)) -> 1.1 | C28: 1.1.3 | E28: SELLO DE CONCRETO | F28: =+'1_OG y 2_ACA'!D253 -> 48.12 | G28: m2 | K28: =+SUBTOTAL(9,K29:K36) -> 157774.98 | L28: =+SUBTOTAL(9,L29:L36) -> 23287.5 | M28: =+SUBTOTAL(9,M29:M36) -> 0 | N28: =+SUBTOTAL(9,N29:N36) -> 181062.48 | O28: =+SUBTOTAL(9,O29:O36) -> 351.57762 | V28: =+C282 -> 1.5.3 | W28: =+E282 -> CHORREA DE COCHERAS Y PILAS | X28: =+L282 -> 608062.5 | Y28: =+X28/$X$50 -> 0.048430453 | Z28: =+X28/$Z$7 -> 5216.2864
B29: =VALUE(IF(AND(LEN(TRIM(C29))-LEN(SUBSTITUTE(TRIM(C29),".",""))=1,ISNUMBER(VALUE(SUBSTITUTE(TRIM(C29),".","")))),TRIM(C29),B28)) -> 1.1 | E29: CONCRETO | V29: =+C299 -> 1.5.4 | W29: =+E299 -> TAPIAS PREFABRICADAS | X29: =+L299 -> 144900 | Y29: =+X29/$X$50 -> 0.011540874 | Z29: =+X29/$Z$7 -> 1243.0299
B30: =VALUE(IF(AND(LEN(TRIM(C30))-LEN(SUBSTITUTE(TRIM(C30),".",""))=1,ISNUMBER(VALUE(SUBSTITUTE(TRIM(C30),".","")))),TRIM(C30),B29)) -> 1.1 | C30: M01-0067 | E30: =+_xlfn.XLOOKUP(C30,'BASE DATOS PRECIOS '!B:B,'BASE DATOS PRECIOS '!E:E) -> TUBO 1X2X1.5MM HN | F30: =+'1_OG y 2_ACA'!D261 -> 1 | G30: =+_xlfn.XLOOKUP(C30,'BASE DATOS PRECIOS '!B:B,'BASE DATOS PRECIOS '!F:F) -> UND | H30: =+_xlfn.XLOOKUP(E30,'BASE DATOS PRECIOS '!E:E,'BASE DATOS PRECIOS '!H:H) -> 14238 | K30: =+F30*H30 -> 14238 | L30: =+F30*I30 -> 0 | M30: =+F30*J30 -> 0 | N30: =SUM(K30:M30) -> 14238 | O30: =SUM(K30:M30)/tc -> 27.646602 | V30: =+C395 -> 2.1.1 | W30: =+E395 -> REPELLOS INTERNO Y EXTERNO | X30: =+L395 -> 1014300 | Y30: =+X30/$X$50 -> 0.080786117 | Z30: =+X30/$Z$7 -> 8701.2096
B31: =VALUE(IF(AND(LEN(TRIM(C31))-LEN(SUBSTITUTE(TRIM(C31),".",""))=1,ISNUMBER(VALUE(SUBSTITUTE(TRIM(C31),".","")))),TRIM(C31),B30)) -> 1.1 | C31: M01-0148 | E31: =+_xlfn.XLOOKUP(C31,'BASE DATOS PRECIOS '!B:B,'BASE DATOS PRECIOS '!E:E) -> VARILLA DEFORME #4 | F31: =+'1_OG y 2_ACA'!D262 -> 1 | G31: =+_xlfn.XLOOKUP(C31,'BASE DATOS PRECIOS '!B:B,'BASE DATOS PRECIOS '!F:F) -> UND | H31: =+_xlfn.XLOOKUP(E31,'BASE DATOS PRECIOS '!E:E,'BASE DATOS PRECIOS '!H:H) -> 2395.6 | K31: =+F31*H31 -> 2395.6 | L31: =+F31*I31 -> 0 | M31: =+F31*J31 -> 0 | N31: =SUM(K31:M31) -> 2395.6 | O31: =SUM(K31:M31)/tc -> 4.6516505 | V31: =+C399 -> 2.1.2 | W31: =+E399 -> EMPASTE | X31: =+L399 -> 263925 | Y31: =+X31/$X$50 -> 0.021020878 | Z31: =+X31/$Z$7 -> 2264.0902 | AA31: =+AVERAGE(Z30:Z31) -> 5482.6499
B32: =VALUE(IF(AND(LEN(TRIM(C32))-LEN(SUBSTITUTE(TRIM(C32),".",""))=1,ISNUMBER(VALUE(SUBSTITUTE(TRIM(C32),".","")))),TRIM(C32),B31)) -> 1.1 | C32: M06-0180 | E32: =+_xlfn.XLOOKUP(C32,'BASE DATOS PRECIOS '!B:B,'BASE DATOS PRECIOS '!E:E) -> CUERDA ALBAÑIL BLANCA | F32: =+'1_OG y 2_ACA'!D263 -> 3 | G32: =+_xlfn.XLOOKUP(C32,'BASE DATOS PRECIOS '!B:B,'BASE DATOS PRECIOS '!F:F) -> UND | H32: =+_xlfn.XLOOKUP(E32,'BASE DATOS PRECIOS '!E:E,'BASE DATOS PRECIOS '!H:H) -> 812.9107 | K32: =+F32*H32 -> 2438.7321 | L32: =+F32*I32 -> 0 | M32: =+F32*J32 -> 0 | N32: =SUM(K32:M32) -> 2438.7321 | O32: =SUM(K32:M32)/tc -> 4.7354021 | V32: =+C407 -> 2.2.1 | W32: =+E407 -> ENCHAPES (INTERNO Y EXTERNO) | X32: =+L407 -> 626175 | Y32: =+X32/$X$50 -> 0.049873062 | Z32: =+X32/$Z$7 -> 5371.6651 | AA32: =+AVERAGE(Z32) -> 5371.6651
B33: =VALUE(IF(AND(LEN(TRIM(C33))-LEN(SUBSTITUTE(TRIM(C33),".",""))=1,ISNUMBER(VALUE(SUBSTITUTE(TRIM(C33),".","")))),TRIM(C33),B32)) -> 1.1 | C33: M09-0042 | E33: =+_xlfn.XLOOKUP(C33,'BASE DATOS PRECIOS '!B:B,'BASE DATOS PRECIOS '!E:E) -> REGLA SEMIDURO 1X3X4 SIN CEPILLAR | F33: =+'1_OG y 2_ACA'!D264 -> 5 | G33: =+_xlfn.XLOOKUP(C33,'BASE DATOS PRECIOS '!B:B,'BASE DATOS PRECIOS '!F:F) -> UND | H33: =+_xlfn.XLOOKUP(E33,'BASE DATOS PRECIOS '!E:E,'BASE DATOS PRECIOS '!H:H) -> 1524.9915 | K33: =+F33*H33 -> 7624.9575 | L33: =+F33*I33 -> 0 | M33: =+F33*J33 -> 0 | N33: =SUM(K33:M33) -> 7624.9575 | O33: =SUM(K33:M33)/tc -> 14.805743 | V33: =+C429 -> 2.3.1 | W33: =+E429 -> PINTURA PAREDES Y CIELOS | X33: =+L429 -> 773662.5 | Y33: =+X33/$X$50 -> 0.061620023 | Z33: =+X33/$Z$7 -> 6636.892
B34: =VALUE(IF(AND(LEN(TRIM(C34))-LEN(SUBSTITUTE(TRIM(C34),".",""))=1,ISNUMBER(VALUE(SUBSTITUTE(TRIM(C34),".","")))),TRIM(C34),B33)) -> 1.1 | C34: M10-0091 | E34: =+_xlfn.XLOOKUP(C34,'BASE DATOS PRECIOS '!B:B,'BASE DATOS PRECIOS '!E:E) -> CONCRETO FC 120 CM2 (Concreto Pobre, Sello) | F34: ='1_OG y 2_ACA'!D255 -> 2.406 | G34: =+_xlfn.XLOOKUP(C34,'BASE DATOS PRECIOS '!B:B,'BASE DATOS PRECIOS '!F:F) -> M3 | H34: =+_xlfn.XLOOKUP(E34,'BASE DATOS PRECIOS '!E:E,'BASE DATOS PRECIOS '!H:H) -> 54479.503 | K34: =+F34*H34 -> 131077.69 | L34: =+F34*I34 -> 0 | M34: =+F34*J34 -> 0 | N34: =SUM(K34:M34) -> 131077.69 | O34: =SUM(K34:M34)/tc -> 254.51978 | V34: =+C431 -> M11-0115 | W34: =+E431 -> PINTURA SEAL COAT CUBETA | X34: =+L431 -> 0 | Y34: =+X34/$X$50 -> 0 | Z34: =+X34/$Z$7 -> 0
A35: Sello Losa | B35: =VALUE(IF(AND(LEN(TRIM(C35))-LEN(SUBSTITUTE(TRIM(C35),".",""))=1,ISNUMBER(VALUE(SUBSTITUTE(TRIM(C35),".","")))),TRIM(C35),B34)) -> 1.1 | C35: OPERARIO | E35: =+_xlfn.XLOOKUP(C35,'BASE DATOS MANO DE OBRA'!A:A,'BASE DATOS MANO DE OBRA'!B:B) -> OPERARIO PLUS | F35: =ROUND('1_OG y 2_ACA'!F267,0)/2 -> 4.5 | G35: =+_xlfn.XLOOKUP(C35,'BASE DATOS MANO DE OBRA'!A:A,'BASE DATOS MANO DE OBRA'!C:C) -> hora | H35: 0 | I35: =+_xlfn.XLOOKUP(C35,'BASE DATOS MANO DE OBRA'!A:A,'BASE DATOS MANO DE OBRA'!E:E) -> 2850 | J35: 0 | K35: =+F35*H35 -> 0 | L35: =+F35*I35 -> 12825 | M35: =+F35*J35 -> 0 | N35: =SUM(K35:M35) -> 12825 | O35: =SUM(K35:M35)/tc -> 24.902913 | V35: =+C452 -> 2.3.2 | W35: =+E452 -> ACABADOS DE AZOTEA | X35: =+L452 -> 113850 | Y35: =+X35/$X$50 -> 0.0090678295 | Z35: =+X35/$Z$7 -> 976.66638
A36: Sello Losa | B36: =VALUE(IF(AND(LEN(TRIM(C36))-LEN(SUBSTITUTE(TRIM(C36),".",""))=1,ISNUMBER(VALUE(SUBSTITUTE(TRIM(C36),".","")))),TRIM(C36),B35)) -> 1.1 | C36: AYUDANTE | E36: =+_xlfn.XLOOKUP(C36,'BASE DATOS MANO DE OBRA'!A:A,'BASE DATOS MANO DE OBRA'!B:B) -> AYUDANTE PLUS | F36: =+F35 -> 4.5 | G36: =+_xlfn.XLOOKUP(C36,'BASE DATOS MANO DE OBRA'!A:A,'BASE DATOS MANO DE OBRA'!C:C) -> hora | H36: 0 | I36: =+_xlfn.XLOOKUP(C36,'BASE DATOS MANO DE OBRA'!A:A,'BASE DATOS MANO DE OBRA'!E:E) -> 2325 | J36: 0 | K36: =+F36*H36 -> 0 | L36: =+F36*I36 -> 10462.5 | M36: =+F36*J36 -> 0 | N36: =SUM(K36:M36) -> 10462.5 | O36: =SUM(K36:M36)/tc -> 20.315534 | V36: =+C462 -> 2.3.3 | W36: =+E462 -> PONCHEO FINAL | X36: =+L462 -> 310500 | Y36: =+X36/$X$50 -> 0.024730444 | Z36: =+X36/$Z$7 -> 2663.6356 | AA36: =+AVERAGE(Z33:Z36) -> 2569.2985
B37: =VALUE(IF(AND(LEN(TRIM(C37))-LEN(SUBSTITUTE(TRIM(C37),".",""))=1,ISNUMBER(VALUE(SUBSTITUTE(TRIM(C37),".","")))),TRIM(C37),B36)) -> 1.1 | C37: 1.1.4 | E37: LOSA FLOTANTE (ACERO, CONCRETO) | F37: =+'1_OG y 2_ACA'!D12 -> 48.12 | G37: m2 | K37: =+SUBTOTAL(9,K38:K53) -> 1386629 | L37: =+SUBTOTAL(9,L38:L53) -> 856462.5 | M37: =+SUBTOTAL(9,M38:M53) -> 0 | N37: =+SUBTOTAL(9,N38:N53) -> 2243091.5 | O37: =+SUBTOTAL(9,O38:O53) -> 4355.5174 | V37: =+C466 -> 2.4.1 | W37: =+E466 -> MUEBLES | X37: =+L466 -> 0 | Y37: =+X37/$X$50 -> 0 | Z37: =+X37/$Z$7 -> 0
B38: =VALUE(IF(AND(LEN(TRIM(C38))-LEN(SUBSTITUTE(TRIM(C38),".",""))=1,ISNUMBER(VALUE(SUBSTITUTE(TRIM(C38),".","")))),TRIM(C38),B37)) -> 1.1 | E38: CONCRETO Y ACERO | V38: =+C472 -> 2.5.1 | W38: =+E472 -> VENTANERIA (INCLUYE PUERTAS DE ALUMINIO) | X38: =+L472 -> 0 | Y38: =+X38/$X$50 -> 0 | Z38: =+X38/$Z$7 -> 0
B39: =VALUE(IF(AND(LEN(TRIM(C39))-LEN(SUBSTITUTE(TRIM(C39),".",""))=1,ISNUMBER(VALUE(SUBSTITUTE(TRIM(C39),".","")))),TRIM(C39),B38)) -> 1.1 | C39: M10-0009 | E39: =+_xlfn.XLOOKUP(C39,'BASE DATOS PRECIOS '!B:B,'BASE DATOS PRECIOS '!E:E) -> ADITIVO ERGO 4000 PG50 | F39: =+'1_OG y 2_ACA'!D283 -> 8 | G39: =+_xlfn.XLOOKUP(C39,'BASE DATOS PRECIOS '!B:B,'BASE DATOS PRECIOS '!F:F) -> LITRO | H39: =(+_xlfn.XLOOKUP(E39,'BASE DATOS PRECIOS '!E:E,'BASE DATOS PRECIOS '!H:H)) -> 748.625 | K39: =+F39*H39 -> 5989 | L39: =+F39*I39 -> 0 | M39: =+F39*J39 -> 0 | N39: =SUM(K39:M39) -> 5989 | O39: =SUM(K39:M39)/tc -> 11.629126 | V39: =+C549 -> 2.8.1 | W39: =+E549 -> ZACATE | X39: =+L549 -> 150075 | Y39: =+X39/$X$50 -> 0.011953048 | Z39: =+X39/$Z$7 -> 1287.4239 | AA39: =+AVERAGE(Z39) -> 1287.4239
B40: =VALUE(IF(AND(LEN(TRIM(C40))-LEN(SUBSTITUTE(TRIM(C40),".",""))=1,ISNUMBER(VALUE(SUBSTITUTE(TRIM(C40),".","")))),TRIM(C40),B39)) -> 1.1 | C40: M01-0146 | E40: =+_xlfn.XLOOKUP(C40,'BASE DATOS PRECIOS '!B:B,'BASE DATOS PRECIOS '!E:E) -> VARILLA DEFORME #2 | F40: =+'1_OG y 2_ACA'!D313 -> 53 | G40: UND | H40: =+_xlfn.XLOOKUP(E40,'BASE DATOS PRECIOS '!E:E,'BASE DATOS PRECIOS '!H:H) -> 569.8025 | K40: =+F40*H40 -> 30199.532 | L40: =+F40*I40 -> 0 | M40: =+F40*J40 -> 0 | N40: =SUM(K40:M40) -> 30199.532 | O40: =SUM(K40:M40)/tc -> 58.639869 | V40: =+C558 -> 3.1 | W40: =+E558 -> ELÉCTRICO | X40: =+L558 -> 0 | Y40: =+X40/$X$50 -> 0 | Z40: =+X40/$Z$7 -> 0
...

Sheet 1_OG y 2_ACA
C3: Modelo | D3: Modelo Casa | E3: VN-L.32
C6: MODELO DE CASA | D6: DATOS GENERALES
C8: DIMENSIONES
C9: Área total de casa | D9: =87.57+39.22 -> 126.79 | E9: m2 | F9: Incluye: Area total N1 y N2 interna, pilas, terrazas, ducto de escaleras SIN AZOTEA
C10: Área interna de casa | D10: =48.12+39.22+(3.5+2.15) -> 92.99 | E10: m2 | F10: Incluye: Area N1 y N2 sin garage, azotea, pilas ni terraza. Sí se debe incluir area de ducto de escalera (monitor de azotea)
C11: Área prorrateada | D11: =+D10+0.6*(D13+D14) -> 116.57 | E11: m2 | F11: Incluye: area total + area cochera * 60% + pila * 60% + terraza * 60%
C12: Área losa de fundación | D12: 48.12 | E12: m2 | F12: *medida a borde externo
C13: Áreas de pilas+terraza | D13: =4.13+5.37 -> 9.5 | E13: m2 | F13: *medida a borde externo
C14: Áreas externas de casa (cochera) | D14: 29.8 | E14: m2 | F14: *medida a borde externo
C15: Perímetro Losa flotante | D15: 34.36 | E15: m
C16: Área pilas mas losa de fundacion | D16: =+D13+D12 -> 57.62 | E16: m2
C17: Área total de nivel 1 | D17: =+D16+D14 -> 87.42 | E17: m2
C18: Área total de azotea | D18: 31.5 | E18: m2
C19: Área entrepiso de nivel 2 | D19: 39.22 | E19: m2
C20: Área total de la casa | D20: =+D19+D18+D17 -> 158.14 | E20: m2
C21: Área de techo de casa | D21: 44.8 | E21: m2
C22: Área de techo de cochera | D22: 16 | E22: m2
C23: Área de lote | D23: =6.8*18.2 -> 123.76 | E23: m2
C24: Niveles | D24: 2
C25: Azotea | D25: Sí
C26: Longitud de paredes nivel 1 | D26: 49.8 | E26: m
C27: Altura paredes nivel 1 | D27: 2.6 | E27: m
C28: Longitud de paredes nivel 2 | D28: 41.8 | E28: m
C29: Altura paredes nivel 2 | D29: 2.6 | E29: m
C30: Longitud de paredes nivel 3 azotea | D30: 24.2 | E30: m
C31: Altura paredes nivel 3 azotea | D31: 1 | E31: m
C32: Área de Muros | D32: =+D343+D547 -> 153.68 | E32: m2
C33: Cantidad de esquinas | D33: 35 | E33: u
C34: Area losa cenital | D34: 0 | E34: m2
C36: TOTAL PUERTAS Y VENTANAS
C37: Codigo | D37: Altura | E37: Ancho | F37: Cantidad
C38: Puertas Nivel 1
C39: P01 | D39: 2.15 | E39: 1 | F39: 1
C40: P02 | D40: 2.15 | E40: 0.8 | F40: 1
C41: P03 | D41: 1.15 | E41: 0.8 | F41: 1
C42: P05 | D42: 2.15 | E42: 1.8 | F42: 1
C43: P06 | D43: 2.15 | E43: 0.9 | F43: 1
C44: P07 | D44: 2.15 | E44: 1.5 | F44: 1
C45: P08 | D45: 2.15 | E45: 0.7 | F45: 1
C46: P08 | D46: 2.15 | E46: 0.8 | F46: 1
...

Sheet 3.2_MEC
C3: Modelo | D3: ='1_OG y 2_ACA'!D3 -> Modelo Casa | E3: ='1_OG y 2_ACA'!E3 -> VN-L.32
C5: 3 | D5: ELECTROMECANICO
C7: 3.2 | D7: MECÁNICO
C10: Elemento | D10: Cantidad | E10: Unidad
C11: Baño Principal | D11: 1 | E11: u
C12: Baño Secundario | D12: 1 | E12: u
C13: Medio baño | D13: 1 | E13: u
C15: 3.2.1 | D15: EXCAVACION TUBERIA SANITARIA
C17: SANITARIO EN LOSA
C18: Tubería
B19: M13-0179 | C19: Tubo PVC 4" | D19: =29.8+10 -> 39.8 | E19: =ROUNDUP(D19/6,0) -> 7
B20: M13-0190 | C20: Tubo PVC 3" | D20: 0 | E20: =ROUNDUP(D20/6,0) -> 0
B21: M13-0173 | C21: Tubo PVC 2" | D21: =12.1+10 -> 22.1 | E21: =ROUNDUP(D21/6,0) -> 4
C22: Accesorios
B23: M13-0096 | C23: Codo 90 PVC 4" | D23: 6 | E23: =ROUNDUP(D23,0) -> 6
B24: M13-0118 | C24: Codo 45 PVC 4" | E24: =ROUNDUP(D24,0) -> 0
B25: M13-0124 | C25: Codo 90 PVC 3" | E25: =ROUNDUP(D25,0) -> 0
B26: M13-0117 | C26: Codo 45 PVC 3" | E26: =ROUNDUP(D26,0) -> 0
B27: M13-0211 | C27: Codo 90 PVC 2" | D27: 9 | E27: =ROUNDUP(D27,0) -> 9
B28: M13-0119 | C28: Codo 45 PVC 2" | D28: 2 | E28: =ROUNDUP(D28,0) -> 2
B29: M13-0193 | C29: Yee PVC 4" | D29: 3 | E29: =ROUNDUP(D29,0) -> 3
B30: M13-0192 | C30: Yee PVC 3" | E30: =ROUNDUP(D30,0) -> 0
B31: M13-0191 | C31: Yee PVC 2" | D31: 3 | E31: =ROUNDUP(D31,0) -> 3
B32: M13-0132 | C32: Reducción 3" a 4" | D32: 2 | E32: =ROUNDUP(D32,0) -> 2
B33: M13-0134 | C33: Reducción 2" a 3" | E33: =ROUNDUP(D33,0) -> 0
D35: Costo | E35: Costo Total | F35: Horas
C36: Mano de obra ml de tuberia | D36: =+'1_OG y 2_ACA'!D154 -> 1200 | E36: =+SUM(D19:D21)*D36 -> 74280 | F36: =+E36/'COSTOS MO CUADRILLA'!K70 -> 26.260606
C37: Mano de obra accesorios | D37: =+'1_OG y 2_ACA'!D155 -> 500 | E37: =+SUM(D23:D33)*D37 -> 12500 | F37: =+E37/'COSTOS MO CUADRILLA'!K70 -> 4.4191919
D38: Total | E38: =SUM(E36:E37) -> 86780 | F38: =+E38/'COSTOS MO CUADRILLA'!K70 -> 30.679798
C41: 3.2.2 | D41: POTABLE DE LOSA
C43: POTABLE EN LOSA
C44: Tubería
B45: M13-0170 | C45: Tubo PVC 1/2 | D45: =39.4+10 -> 49.4 | E45: =ROUNDUP(D45/6,0) -> 9
B46: M13-0166 | C46: Tubo CPVC 1/2 | D46: =26.2+12 -> 38.2 | E46: =ROUNDUP(D46/6,0) -> 7
C47: Accesorios
B48: M13-0120 | C48: Codo 90 PVC 1/2 | D48: 18 | E48: =ROUNDUP(D48,0) -> 18
B49: M13-0094 | C49: Codo 90 CPVC 1/2 | D49: 15 | E49: =ROUNDUP(D49,0) -> 15
B50: M13-0159 | C50: Tee PVC 1/2 | D50: 12 | E50: =ROUNDUP(D50,0) -> 12
B51: M13-0157 | C51: Tee CPVC 1/2 | D51: 5 | E51: =ROUNDUP(D51,0) -> 5
B52: M13-0091 | C52: Adaptador macho PVC 1/2 | D52: 1 | E52: =ROUNDUP(D52,0) -> 1
...

Sheet 3.1_ELEC
C3: Modelo | D3: ='1_OG y 2_ACA'!D3 -> Modelo Casa | E3: ='1_OG y 2_ACA'!E3 -> VN-L.32
C5: 3 | D5: ELECTROMECANICO
C7: 3.1 | D7: ELÉCTRICO
C9: 3.1.1 | D9: ACOMETIDA & ELECTRICO LOSA
C11: Seleccionar modelo: | D11: Zante / Azotea
C13: Tuberia acometida electrica
B14: M05-0362 | C14: Curva 38mm 1 1/2" | D14: =IFERROR(_xlfn.XLOOKUP($D$11,ELEC!$F$5:$AV$5,ELEC!F6:AV6,0,0,1),0) -> 1 | E14: =ROUNDUP(D14,0) -> 1
B15: M05-0366 | C15: Curva 25mm 1" | D15: =IFERROR(_xlfn.XLOOKUP($D$11,ELEC!$F$5:$AV$5,ELEC!F7:AV7,0,0,1),0) -> 3 | E15: =ROUNDUP(D15,0) -> 3
B16: M05-0361 | C16: Curva 13mm 1/2" | D16: =IFERROR(_xlfn.XLOOKUP($D$11,ELEC!$F$5:$AV$5,ELEC!F8:AV8,0,0,1),0) -> 45 | E16: =ROUNDUP(D16,0) -> 45
B17: M05-0367 | C17: Curva 19mm 3/4" | D17: =IFERROR(_xlfn.XLOOKUP($D$11,ELEC!$F$5:$AV$5,ELEC!F9:AV9,0,0,1),0) -> 15 | E17: =ROUNDUP(D17,0) -> 15
B18: M05-0368 | C18: Tubo 38mm 1 1/2" | D18: =IFERROR(_xlfn.XLOOKUP($D$11,ELEC!$F$5:$AV$5,ELEC!F10:AV10,0,0,1),0) -> 4 | E18: =ROUNDUP(D18,0) -> 4 | H18: Ikaria / Techo
B19: M05-0369 | C19: Tubo 25mm 1" | D19: =IFERROR(_xlfn.XLOOKUP($D$11,ELEC!$F$5:$AV$5,ELEC!F11:AV11,0,0,1),0) -> 7 | E19: =ROUNDUP(D19,0) -> 7 | H19: Ikaria Especial / Techo
B20: M05-0370 | C20: Tubo 13mm 1/2" | D20: =IFERROR(_xlfn.XLOOKUP($D$11,ELEC!$F$5:$AV$5,ELEC!F12:AV12,0,0,1),0) -> 45 | E20: =ROUNDUP(D20,0) -> 45 | H20: Ikaria / Azotea
B21: M05-0371 | C21: Tubo 19mm 3/4" | D21: =IFERROR(_xlfn.XLOOKUP($D$11,ELEC!$F$5:$AV$5,ELEC!F13:AV13,0,0,1),0) -> 25 | E21: =ROUNDUP(D21,0) -> 25 | H21: Milo / Azotea
B22: M05-0372 | C22: Union 38mm 1 1/2" | D22: =IFERROR(_xlfn.XLOOKUP($D$11,ELEC!$F$5:$AV$5,ELEC!F14:AV14,0,0,1),0) -> 3 | E22: =ROUNDUP(D22,0) -> 3 | H22: Milo / Techo
B23: M05-0373 | C23: Union 25mm 1" | D23: =IFERROR(_xlfn.XLOOKUP($D$11,ELEC!$F$5:$AV$5,ELEC!F15:AV15,0,0,1),0) -> 3 | E23: =ROUNDUP(D23,0) -> 3 | H23: Milo 1,1 / Techo
B24: M05-0374 | C24: Union 13mm 1/2" | D24: =IFERROR(_xlfn.XLOOKUP($D$11,ELEC!$F$5:$AV$5,ELEC!F16:AV16,0,0,1),0) -> 18 | E24: =ROUNDUP(D24,0) -> 18 | H24: Neo Tripoli / Techo
B25: M05-0375 | C25: Union 19mm 3/4" | D25: =IFERROR(_xlfn.XLOOKUP($D$11,ELEC!$F$5:$AV$5,ELEC!F17:AV17,0,0,1),0) -> 15 | E25: =ROUNDUP(D25,0) -> 15 | H25: Neo Tripoli / Azotea
B26: M05-0476 | C26: Conector de 1/2" UL | D26: =IFERROR(_xlfn.XLOOKUP($D$11,ELEC!$F$5:$AV$5,ELEC!F18:AV18,0,0,1),0) -> 0 | E26: =ROUNDUP(D26,0) -> 0 | H26: Santorini / Azotea
B27: M11-0071 | C27: Spray | D27: =IFERROR(_xlfn.XLOOKUP($D$11,ELEC!$F$5:$AV$5,ELEC!F19:AV19,0,0,1),0) -> 1 | E27: =ROUNDUP(D27,0) -> 1 | H27: Santorini 4D / Azotea
B28: M06-0175 | C28: Cinta empaque | D28: =IFERROR(_xlfn.XLOOKUP($D$11,ELEC!$F$5:$AV$5,ELEC!F20:AV20,0,0,1),0) -> 1 | E28: =ROUNDUP(D28,0) -> 1 | H28: Santorini DA / Azotea
B29: M06-0013 | C29: Pegamento | D29: =IFERROR(_xlfn.XLOOKUP($D$11,ELEC!$F$5:$AV$5,ELEC!F21:AV21,0,0,1),0) -> 1 | E29: =ROUNDUP(D29,0) -> 1 | H29: Skyros / Techo
